Workbook

Sheet Overview
A1: Shop Drawing Approval Summary
A3: Trade | B3: Planned Equipment Shop Drawing | C3: Rev0 | N3: Rev1 | Z3: Rev2
C4: GAA Status | D4: CTA Status | F4: AUR Status | H4: STT Status | N4: GAA Status | P4: CTA Status | R4: AUR Status | T4: STT Status | Z4: GAA Status | AB4: CTA Status | AD4: AUR Status | AF4: STT Status
C5: Total Submission | D5: Total reviewed | E5: Total outstanding | F5: Total reviewed | G5: Total outstanding | H5: Total reviewed | I5: Total outstanding | J5: Status A | K5: Status B | L5: Status C | N5: Pending resubmission | O5: Submitted | P5: Total reviewed | Q5: Total outstanding | R5: Total reviewed | S5: Total outstanding | T5: Total reviewed | U5: Total outstanding | V5: Status A | W5: Status B | X5: Status C | Z5: Pending resubmission | AA5: Submitted | AB5: Total reviewed | AC5: Total outstanding | AD5: Total reviewed | AE5: Total outstanding | AF5: Total reviewed | AG5: Total outstanding | AH5: Status A | AI5: Status B | AJ5: Status C
A6: Structural | B6: {=SUMPRODUCT((ST!$C$4:$C$961<>"")*(ST!$D$4:$D$961<>""))} -> 19 | C6: {=SUMPRODUCT((ST!$C$4:$C$961<>"")*(ST!$O$4:$O$961<>""))} -> 0 | D6: {=SUMPRODUCT((ST!$C$4:$C$961<>"")*(ST!$P$4:$P$961<>""))} -> 0 | E6: {=SUMPRODUCT((ST!$C$4:$C$961<>"")*(ST!$O$4:$O$961<>"")*(ST!$P$4:$P$961=""))} -> 0 | F6: {=SUMPRODUCT((ST!$C$4:$C$961<>"")*(ST!$Q$4:$Q$961<>""))} -> 0 | G6: {=SUMPRODUCT((ST!$C$4:$C$961<>"")*(ST!$O$4:$O$961<>"")*(ST!$Q$4:$Q$961=""))} -> 0 | H6: {=SUMPRODUCT((ST!$C$4:$C$961<>"")*(ST!$R$4:$R$961<>""))} -> 0 | I6: {=SUMPRODUCT((ST!$C$4:$C$961<>"")*(ST!$O$4:$O$961<>"")*(ST!$R$4:$R$961=""))} -> 0 | J6: {=SUMPRODUCT((ST!$C$4:$C$961<>"")*(ST!$S$4:$S$961="A"))} -> 0 | K6: {=SUMPRODUCT((ST!$C$4:$C$957<>"")*(ST!$S$4:$S$957="B"))} -> 0 | L6: {=SUMPRODUCT((ST!$C$4:$C$957<>"")*(ST!$S$4:$S$957="C"))} -> 0 | N6: =L6 -> 0 | O6: {=SUMPRODUCT((ST!$C$4:$C$963<>"")*(ST!$T$4:$T$963<>""))} -> 0 | P6: {=SUMPRODUCT((ST!$C$4:$C$963<>"")*(ST!$U$4:$U$963<>""))} -> 0 | Q6: {=SUMPRODUCT((ST!$C$4:$C$963<>"")*(ST!$T$4:$T$963<>"")*(ST!$U$4:$U$963=""))} -> 0 | R6: {=SUMPRODUCT((ST!$C$4:$C$963<>"")*(ST!$V$4:$V$963<>""))} -> 0 | S6: {=SUMPRODUCT((ST!$C$4:$C$963<>"")*(ST!$T$4:$T$963<>"")*(ST!$V$4:$V$963=""))} -> 0 | T6: {=SUMPRODUCT((ST!$C$4:$C$963<>"")*(ST!$W$4:$W$963<>""))} -> 0 | U6: {=SUMPRODUCT((ST!$C$4:$C$963<>"")*(ST!$T$4:$T$963<>"")*(ST!$W$4:$W$963=""))} -> 0 | V6: {=SUMPRODUCT((ST!$C$4:$C$963<>"")*(ST!$X$4:$X$963="A"))} -> 0 | W6: {=SUMPRODUCT((ST!$C$4:$C$963<>"")*(ST!$X$4:$X$963="B"))} -> 0 | X6: {=SUMPRODUCT((ST!$C$4:$C$963<>"")*(ST!$X$4:$X$963="C"))} -> 0 | Z6: =X6 -> 0 | AA6: {=SUMPRODUCT((ST!$C$4:$C$963<>"")*(ST!$Y$4:$Y$963<>""))} -> 0 | AB6: {=SUMPRODUCT((ST!$C$4:$C$963<>"")*(ST!$Z$4:$Z$963<>""))} -> 0 | AC6: {=SUMPRODUCT((ST!$C$4:$C$963<>"")*(ST!$Y$4:$Y$963<>"")*(ST!$Z$4:$Z$963=""))} -> 0 | AD6: {=SUMPRODUCT((ST!$C$4:$C$963<>"")*(ST!$AA$4:$AA$963<>""))} -> 0 | AE6: {=SUMPRODUCT((ST!$C$4:$C$963<>"")*(ST!$Y$4:$Y$963<>"")*(ST!$AA$4:$AA$963=""))} -> 0 | AF6: {=SUMPRODUCT((ST!$C$4:$C$963<>"")*(ST!$AB$4:$AB$963<>""))} -> 0 | AG6: {=SUMPRODUCT((ST!$C$4:$C$963<>"")*(ST!$Y$4:$Y$963<>"")*(ST!$AB$4:$AB$963=""))} -> 0 | AH6: {=SUMPRODUCT((ST!$C$4:$C$963<>"")*(ST!$AC$4:$AC$963="A"))} -> 0 | AI6: {=SUMPRODUCT((ST!$C$4:$C$963<>"")*(ST!$AC$4:$AC$963="B"))} -> 0 | AJ6: {=SUMPRODUCT((ST!$C$4:$C$963<>"")*(ST!$AC$4:$AC$963="C"))} -> 0
A7: Architectural | B7: {=SUMPRODUCT((AR!$C$4:$C$964<>"")*(AR!$D$4:$D$964<>""))} -> 83 | C7: =SUMPRODUCT((AR!$C$4:$C$964<>"")*(AR!$O$4:$O$964<>"")) -> 26 | D7: =SUMPRODUCT((AR!$C$4:$C$964<>"")*(AR!$P$4:$P$964<>"")) -> 26 | E7: =SUMPRODUCT((AR!$C$4:$C$964<>"")*(AR!$O$4:$O$964<>"")*(AR!$P$4:$P$964="")) -> 0 | F7: =SUMPRODUCT((AR!$C$4:$C$964<>"")*(AR!$Q$4:$Q$964<>"")) -> 23 | G7: =SUMPRODUCT((AR!$C$4:$C$964<>"")*(AR!$O$4:$O$964<>"")*(AR!$Q$4:$Q$964="")) -> 3 | H7: =SUMPRODUCT((AR!$C$4:$C$964<>"")*(AR!$R$4:$R$964<>"")) -> 15 | I7: =SUMPRODUCT((AR!$C$4:$C$964<>"")*(AR!$O$4:$O$964<>"")*(AR!$R$4:$R$964="")) -> 11 | J7: =SUMPRODUCT((AR!$C$4:$C$964<>"")*(AR!$S$4:$S$964="A")) -> 0 | K7: {=SUMPRODUCT((AR!$C$4:$C$968<>"")*(AR!$S$4:$S$968="B"))} -> 14 | L7: {=SUMPRODUCT((AR!$C$4:$C$968<>"")*(AR!$S$4:$S$968="C"))} -> 2 | N7: =L7 -> 2 | O7: =SUMPRODUCT((AR!$C$4:$C$964<>"")*(AR!$T$4:$T$964<>"")) -> 1 | P7: =SUMPRODUCT((AR!$C$4:$C$964<>"")*(AR!$U$4:$U$964<>"")) -> 1 | Q7: =SUMPRODUCT((AR!$C$4:$C$964<>"")*(AR!$T$4:$T$964<>"")*(AR!$U$4:$U$964="")) -> 0 | R7: =SUMPRODUCT((AR!$C$4:$C$964<>"")*(AR!$V$4:$V$964<>"")) -> 1 | S7: =SUMPRODUCT((AR!$C$4:$C$964<>"")*(AR!$T$4:$T$964<>"")*(AR!$V$4:$V$964="")) -> 0 | T7: =SUMPRODUCT((AR!$C$4:$C$964<>"")*(AR!$W$4:$W$964<>"")) -> 0 | U7: =SUMPRODUCT((AR!$C$4:$C$964<>"")*(AR!$T$4:$T$964<>"")*(AR!$W$4:$W$964="")) -> 1 | V7: =SUMPRODUCT((AR!$C$4:$C$964<>"")*(AR!$X$4:$X$964="A")) -> 0 | W7: =SUMPRODUCT((AR!$C$4:$C$964<>"")*(AR!$X$4:$X$964="B")) -> 0 | X7: {=SUMPRODUCT((AR!$C$4:$C$964<>"")*(AR!$X$4:$X$964="C"))} -> 0 | Z7: =X7 -> 0 | AA7: =SUMPRODUCT((AR!$C$4:$C$964<>"")*(AR!$Y$4:$Y$964<>"")) -> 0 | AB7: =SUMPRODUCT((AR!$C$4:$C$964<>"")*(AR!$Z$4:$Z$964<>"")) -> 0 | AC7: =SUMPRODUCT((AR!$C$4:$C$964<>"")*(AR!$Y$4:$Y$964<>"")*(AR!$Z$4:$Z$964="")) -> 0 | AD7: =SUMPRODUCT((AR!$C$4:$C$964<>"")*(AR!$AA$4:$AA$964<>"")) -> 0 | AE7: =SUMPRODUCT((AR!$C$4:$C$964<>"")*(AR!$Y$4:$Y$964<>"")*(AR!$AA$4:$AA$964="")) -> 0 | AF7: =SUMPRODUCT((AR!$C$4:$C$964<>"")*(AR!$AB$4:$AB$964<>"")) -> 0 | AG7: =SUMPRODUCT((AR!$C$4:$C$964<>"")*(AR!$Y$4:$Y$964<>"")*(AR!$AB$4:$AB$964="")) -> 0 | AH7: =SUMPRODUCT((AR!$C$4:$C$964<>"")*(AR!$AC$4:$AC$964="A")) -> 0 | AI7: =SUMPRODUCT((AR!$C$4:$C$964<>"")*(AR!$AC$4:$AC$964="B")) -> 0 | AJ7: =SUMPRODUCT((AR!$C$4:$C$964<>"")*(AR!$AC$4:$AC$964="C")) -> 0
A8: Mechanical | B8: {=SUMPRODUCT((ME!$C$4:$C$962<>"")*(ME!$D$4:$D$962<>""))} -> 52 | C8: =SUMPRODUCT((ME!$C$4:$C$927<>"")*(ME!$O$4:$O$927<>"")) -> 5 | D8: =SUMPRODUCT((ME!$C$4:$C$927<>"")*(ME!$P$4:$P$927<>"")) -> 5 | E8: =SUMPRODUCT((ME!$C$4:$C$927<>"")*(ME!$O$4:$O$927<>"")*(ME!$P$4:$P$927="")) -> 0 | F8: =SUMPRODUCT((ME!$C$4:$C$927<>"")*(ME!$Q$4:$Q$927<>"")) -> 0 | G8: =SUMPRODUCT((ME!$C$4:$C$927<>"")*(ME!$O$4:$O$927<>"")*(ME!$Q$4:$Q$927="")) -> 5 | H8: =SUMPRODUCT((ME!$C$4:$C$927<>"")*(ME!$R$4:$R$927<>"")) -> 0 | I8: =SUMPRODUCT((ME!$C$4:$C$927<>"")*(ME!$O$4:$O$927<>"")*(ME!$R$4:$R$927="")) -> 5 | J8: =SUMPRODUCT((ME!$C$4:$C$927<>"")*(ME!$S$4:$S$927="A")) -> 0 | K8: =SUMPRODUCT((ME!$C$4:$C$927<>"")*(ME!$S$4:$S$927="B")) -> 0 | L8: =SUMPRODUCT((ME!$C$4:$C$927<>"")*(ME!$S$4:$S$927="C")) -> 1 | N8: =L8 -> 1 | O8: =SUMPRODUCT((ME!$C$4:$C$927<>"")*(ME!$T$4:$T$927<>"")) -> 0 | P8: =SUMPRODUCT((ME!$C$4:$C$927<>"")*(ME!$U$4:$U$927<>"")) -> 0 | Q8: =SUMPRODUCT((ME!$C$4:$C$927<>"")*(ME!$T$4:$T$927<>"")*(ME!$U$4:$U$927="")) -> 0 | R8: =SUMPRODUCT((ME!$C$4:$C$927<>"")*(ME!$V$4:$V$927<>"")) -> 0 | S8: =SUMPRODUCT((ME!$C$4:$C$927<>"")*(ME!$T$4:$T$927<>"")*(ME!$V$4:$V$927="")) -> 0 | T8: =SUMPRODUCT((ME!$C$4:$C$927<>"")*(ME!$W$4:$W$927<>"")) -> 0 | U8: =SUMPRODUCT((ME!$C$4:$C$927<>"")*(ME!$T$4:$T$927<>"")*(ME!$W$4:$W$927="")) -> 0 | V8: =SUMPRODUCT((ME!$C$4:$C$927<>"")*(ME!$X$4:$X$927="A")) -> 0 | W8: =SUMPRODUCT((ME!$C$4:$C$927<>"")*(ME!$X$4:$X$927="B")) -> 0 | X8: =SUMPRODUCT((ME!$C$4:$C$927<>"")*(ME!$X$4:$X$927="C")) -> 0 | Z8: =X8 -> 0 | AA8: =SUMPRODUCT((ME!$C$4:$C$927<>"")*(ME!$Y$4:$Y$927<>"")) -> 0 | AB8: =SUMPRODUCT((ME!$C$4:$C$927<>"")*(ME!$Z$4:$Z$927<>"")) -> 0 | AC8: =SUMPRODUCT((ME!$C$4:$C$927<>"")*(ME!$Y$4:$Y$927<>"")*(ME!$Z$4:$Z$927="")) -> 0 | AD8: =SUMPRODUCT((ME!$C$4:$C$927<>"")*(ME!$AA$4:$AA$927<>"")) -> 0 | AE8: =SUMPRODUCT((ME!$C$4:$C$927<>"")*(ME!$Y$4:$Y$927<>"")*(ME!$AA$4:$AA$927="")) -> 0 | AF8: =SUMPRODUCT((ME!$C$4:$C$927<>"")*(ME!$AB$4:$AB$927<>"")) -> 0 | AG8: =SUMPRODUCT((ME!$C$4:$C$927<>"")*(ME!$Y$4:$Y$927<>"")*(ME!$AB$4:$AB$927="")) -> 0 | AH8: =SUMPRODUCT((ME!$C$4:$C$927<>"")*(ME!$AC$4:$AC$927="A")) -> 0 | AI8: =SUMPRODUCT((ME!$C$4:$C$927<>"")*(ME!$AC$4:$AC$927="B")) -> 0 | AJ8: =SUMPRODUCT((ME!$C$4:$C$927<>"")*(ME!$AC$4:$AC$927="C")) -> 0
A9: Fire Protection | B9: {=SUMPRODUCT((FI!$C$4:$C$949<>"")*(FI!$D$4:$D$949<>""))} -> 40 | C9: =SUMPRODUCT((FI!$C$4:$C$988<>"")*(FI!$O$4:$O$988<>"")) -> 11 | D9: =SUMPRODUCT((FI!$C$4:$C$988<>"")*(FI!$P$4:$P$988<>"")) -> 7 | E9: =SUMPRODUCT((FI!$C$4:$C$988<>"")*(FI!$O$4:$O$988<>"")*(FI!$P$4:$P$988="")) -> 4 | F9: =SUMPRODUCT((FI!$C$4:$C$988<>"")*(FI!$Q$4:$Q$988<>"")) -> 0 | G9: =SUMPRODUCT((FI!$C$4:$C$988<>"")*(FI!$O$4:$O$988<>"")*(FI!$Q$4:$Q$988="")) -> 11 | H9: =SUMPRODUCT((FI!$C$4:$C$988<>"")*(FI!$R$4:$R$988<>"")) -> 0 | I9: =SUMPRODUCT((FI!$C$4:$C$988<>"")*(FI!$O$4:$O$988<>"")*(FI!$R$4:$R$988="")) -> 11 | J9: =SUMPRODUCT((FI!$C$4:$C$988<>"")*(FI!$S$4:$S$988="A")) -> 0 | K9: =SUMPRODUCT((FI!$C$4:$C$988<>"")*(FI!$S$4:$S$988="B")) -> 0 | L9: =SUMPRODUCT((FI!$C$4:$C$988<>"")*(FI!$S$4:$S$988="C")) -> 0 | N9: =L9 -> 0 | O9: =SUMPRODUCT((FI!$C$4:$C$988<>"")*(FI!$T$4:$T$988<>"")) -> 0 | P9: =SUMPRODUCT((FI!$C$4:$C$988<>"")*(FI!$U$4:$U$988<>"")) -> 0 | Q9: =SUMPRODUCT((FI!$C$4:$C$988<>"")*(FI!$T$4:$T$988<>"")*(FI!$U$4:$U$988="")) -> 0 | R9: =SUMPRODUCT((FI!$C$4:$C$988<>"")*(FI!$V$4:$V$988<>"")) -> 0 | S9: =SUMPRODUCT((FI!$C$4:$C$988<>"")*(FI!$T$4:$T$988<>"")*(FI!$V$4:$V$988="")) -> 0 | T9: =SUMPRODUCT((FI!$C$4:$C$988<>"")*(FI!$W$4:$W$988<>"")) -> 0 | U9: =SUMPRODUCT((FI!$C$4:$C$988<>"")*(FI!$T$4:$T$988<>"")*(FI!$W$4:$W$988="")) -> 0 | V9: =SUMPRODUCT((FI!$C$4:$C$988<>"")*(FI!$X$4:$X$988="A")) -> 0 | W9: =SUMPRODUCT((FI!$C$4:$C$988<>"")*(FI!$X$4:$X$988="B")) -> 0 | X9: =SUMPRODUCT((FI!$C$4:$C$988<>"")*(FI!$X$4:$X$988="C")) -> 0 | Z9: =X9 -> 0 | AA9: =SUMPRODUCT((FI!$C$4:$C$988<>"")*(FI!$Y$4:$Y$988<>"")) -> 0 | AB9: =SUMPRODUCT((FI!$C$4:$C$988<>"")*(FI!$Z$4:$Z$988<>"")) -> 0 | AC9: =SUMPRODUCT((FI!$C$4:$C$988<>"")*(FI!$Y$4:$Y$988<>"")*(FI!$Z$4:$Z$988="")) -> 0 | AD9: =SUMPRODUCT((FI!$C$4:$C$988<>"")*(FI!$AA$4:$AA$988<>"")) -> 0 | AE9: =SUMPRODUCT((FI!$C$4:$C$988<>"")*(FI!$Y$4:$Y$988<>"")*(FI!$AA$4:$AA$988="")) -> 0 | AF9: =SUMPRODUCT((FI!$C$4:$C$988<>"")*(FI!$AB$4:$AB$988<>"")) -> 0 | AG9: =SUMPRODUCT((FI!$C$4:$C$988<>"")*(FI!$Y$4:$Y$988<>"")*(FI!$AB$4:$AB$988="")) -> 0 | AH9: =SUMPRODUCT((FI!$C$4:$C$988<>"")*(FI!$AC$4:$AC$988="A")) -> 0 | AI9: =SUMPRODUCT((FI!$C$4:$C$988<>"")*(FI!$AC$4:$AC$988="B")) -> 0 | AJ9: =SUMPRODUCT((FI!$C$4:$C$988<>"")*(FI!$AC$4:$AC$988="C")) -> 0
A10: Hydraulics | B10: {=SUMPRODUCT((HY!$C$5:$C$957<>"")*(HY!$D$5:$D$957<>""))} -> 31 | C10: {=SUMPRODUCT((HY!$C$5:$C$999<>"")*(HY!$O$5:$O$999<>""))} -> 11 | D10: =SUMPRODUCT((HY!$C$5:$C$999<>"")*(HY!$P$5:$P$999<>"")) -> 11 | E10: =SUMPRODUCT((HY!$C$5:$C$999<>"")*(HY!$O$5:$O$999<>"")*(HY!$P$5:$P$999="")) -> 0 | F10: =SUMPRODUCT((HY!$C$5:$C$999<>"")*(HY!$Q$5:$Q$999<>"")) -> 0 | G10: =SUMPRODUCT((HY!$C$5:$C$999<>"")*(HY!$O$5:$O$999<>"")*(HY!$Q$5:$Q$999="")) -> 11 | H10: =SUMPRODUCT((HY!$C$5:$C$999<>"")*(HY!$R$5:$R$999<>"")) -> 0 | I10: =SUMPRODUCT((HY!$C$5:$C$999<>"")*(HY!$O$5:$O$999<>"")*(HY!$R$5:$R$999="")) -> 11 | J10: =SUMPRODUCT((HY!$C$5:$C$999<>"")*(HY!$S$5:$S$999="A")) -> 0 | K10: =SUMPRODUCT((HY!$C$5:$C$999<>"")*(HY!$S$5:$S$999="B")) -> 0 | L10: =SUMPRODUCT((HY!$C$5:$C$999<>"")*(HY!$S$5:$S$999="C")) -> 0 | N10: =L10 -> 0 | O10: =SUMPRODUCT((HY!$C$5:$C$999<>"")*(HY!$T$5:$T$999<>"")) -> 0 | P10: =SUMPRODUCT((HY!$C$5:$C$999<>"")*(HY!$U$5:$U$999<>"")) -> 0 | Q10: =SUMPRODUCT((HY!$C$5:$C$999<>"")*(HY!$T$5:$T$999<>"")*(HY!$U$5:$U$999="")) -> 0 | R10: =SUMPRODUCT((HY!$C$5:$C$999<>"")*(HY!$V$5:$V$999<>"")) -> 0 | S10: =SUMPRODUCT((HY!$C$5:$C$999<>"")*(HY!$T$5:$T$999<>"")*(HY!$V$5:$V$999="")) -> 0 | T10: =SUMPRODUCT((HY!$C$5:$C$999<>"")*(HY!$W$5:$W$999<>"")) -> 0 | U10: =SUMPRODUCT((HY!$C$5:$C$999<>"")*(HY!$T$5:$T$999<>"")*(HY!$W$5:$W$999="")) -> 0 | V10: =SUMPRODUCT((HY!$C$5:$C$999<>"")*(HY!$X$5:$X$999="A")) -> 0 | W10: =SUMPRODUCT((HY!$C$5:$C$999<>"")*(HY!$X$5:$X$999="B")) -> 0 | X10: =SUMPRODUCT((HY!$C$5:$C$999<>"")*(HY!$X$5:$X$999="C")) -> 0 | Z10: =X10 -> 0 | AA10: =SUMPRODUCT((HY!$C$5:$C$999<>"")*(HY!$Y$5:$Y$999<>"")) -> 0 | AB10: =SUMPRODUCT((HY!$C$5:$C$999<>"")*(HY!$Z$5:$Z$999<>"")) -> 0 | AC10: =SUMPRODUCT((HY!$C$5:$C$999<>"")*(HY!$Y$5:$Y$999<>"")*(HY!$Z$5:$Z$999="")) -> 0 | AD10: =SUMPRODUCT((HY!$C$5:$C$999<>"")*(HY!$AA$5:$AA$999<>"")) -> 0 | AE10: =SUMPRODUCT((HY!$C$5:$C$999<>"")*(HY!$Y$5:$Y$999<>"")*(HY!$AA$5:$AA$999="")) -> 0 | AF10: =SUMPRODUCT((HY!$C$5:$C$999<>"")*(HY!$AB$5:$AB$999<>"")) -> 0 | AG10: =SUMPRODUCT((HY!$C$5:$C$999<>"")*(HY!$Y$5:$Y$999<>"")*(HY!$AB$5:$AB$999="")) -> 0 | AH10: =SUMPRODUCT((HY!$C$5:$C$999<>"")*(HY!$AC$5:$AC$999="A")) -> 0 | AI10: =SUMPRODUCT((HY!$C$5:$C$999<>"")*(HY!$AC$5:$AC$999="B")) -> 0 | AJ10: =SUMPRODUCT((HY!$C$5:$C$999<>"")*(HY!$AC$5:$AC$999="C")) -> 0
A11: Electrical & Comms | B11: {=SUMPRODUCT((EL!$C$4:$C$960<>"")*(EL!$D$4:$D$960<>""))} -> 258 | C11: {=SUMPRODUCT((EL!$C$4:$C$929<>"")*(EL!$Q$4:$Q$929<>""))} -> 71 | D11: =SUMPRODUCT((EL!$C$4:$C$1136<>"")*(EL!$R$4:$R$1136<>"")) -> 36 | E11: =SUMPRODUCT((EL!$C$4:$C$1136<>"")*(EL!$Q$4:$Q$1136<>"")*(EL!$R$4:$R$1136="")) -> 35 | F11: =SUMPRODUCT((EL!$C$4:$C$1136<>"")*(EL!$S$4:$S$1136<>"")) -> 24 | G11: =SUMPRODUCT((EL!$C$4:$C$1136<>"")*(EL!$Q$4:$Q$1136<>"")*(EL!$S$4:$S$1136="")) -> 47 | H11: =SUMPRODUCT((EL!$C$4:$C$1136<>"")*(EL!$T$4:$T$1136<>"")) -> 3 | I11: =SUMPRODUCT((EL!$C$4:$C$1136<>"")*(EL!$Q$4:$Q$1136<>"")*(EL!$T$4:$T$1136="")) -> 68 | J11: =SUMPRODUCT((EL!$C$4:$C$1136<>"")*(EL!$U$4:$U$1136="A")) -> 0 | K11: =SUMPRODUCT((EL!$C$4:$C$1136<>"")*(EL!$U$4:$U$1136="B")) -> 0 | L11: =SUMPRODUCT((EL!$C$4:$C$1136<>"")*(EL!$U$4:$U$1136="C")) -> 3 | N11: =L11 -> 3 | O11: =SUMPRODUCT((EL!$C$4:$C$1136<>"")*(EL!$V$4:$V$1136<>"")) -> 3 | P11: =SUMPRODUCT((EL!$C$4:$C$1136<>"")*(EL!$W$4:$W$1136<>"")) -> 2 | Q11: =SUMPRODUCT((EL!$C$4:$C$1136<>"")*(EL!$V$4:$V$1136<>"")*(EL!$W$4:$W$1136="")) -> 1 | R11: =SUMPRODUCT((EL!$C$4:$C$1136<>"")*(EL!$X$4:$X$1136<>"")) -> 1 | S11: =SUMPRODUCT((EL!$C$4:$C$1136<>"")*(EL!$V$4:$V$1136<>"")*(EL!$X$4:$X$1136="")) -> 2 | T11: =SUMPRODUCT((EL!$C$4:$C$1136<>"")*(EL!$Y$4:$Y$1136<>"")) -> 0 | U11: =SUMPRODUCT((EL!$C$4:$C$1136<>"")*(EL!$V$4:$V$1136<>"")*(EL!$Y$4:$Y$1136="")) -> 3 | V11: =SUMPRODUCT((EL!$C$4:$C$1136<>"")*(EL!$Z$4:$Z$1136="A")) -> 0 | W11: =SUMPRODUCT((EL!$C$4:$C$1136<>"")*(EL!$Z$4:$Z$1136="B")) -> 0 | X11: =SUMPRODUCT((EL!$C$4:$C$1136<>"")*(EL!$Z$4:$Z$1136="C")) -> 0 | Z11: =X11 -> 0 | AA11: =SUMPRODUCT((EL!$C$4:$C$1136<>"")*(EL!$AA$4:$AA$1136<>"")) -> 0 | AB11: =SUMPRODUCT((EL!$C$4:$C$1136<>"")*(EL!$AB$4:$AB$1136<>"")) -> 0 | AC11: =SUMPRODUCT((EL!$C$4:$C$1136<>"")*(EL!$AA$4:$AA$1136<>"")*(EL!$AB$4:$AB$1136="")) -> 0 | AD11: =SUMPRODUCT((EL!$C$4:$C$1136<>"")*(EL!$AC$4:$AC$1136<>"")) -> 0 | AE11: =SUMPRODUCT((EL!$C$4:$C$1136<>"")*(EL!$AA$4:$AA$1136<>"")*(EL!$AC$4:$AC$1136="")) -> 0 | AF11: =SUMPRODUCT((EL!$C$4:$C$1136<>"")*(EL!$AD$4:$AD$1136<>"")) -> 0 | AG11: =SUMPRODUCT((EL!$C$4:$C$1136<>"")*(EL!$AA$4:$AA$1136<>"")*(EL!$AD$4:$AD$1136="")) -> 0 | AH11: =SUMPRODUCT((EL!$C$4:$C$1136<>"")*(EL!$AE$4:$AE$1136="A")) -> 0 | AI11: =SUMPRODUCT((EL!$C$4:$C$1136<>"")*(EL!$AE$4:$AE$1136="B")) -> 0 | AJ11: =SUMPRODUCT((EL!$C$4:$C$1136<>"")*(EL!$AE$4:$AE$1136="C")) -> 0
A12: Combine services drawing | B12: {=SUMPRODUCT((CSD!$C$4:$C$972<>"")*(CSD!$D$4:$D$972<>""))} -> 27 | C12: {=SUMPRODUCT((CSD!$C$4:$C$980<>"")*(CSD!$O$4:$O$980<>""))} -> 13 | D12: {=SUMPRODUCT((CSD!$C$4:$C$1187<>"")*(CSD!$P$4:$P$1187<>""))} -> 0 | E12: {=SUMPRODUCT((CSD!$C$4:$C$1187<>"")*(CSD!$O$4:$O$1187<>"")*(CSD!$P$4:$P$1187=""))} -> 13 | F12: {=SUMPRODUCT((CSD!$C$4:$C$1187<>"")*(CSD!$Q$4:$Q$1187<>""))} -> 0 | G12: {=SUMPRODUCT((CSD!$C$4:$C$1187<>"")*(CSD!$O$4:$O$1187<>"")*(CSD!$Q$4:$Q$1187=""))} -> 13 | H12: {=SUMPRODUCT((CSD!$C$4:$C$1187<>"")*(CSD!$R$4:$R$1187<>""))} -> 0 | I12: {=SUMPRODUCT((CSD!$C$4:$C$1187<>"")*(CSD!$O$4:$O$1187<>"")*(CSD!$R$4:$R$1187=""))} -> 13 | J12: {=SUMPRODUCT((CSD!$C$4:$C$1187<>"")*(CSD!$S$4:$S$1187="A"))} -> 0 | K12: {=SUMPRODUCT((CSD!$C$4:$C$1187<>"")*(CSD!$S$4:$S$1187="B"))} -> 0 | L12: {=SUMPRODUCT((CSD!$C$4:$C$1187<>"")*(CSD!$S$4:$S$1187="C"))} -> 0 | N12: =L12 -> 0 | O12: {=SUMPRODUCT((CSD!$C$4:$C$1187<>"")*(CSD!$T$4:$T$1187<>""))} -> 0 | P12: {=SUMPRODUCT((CSD!$C$4:$C$1187<>"")*(CSD!$U$4:$U$1187<>""))} -> 0 | Q12: {=SUMPRODUCT((CSD!$C$4:$C$1187<>"")*(CSD!$T$4:$T$1187<>"")*(CSD!$U$4:$U$1187=""))} -> 0 | R12: {=SUMPRODUCT((CSD!$C$4:$C$1187<>"")*(CSD!$V$4:$V$1187<>""))} -> 0 | S12: {=SUMPRODUCT((CSD!$C$4:$C$1187<>"")*(CSD!$T$4:$T$1187<>"")*(CSD!$V$4:$V$1187=""))} -> 0 | T12: {=SUMPRODUCT((CSD!$C$4:$C$1187<>"")*(CSD!$W$4:$W$1187<>""))} -> 0 | U12: {=SUMPRODUCT((CSD!$C$4:$C$1187<>"")*(CSD!$T$4:$T$1187<>"")*(CSD!$W$4:$W$1187=""))} -> 0 | V12: {=SUMPRODUCT((CSD!$C$4:$C$1187<>"")*(CSD!$X$4:$X$1187="A"))} -> 0 | W12: {=SUMPRODUCT((CSD!$C$4:$C$1187<>"")*(CSD!$X$4:$X$1187="B"))} -> 0 | X12: {=SUMPRODUCT((CSD!$C$4:$C$1187<>"")*(CSD!$X$4:$X$1187="C"))} -> 0 | Z12: =X12 -> 0 | AA12: {=SUMPRODUCT((CSD!$C$4:$C$1187<>"")*(CSD!$Y$4:$Y$1187<>""))} -> 0 | AB12: {=SUMPRODUCT((CSD!$C$4:$C$1187<>"")*(CSD!$Z$4:$Z$1187<>""))} -> 0 | AC12: {=SUMPRODUCT((CSD!$C$4:$C$1187<>"")*(CSD!$Y$4:$Y$1187<>"")*(CSD!$Z$4:$Z$1187=""))} -> 0 | AD12: {=SUMPRODUCT((CSD!$C$4:$C$1187<>"")*(CSD!$AA$4:$AA$1187<>""))} -> 0 | AE12: {=SUMPRODUCT((CSD!$C$4:$C$1187<>"")*(CSD!$Y$4:$Y$1187<>"")*(CSD!$AA$4:$AA$1187=""))} -> 0 | AF12: {=SUMPRODUCT((CSD!$C$4:$C$1187<>"")*(CSD!$AB$4:$AB$1187<>""))} -> 0 | AG12: {=SUMPRODUCT((CSD!$C$4:$C$1187<>"")*(CSD!$Y$4:$Y$1187<>"")*(CSD!$AB$4:$AB$1187=""))} -> 0 | AH12: {=SUMPRODUCT((CSD!$C$4:$C$1187<>"")*(CSD!$AC$4:$AC$1187="A"))} -> 0 | AI12: {=SUMPRODUCT((CSD!$C$4:$C$1187<>"")*(CSD!$AC$4:$AC$1187="B"))} -> 0 | AJ12: {=SUMPRODUCT((CSD!$C$4:$C$1187<>"")*(CSD!$AC$4:$AC$1187="C"))} -> 0
A13: Overall | B13: =SUM(B6:B12) -> 510 | C13: =SUM(C6:C12) -> 137 | D13: =SUM(D6:D12) -> 85 | E13: =SUM(E6:E12) -> 52 | F13: =SUM(F6:F12) -> 47 | G13: =SUM(G6:G12) -> 90 | H13: =SUM(H6:H12) -> 18 | I13: =SUM(I6:I12) -> 119 | ... AJ13: =SUM(AJ6:AJ12) -> 0
C120: Trade | D120: Submission | E120: Submitted | F120: Approved by All | G120: Rejected | H120: Pending submission | I120: CTA Approved | J120: CTA Outstanding | K120: AUR Approved | L120: AUR Outstanding | M120: STT Approved | N120: STT outstanding
C121: Structural | D121: =B6 -> 19 | E121: {=SUMPRODUCT((ST!$C$4:$C$957<>"")*(ST!$D$4:$D$957<>"")*((ST!$K$4:$K$957="A")+(ST!$K$4:$K$957="B")+(ST!$K$4:$K$957="PENDING")))} -> 0 | F121: {=SUMPRODUCT((ST!$C$4:$C$957<>"")*(ST!$D$4:$D$957<>"")*((ST!$K$4:$K$957="A")+(ST!$K$4:$K$957="B")))} -> 0 | G121: {=SUMPRODUCT((ST!$C$4:$C$957<>"")*(ST!$D$4:$D$957<>"")*(ST!$K$4:$K$957="C"))} -> 0 | H121: {=SUMPRODUCT((ST!$C$4:$C$957<>"")*(ST!$D$4:$D$957<>"")*((ST!$K$4:$K$957="C")+(ST!$K$4:$K$957="")))} -> 19 | I121: {=SUMPRODUCT((ST!$C$4:$C$965<>"")*(ST!$D$4:$D$965<>"")*((ST!$I$4:$I$965=0)*(ST!$P$4:$P$965<>"")+(ST!$I$4:$I$965=1)*(ST!$U$4:$U$965<>"")+(ST!$I$4:$I$965=2)*(ST!$Z$4:$Z$965<>"")))} -> 0 | J121: {=SUMPRODUCT((ST!$C$4:$C$957<>"")*(ST!$D$4:$D$957<>"")*(ST!$J$4:$J$957="CTA"))} -> 0 | K121: {=SUMPRODUCT((ST!$C$4:$C$965<>"")*(ST!$D$4:$D$965<>"")*((ST!$I$4:$I$965=0)*(ST!$Q$4:$Q$965<>"")+(ST!$I$4:$I$965=1)*(ST!$V$4:$V$965<>"")+(ST!$I$4:$I$965=2)*(ST!$AA$4:$AA$965<>"")))} -> 0 | L121: {=SUMPRODUCT((ST!$C$4:$C$957<>"")*(ST!$D$4:$D$957<>"")*(ST!$J$4:$J$957="AUR"))} -> 0 | M121: {=SUMPRODUCT((ST!$C$4:$C$965<>"")*(ST!$D$4:$D$965<>"")*((ST!$I$4:$I$965=0)*(ST!$R$4:$R$965<>"")+(ST!$I$4:$I$965=1)*(ST!$W$4:$W$965<>"")+(ST!$I$4:$I$965=2)*(ST!$AB$4:$AB$965<>"")))} -> 0 | N121: {=SUMPRODUCT((ST!$C$4:$C$957<>"")*(ST!$D$4:$D$957<>"")*(ST!$J$4:$J$957="STT"))} -> 0
C122: Architectural | D122: =B7 -> 83 | E122: =SUMPRODUCT((AR!$C$4:$C$964<>"")*(AR!$D$4:$D$964<>"")*((AR!$K$4:$K$964="A")+(AR!$K$4:$K$964="B")+(AR!$K$4:$K$964="PENDING"))) -> 25 | F122: =SUMPRODUCT((AR!$C$4:$C$964<>"")*(AR!$D$4:$D$964<>"")*((AR!$K$4:$K$964="A")+(AR!$K$4:$K$964="B"))) -> 14 | G122: =SUMPRODUCT((AR!$C$4:$C$964<>"")*(AR!$D$4:$D$964<>"")*(AR!$K$4:$K$964="C")) -> 1 | H122: =SUMPRODUCT((AR!$C$4:$C$964<>"")*(AR!$D$4:$D$964<>"")*((AR!$K$4:$K$964="C")+(AR!$K$4:$K$964=""))) -> 58 | I122: {=SUMPRODUCT((AR!$C$4:$C$972<>"")*(AR!$D$4:$D$972<>"")*((AR!$I$4:$I$972=0)*(AR!$P$4:$P$972<>"")+(AR!$I$4:$I$972=1)*(AR!$U$4:$U$972<>"")+(AR!$I$4:$I$972=2)*(AR!$Z$4:$Z$972<>"")))} -> 26 | J122: {=SUMPRODUCT((AR!$C$4:$C$964<>"")*(AR!$D$4:$D$964<>"")*(AR!$J$4:$J$964="CTA"))} -> 0 | K122: {=SUMPRODUCT((AR!$C$4:$C$972<>"")*(AR!$D$4:$D$972<>"")*((AR!$I$4:$I$972=0)*(AR!$Q$4:$Q$972<>"")+(AR!$I$4:$I$972=1)*(AR!$V$4:$V$972<>"")+(AR!$I$4:$I$972=2)*(AR!$AA$4:$AA$972<>"")))} -> 24 | L122: =SUMPRODUCT((AR!$C$4:$C$964<>"")*(AR!$D$4:$D$964<>"")*(AR!$J$4:$J$964="AUR")) -> 2 | M122: {=SUMPRODUCT((AR!$C$4:$C$972<>"")*(AR!$D$4:$D$972<>"")*((AR!$I$4:$I$972=0)*(AR!$R$4:$R$972<>"")+(AR!$I$4:$I$972=1)*(AR!$W$4:$W$972<>"")+(AR!$I$4:$I$972=2)*(AR!$AB$4:$AB$972<>"")))} -> 15 | N122: {=SUMPRODUCT((AR!$C$4:$C$964<>"")*(AR!$D$4:$D$964<>"")*(AR!$J$4:$J$964="STT"))} -> 9
C123: AR & ST | D123: =SUM(D121:D122) -> 102 | E123: =SUM(E121:E122) -> 25 | F123: =SUM(F121:F122) -> 14 | G123: =SUM(G121:G122) -> 1 | H123: =SUM(H121:H122) -> 77 | I123: =SUM(I121:I122) -> 26 | J123: =SUM(J121:J122) -> 0 | K123: =SUM(K121:K122) -> 24 | ... N123: =SUM(N121:N122) -> 9
C124: Mechanical | D124: =B8 -> 52 | E124: {=SUMPRODUCT((ME!$C$4:$C$957<>"")*(ME!$D$4:$D$957<>"")*((ME!$K$4:$K$957="A")+(ME!$K$4:$K$957="B")+(ME!$K$4:$K$957="PENDING")))} -> 4 | F124: {=SUMPRODUCT((ME!$C$4:$C$957<>"")*(ME!$D$4:$D$957<>"")*((ME!$K$4:$K$957="A")+(ME!$K$4:$K$957="B")))} -> 0 | G124: {=SUMPRODUCT((ME!$C$4:$C$957<>"")*(ME!$D$4:$D$957<>"")*(ME!$K$4:$K$957="C"))} -> 1 | H124: {=SUMPRODUCT((ME!$C$4:$C$957<>"")*(ME!$D$4:$D$957<>"")*((ME!$K$4:$K$957="C")+(ME!$K$4:$K$957="")))} -> 48 | I124: {=SUMPRODUCT((ME!$C$4:$C$965<>"")*(ME!$D$4:$D$965<>"")*((ME!$I$4:$I$965=0)*(ME!$P$4:$P$965<>"")+(ME!$I$4:$I$965=1)*(ME!$U$4:$U$965<>"")+(ME!$I$4:$I$965=2)*(ME!$Z$4:$Z$965<>"")))} -> 5 | J124: {=SUMPRODUCT((ME!$C$4:$C$957<>"")*(ME!$D$4:$D$957<>"")*(ME!$J$4:$J$957="CTA"))} -> 0 | K124: {=SUMPRODUCT((ME!$C$4:$C$965<>"")*(ME!$D$4:$D$965<>"")*((ME!$I$4:$I$965=0)*(ME!$Q$4:$Q$965<>"")+(ME!$I$4:$I$965=1)*(ME!$V$4:$V$965<>"")+(ME!$I$4:$I$965=2)*(ME!$AA$4:$AA$965<>"")))} -> 0 | L124: {=SUMPRODUCT((ME!$C$4:$C$957<>"")*(ME!$D$4:$D$957<>"")*(ME!$J$4:$J$957="AUR"))} -> 4 | M124: {=SUMPRODUCT((ME!$C$4:$C$965<>"")*(ME!$D$4:$D$965<>"")*((ME!$I$4:$I$965=0)*(ME!$R$4:$R$965<>"")+(ME!$I$4:$I$965=1)*(ME!$W$4:$W$965<>"")+(ME!$I$4:$I$965=2)*(ME!$AB$4:$AB$965<>"")))} -> 0 | N124: {=SUMPRODUCT((ME!$C$4:$C$957<>"")*(ME!$D$4:$D$957<>"")*(ME!$J$4:$J$957="MET"))} -> 0
C125: Fire | D125: =B9 -> 40 | E125: {=SUMPRODUCT((FI!$C$4:$C$955<>"")*(FI!$D$4:$D$955<>"")*((FI!$K$4:$K$955="A")+(FI!$K$4:$K$955="B")+(FI!$K$4:$K$955="PENDING")))} -> 11 | F125: {=SUMPRODUCT((FI!$C$4:$C$955<>"")*(FI!$D$4:$D$955<>"")*((FI!$K$4:$K$955="A")+(FI!$K$4:$K$955="B")))} -> 0 | G125: {=SUMPRODUCT((FI!$C$4:$C$955<>"")*(FI!$D$4:$D$955<>"")*(FI!$K$4:$K$955="C"))} -> 0 | H125: {=SUMPRODUCT((FI!$C$4:$C$955<>"")*(FI!$D$4:$D$955<>"")*((FI!$K$4:$K$955="C")+(FI!$K$4:$K$955="")))} -> 29 | I125: {=SUMPRODUCT((FI!$C$4:$C$963<>"")*(FI!$D$4:$D$963<>"")*((FI!$I$4:$I$963=0)*(FI!$P$4:$P$963<>"")+(FI!$I$4:$I$963=1)*(FI!$U$4:$U$963<>"")+(FI!$I$4:$I$963=2)*(FI!$Z$4:$Z$963<>"")))} -> 7 | J125: {=SUMPRODUCT((FI!$C$4:$C$955<>"")*(FI!$D$4:$D$955<>"")*(FI!$J$4:$J$955="CTA"))} -> 4 | K125: {=SUMPRODUCT((FI!$C$4:$C$963<>"")*(FI!$D$4:$D$963<>"")*((FI!$I$4:$I$963=0)*(FI!$Q$4:$Q$963<>"")+(FI!$I$4:$I$963=1)*(FI!$V$4:$V$963<>"")+(FI!$I$4:$I$963=2)*(FI!$AA$4:$AA$963<>"")))} -> 0 | L125: {=SUMPRODUCT((FI!$C$4:$C$955<>"")*(FI!$D$4:$D$955<>"")*(FI!$J$4:$J$955="AUR"))} -> 7 | M125: {=SUMPRODUCT((FI!$C$4:$C$963<>"")*(FI!$D$4:$D$963<>"")*((FI!$I$4:$I$963=0)*(FI!$R$4:$R$963<>"")+(FI!$I$4:$I$963=1)*(FI!$W$4:$W$963<>"")+(FI!$I$4:$I$963=2)*(FI!$AB$4:$AB$963<>"")))} -> 0 | N125: {=SUMPRODUCT((FI!$C$4:$C$955<>"")*(FI!$D$4:$D$955<>"")*(FI!$J$4:$J$955="FIT"))} -> 0
C126: Hydraulics | D126: =B10 -> 31 | E126: {=SUMPRODUCT((HY!$C$4:$C$955<>"")*(HY!$D$4:$D$955<>"")*((HY!$K$4:$K$955="A")+(HY!$K$4:$K$955="B")+(HY!$K$4:$K$955="PENDING")))} -> 11 | F126: {=SUMPRODUCT((HY!$C$4:$C$955<>"")*(HY!$D$4:$D$955<>"")*((HY!$K$4:$K$955="A")+(HY!$K$4:$K$955="B")))} -> 0 | G126: {=SUMPRODUCT((HY!$C$4:$C$955<>"")*(HY!$D$4:$D$955<>"")*(HY!$K$4:$K$955="C"))} -> 0 | H126: {=SUMPRODUCT((HY!$C$4:$C$955<>"")*(HY!$D$4:$D$955<>"")*((HY!$K$4:$K$955="C")+(HY!$K$4:$K$955="")))} -> 21 | I126: {=SUMPRODUCT((HY!$C$4:$C$963<>"")*(HY!$D$4:$D$963<>"")*((HY!$I$4:$I$963=0)*(HY!$P$4:$P$963<>"")+(HY!$I$4:$I$963=1)*(HY!$U$4:$U$963<>"")+(HY!$I$4:$I$963=2)*(HY!$Z$4:$Z$963<>"")))} -> 11 | J126: {=SUMPRODUCT((HY!$C$4:$C$955<>"")*(HY!$D$4:$D$955<>"")*(HY!$J$4:$J$955="CTA"))} -> 0 | K126: {=SUMPRODUCT((HY!$C$4:$C$963<>"")*(HY!$D$4:$D$963<>"")*((HY!$I$4:$I$963=0)*(HY!$Q$4:$Q$963<>"")+(HY!$I$4:$I$963=1)*(HY!$V$4:$V$963<>"")+(HY!$I$4:$I$963=2)*(HY!$AA$4:$AA$963<>"")))} -> 0 | L126: {=SUMPRODUCT((HY!$C$4:$C$955<>"")*(HY!$D$4:$D$955<>"")*(HY!$J$4:$J$955="AUR"))} -> 11 | M126: {=SUMPRODUCT((HY!$C$4:$C$963<>"")*(HY!$D$4:$D$963<>"")*((HY!$I$4:$I$963=0)*(HY!$R$4:$R$963<>"")+(HY!$I$4:$I$963=1)*(HY!$W$4:$W$963<>"")+(HY!$I$4:$I$963=2)*(HY!$AB$4:$AB$963<>"")))} -> 0 | N126: {=SUMPRODUCT((HY!$C$4:$C$955<>"")*(HY!$D$4:$D$955<>"")*(HY!$J$4:$J$955="HYT"))} -> 0
C127: Electrical & Comms | D127: =B11 -> 258 | E127: {=SUMPRODUCT((EL!$C$4:$C$964<>"")*(EL!$D$4:$D$964<>"")*((EL!$K$4:$K$964="A")+(EL!$K$4:$K$964="B")+(EL!$K$4:$K$964="PENDING")))} -> 0 | F127: {=SUMPRODUCT((EL!$C$4:$C$964<>"")*(EL!$D$4:$D$964<>"")*((EL!$K$4:$K$964="A")+(EL!$K$4:$K$964="B")))} -> 0 | G127: {=SUMPRODUCT((EL!$C$4:$C$964<>"")*(EL!$D$4:$D$964<>"")*(EL!$K$4:$K$964="C"))} -> 0 | H127: {=SUMPRODUCT((EL!$C$4:$C$964<>"")*(EL!$D$4:$D$964<>"")*((EL!$K$4:$K$964="C")+(EL!$K$4:$K$964="")))} -> 188 | I127: {=SUMPRODUCT((EL!$C$4:$C$972<>"")*(EL!$D$4:$D$972<>"")*((EL!$I$4:$I$972=0)*(EL!$P$4:$P$972<>"")+(EL!$I$4:$I$972=1)*(EL!$U$4:$U$972<>"")+(EL!$I$4:$I$972=2)*(EL!$Z$4:$Z$972<>"")))} -> 42 | J127: {=SUMPRODUCT((EL!$C$4:$C$964<>"")*(EL!$D$4:$D$964<>"")*(EL!$J$4:$J$964="CTA"))} -> #VALUE! | K127: {=SUMPRODUCT((EL!$C$4:$C$972<>"")*(EL!$D$4:$D$972<>"")*((EL!$I$4:$I$972=0)*(EL!$Q$4:$Q$972<>"")+(EL!$I$4:$I$972=1)*(EL!$V$4:$V$972<>"")+(EL!$I$4:$I$972=2)*(EL!$AA$4:$AA$972<>"")))} -> 1 | L127: {=SUMPRODUCT((EL!$C$4:$C$964<>"")*(EL!$D$4:$D$964<>"")*(EL!$J$4:$J$964="AUR"))} -> #VALUE! | M127: {=SUMPRODUCT((EL!$C$4:$C$972<>"")*(EL!$D$4:$D$972<>"")*((EL!$I$4:$I$972=0)*(EL!$R$4:$R$972<>"")+(EL!$I$4:$I$972=1)*(EL!$W$4:$W$972<>"")+(EL!$I$4:$I$972=2)*(EL!$AB$4:$AB$972<>"")))} -> 0 | N127: {=SUMPRODUCT((EL!$C$4:$C$964<>"")*(EL!$D$4:$D$964<>"")*(EL!$J$4:$J$964="ELT"))} -> #VALUE!
C128: CSD | D128: =B12 -> 27 | E128: {=SUMPRODUCT((CSD!$C$4:$C$959<>"")*(CSD!$D$4:$D$959<>"")*((CSD!$K$4:$K$959="A")+(CSD!$K$4:$K$959="B")+(CSD!$K$4:$K$959="PENDING")))} -> 13 | F128: {=SUMPRODUCT((CSD!$C$4:$C$959<>"")*(CSD!$D$4:$D$959<>"")*((CSD!$K$4:$K$959="A")+(CSD!$K$4:$K$959="B")))} -> 0 | G128: {=SUMPRODUCT((CSD!$C$4:$C$959<>"")*(CSD!$D$4:$D$959<>"")*(CSD!$K$4:$K$959="C"))} -> 0 | H128: {=SUMPRODUCT((CSD!$C$4:$C$959<>"")*(CSD!$D$4:$D$959<>"")*((CSD!$K$4:$K$959="C")+(CSD!$K$4:$K$959="")))} -> 14 | I128: {=SUMPRODUCT((CSD!$C$4:$C$967<>"")*(CSD!$D$4:$D$967<>"")*((CSD!$I$4:$I$967=0)*(CSD!$P$4:$P$967<>"")+(CSD!$I$4:$I$967=1)*(CSD!$U$4:$U$967<>"")+(CSD!$I$4:$I$967=2)*(CSD!$Z$4:$Z$967<>"")))} -> 0 | J128: {=SUMPRODUCT((CSD!$C$4:$C$959<>"")*(CSD!$D$4:$D$959<>"")*(CSD!$J$4:$J$959="CTA"))} -> 13 | K128: {=SUMPRODUCT((CSD!$C$4:$C$967<>"")*(CSD!$D$4:$D$967<>"")*((CSD!$I$4:$I$967=0)*(CSD!$Q$4:$Q$967<>"")+(CSD!$I$4:$I$967=1)*(CSD!$V$4:$V$967<>"")+(CSD!$I$4:$I$967=2)*(CSD!$AA$4:$AA$967<>"")))} -> 0 | L128: {=SUMPRODUCT((CSD!$C$4:$C$959<>"")*(CSD!$D$4:$D$959<>"")*(CSD!$J$4:$J$959="AUR"))} -> 0 | M128: {=SUMPRODUCT((CSD!$C$4:$C$967<>"")*(CSD!$D$4:$D$967<>"")*((CSD!$I$4:$I$967=0)*(CSD!$R$4:$R$967<>"")+(CSD!$I$4:$I$967=1)*(CSD!$W$4:$W$967<>"")+(CSD!$I$4:$I$967=2)*(CSD!$AB$4:$AB$967<>"")))} -> 0 | N128: {=SUMPRODUCT((CSD!$C$4:$C$959<>"")*(CSD!$D$4:$D$959<>"")*(CSD!$J$4:$J$959="CSDT"))} -> 0
C129: Overall | D129: =SUM(D123:D128) -> 510 | E129: =SUM(E123:E128) -> 64 | F129: =SUM(F123:F128) -> 14 | G129: =SUM(G123:G128) -> 2 | H129: =SUM(H123:H128) -> 377 | I129: =SUM(I123:I128) -> 91 | J129: =SUM(J123:J128) -> #VALUE! | K129: =SUM(K123:K128) -> 25 | ... N129: =SUM(N123:N128) -> #VALUE!
C130: AR & ST | E130: =E123/$D123 -> 0.24509804 | F130: =F123/$D123 -> 0.1372549 | G130: =G123/$D123 -> 0.0098039216 | H130: =H123/$D123 -> 0.75490196 | I130: =I123/$D123 -> 0.25490196 | J130: =J123/$D123 -> 0 | K130: =K123/$D123 -> 0.23529412 | L130: =L123/$D123 -> 0.019607843 | ... N130: =N123/$D123 -> 0.088235294
C131: Mechanical | E131: =E124/$D124 -> 0.076923077 | F131: =F124/$D124 -> 0 | G131: =G124/$D124 -> 0.019230769 | H131: =H124/$D124 -> 0.92307692 | I131: =I124/$D124 -> 0.096153846 | J131: =J124/$D124 -> 0 | K131: =K124/$D124 -> 0 | L131: =L124/$D124 -> 0.076923077 | ... N131: =N124/$D124 -> 0
C132: Fire | E132: =E125/$D125 -> 0.275 | F132: =F125/$D125 -> 0 | G132: =G125/$D125 -> 0 | H132: =H125/$D125 -> 0.725 | I132: =I125/$D125 -> 0.175 | J132: =J125/$D125 -> 0.1 | K132: =K125/$D125 -> 0 | L132: =L125/$D125 -> 0.175 | ... N132: =N125/$D125 -> 0
C133: Hydraulics | E133: =E126/$D126 -> 0.35483871 | F133: =F126/$D126 -> 0 | G133: =G126/$D126 -> 0 | H133: =H126/$D126 -> 0.67741935 | I133: =I126/$D126 -> 0.35483871 | J133: =J126/$D126 -> 0 | K133: =K126/$D126 -> 0 | L133: =L126/$D126 -> 0.35483871 | ... N133: =N126/$D126 -> 0
C134: Electrical & Comms | E134: =E127/$D127 -> 0 | F134: =F127/$D127 -> 0 | G134: =G127/$D127 -> 0 | H134: =H127/$D127 -> 0.72868217 | I134: =I127/$D127 -> 0.1627907 | J134: =J127/$D127 -> #VALUE! | K134: =K127/$D127 -> 0.003875969 | L134: =L127/$D127 -> #VALUE! | ... N134: =N127/$D127 -> #VALUE!
C135: CSD | E135: =E128/$D128 -> 0.48148148 | F135: =F128/$D128 -> 0 | G135: =G128/$D128 -> 0 | H135: =H128/$D128 -> 0.51851852 | I135: =I128/$D128 -> 0 | J135: =J128/$D128 -> 0.48148148 | K135: =K128/$D128 -> 0 | L135: =L128/$D128 -> 0 | ... N135: =N128/$D128 -> 0
C136: Overall | E136: =E129/$D129 -> 0.1254902 | F136: =F129/$D129 -> 0.02745098 | G136: =G129/$D129 -> 0.0039215686 | H136: =H129/$D129 -> 0.73921569 | I136: =I129/$D129 -> 0.17843137 | J136: =J129/$D129 -> #VALUE! | K136: =K129/$D129 -> 0.049019608 | L136: =L129/$D129 -> #VALUE! | ... N136: =N129/$D129 -> #VALUE!
E138: Do not tounch
F486: 45696
F487: 45696
F524: 45696

Sheet Summary
A2: Shop Drawing Approval Summary
B4: Structural
B5: w/e | C5: Total Expected | D5: Planned Submission | E5: Actual Submitted | F5: Status
F6: Under Review | I6: A | J6: B | K6: C
F7: CTA | G7: AUR | H7: STT
B8: 46027 | C8: {=SUMPRODUCT((ST!$C$4:$C$504<>"")*(ST!$D$4:$D$504<>"")*((ST!$F$4:$F$504<=B8)+(ST!$F$4:$F$504>B8)))} -> 19 | D8: {=SUMPRODUCT((ST!$C$4:$C$504<>"")*(ST!$D$4:$D$504<>"")*(ST!$F$4:$F$504<=B8))} -> 1 | E8: {=SUMPRODUCT((ST!$C$4:$C$504<>"")*(ST!$D$4:$D$504<>"")*(ST!$G$4:$G$504<>"")*(ST!$G$4:$G$504<=B8))} -> 0 | F8: {=SUMPRODUCT((ST!$C$4:$C$504<>"")*(ST!$D$4:$D$504<>"")*(ST!$G$4:$G$504<=$B8)*(ST!$K$4:$K$504="Pending")*(ST!$J$4:$J$504="CTA"))} -> 0 | G8: {=SUMPRODUCT((ST!$C$4:$C$504<>"")*(ST!$D$4:$D$504<>"")*(ST!$G$4:$G$504<=$B8)*(ST!$K$4:$K$504="Pending")*(ST!$J$4:$J$504="AUR"))} -> 0 | H8: {=SUMPRODUCT((ST!$C$4:$C$504<>"")*(ST!$D$4:$D$504<>"")*(ST!$G$4:$G$504<=$B8)*(ST!$K$4:$K$504="Pending")*(ST!$J$4:$J$504="STT"))} -> 0 | I8: {=SUMPRODUCT((ST!$C$4:$C$504<>"")*(ST!$D$4:$D$504<>"")*(ST!$G$4:$G$504<=$B8)*(ST!$K$4:$K$504="A"))} -> 0 | J8: {=SUMPRODUCT((ST!$C$4:$C$504<>"")*(ST!$D$4:$D$504<>"")*(ST!$G$4:$G$504<=$B8)*(ST!$K$4:$K$504="B"))} -> 0 | K8: {=SUMPRODUCT((ST!$C$4:$C$504<>"")*(ST!$D$4:$D$504<>"")*(ST!$G$4:$G$504<=$B8)*(ST!$K$4:$K$504="C"))} -> 0
B9: =B8+7 -> 46034 | C9: {=SUMPRODUCT((ST!$C$4:$C$504<>"")*(ST!$D$4:$D$504<>"")*((ST!$F$4:$F$504<=B9)+(ST!$F$4:$F$504>B9)))} -> 19 | D9: {=SUMPRODUCT((ST!$C$4:$C$504<>"")*(ST!$D$4:$D$504<>"")*(ST!$F$4:$F$504<=B9))} -> 1 | E9: {=SUMPRODUCT((ST!$C$4:$C$504<>"")*(ST!$D$4:$D$504<>"")*(ST!$G$4:$G$504<>"")*(ST!$G$4:$G$504<=B9))} -> 0 | F9: {=SUMPRODUCT((ST!$C$4:$C$504<>"")*(ST!$D$4:$D$504<>"")*(ST!$G$4:$G$504<=$B9)*(ST!$K$4:$K$504="Pending")*(ST!$J$4:$J$504="CTA"))} -> 0 | G9: {=SUMPRODUCT((ST!$C$4:$C$504<>"")*(ST!$D$4:$D$504<>"")*(ST!$G$4:$G$504<=$B9)*(ST!$K$4:$K$504="Pending")*(ST!$J$4:$J$504="AUR"))} -> 0 | H9: {=SUMPRODUCT((ST!$C$4:$C$504<>"")*(ST!$D$4:$D$504<>"")*(ST!$G$4:$G$504<=$B9)*(ST!$K$4:$K$504="Pending")*(ST!$J$4:$J$504="STT"))} -> 0 | I9: {=SUMPRODUCT((ST!$C$4:$C$504<>"")*(ST!$D$4:$D$504<>"")*(ST!$G$4:$G$504<=$B9)*(ST!$K$4:$K$504="A"))} -> 0 | J9: {=SUMPRODUCT((ST!$C$4:$C$504<>"")*(ST!$D$4:$D$504<>"")*(ST!$G$4:$G$504<=$B9)*(ST!$K$4:$K$504="B"))} -> 0 | K9: {=SUMPRODUCT((ST!$C$4:$C$504<>"")*(ST!$D$4:$D$504<>"")*(ST!$G$4:$G$504<=$B9)*(ST!$K$4:$K$504="C"))} -> 0
B10: =B9+7 -> 46041 | C10: {=SUMPRODUCT((ST!$C$4:$C$504<>"")*(ST!$D$4:$D$504<>"")*((ST!$F$4:$F$504<=B10)+(ST!$F$4:$F$504>B10)))} -> 19 | D10: {=SUMPRODUCT((ST!$C$4:$C$504<>"")*(ST!$D$4:$D$504<>"")*(ST!$F$4:$F$504<=B10))} -> 1 | E10: {=SUMPRODUCT((ST!$C$4:$C$504<>"")*(ST!$D$4:$D$504<>"")*(ST!$G$4:$G$504<>"")*(ST!$G$4:$G$504<=B10))} -> 0 | F10: {=SUMPRODUCT((ST!$C$4:$C$504<>"")*(ST!$D$4:$D$504<>"")*(ST!$G$4:$G$504<=$B10)*(ST!$K$4:$K$504="Pending")*(ST!$J$4:$J$504="CTA"))} -> 0 | G10: {=SUMPRODUCT((ST!$C$4:$C$504<>"")*(ST!$D$4:$D$504<>"")*(ST!$G$4:$G$504<=$B10)*(ST!$K$4:$K$504="Pending")*(ST!$J$4:$J$504="AUR"))} -> 0 | H10: {=SUMPRODUCT((ST!$C$4:$C$504<>"")*(ST!$D$4:$D$504<>"")*(ST!$G$4:$G$504<=$B10)*(ST!$K$4:$K$504="Pending")*(ST!$J$4:$J$504="STT"))} -> 0 | I10: {=SUMPRODUCT((ST!$C$4:$C$504<>"")*(ST!$D$4:$D$504<>"")*(ST!$G$4:$G$504<=$B10)*(ST!$K$4:$K$504="A"))} -> 0 | J10: {=SUMPRODUCT((ST!$C$4:$C$504<>"")*(ST!$D$4:$D$504<>"")*(ST!$G$4:$G$504<=$B10)*(ST!$K$4:$K$504="B"))} -> 0 | K10: {=SUMPRODUCT((ST!$C$4:$C$504<>"")*(ST!$D$4:$D$504<>"")*(ST!$G$4:$G$504<=$B10)*(ST!$K$4:$K$504="C"))} -> 0
B11: =B10+7 -> 46048 | C11: {=SUMPRODUCT((ST!$C$4:$C$504<>"")*(ST!$D$4:$D$504<>"")*((ST!$F$4:$F$504<=B11)+(ST!$F$4:$F$504>B11)))} -> 19 | D11: {=SUMPRODUCT((ST!$C$4:$C$504<>"")*(ST!$D$4:$D$504<>"")*(ST!$F$4:$F$504<=B11))} -> 1 | E11: {=SUMPRODUCT((ST!$C$4:$C$504<>"")*(ST!$D$4:$D$504<>"")*(ST!$G$4:$G$504<>"")*(ST!$G$4:$G$504<=B11))} -> 0 | F11: {=SUMPRODUCT((ST!$C$4:$C$504<>"")*(ST!$D$4:$D$504<>"")*(ST!$G$4:$G$504<=$B11)*(ST!$K$4:$K$504="Pending")*(ST!$J$4:$J$504="CTA"))} -> 0 | G11: {=SUMPRODUCT((ST!$C$4:$C$504<>"")*(ST!$D$4:$D$504<>"")*(ST!$G$4:$G$504<=$B11)*(ST!$K$4:$K$504="Pending")*(ST!$J$4:$J$504="AUR"))} -> 0 | H11: {=SUMPRODUCT((ST!$C$4:$C$504<>"")*(ST!$D$4:$D$504<>"")*(ST!$G$4:$G$504<=$B11)*(ST!$K$4:$K$504="Pending")*(ST!$J$4:$J$504="STT"))} -> 0 | I11: {=SUMPRODUCT((ST!$C$4:$C$504<>"")*(ST!$D$4:$D$504<>"")*(ST!$G$4:$G$504<=$B11)*(ST!$K$4:$K$504="A"))} -> 0 | J11: {=SUMPRODUCT((ST!$C$4:$C$504<>"")*(ST!$D$4:$D$504<>"")*(ST!$G$4:$G$504<=$B11)*(ST!$K$4:$K$504="B"))} -> 0 | K11: {=SUMPRODUCT((ST!$C$4:$C$504<>"")*(ST!$D$4:$D$504<>"")*(ST!$G$4:$G$504<=$B11)*(ST!$K$4:$K$504="C"))} -> 0
B12: =B11+7 -> 46055 | C12: {=SUMPRODUCT((ST!$C$4:$C$504<>"")*(ST!$D$4:$D$504<>"")*((ST!$F$4:$F$504<=B12)+(ST!$F$4:$F$504>B12)))} -> 19 | D12: {=SUMPRODUCT((ST!$C$4:$C$504<>"")*(ST!$D$4:$D$504<>"")*(ST!$F$4:$F$504<=B12))} -> 1 | E12: {=SUMPRODUCT((ST!$C$4:$C$504<>"")*(ST!$D$4:$D$504<>"")*(ST!$G$4:$G$504<>"")*(ST!$G$4:$G$504<=B12))} -> 0 | F12: {=SUMPRODUCT((ST!$C$4:$C$504<>"")*(ST!$D$4:$D$504<>"")*(ST!$G$4:$G$504<=$B12)*(ST!$K$4:$K$504="Pending")*(ST!$J$4:$J$504="CTA"))} -> 0 | G12: {=SUMPRODUCT((ST!$C$4:$C$504<>"")*(ST!$D$4:$D$504<>"")*(ST!$G$4:$G$504<=$B12)*(ST!$K$4:$K$504="Pending")*(ST!$J$4:$J$504="AUR"))} -> 0 | H12: {=SUMPRODUCT((ST!$C$4:$C$504<>"")*(ST!$D$4:$D$504<>"")*(ST!$G$4:$G$504<=$B12)*(ST!$K$4:$K$504="Pending")*(ST!$J$4:$J$504="STT"))} -> 0 | I12: {=SUMPRODUCT((ST!$C$4:$C$504<>"")*(ST!$D$4:$D$504<>"")*(ST!$G$4:$G$504<=$B12)*(ST!$K$4:$K$504="A"))} -> 0 | J12: {=SUMPRODUCT((ST!$C$4:$C$504<>"")*(ST!$D$4:$D$504<>"")*(ST!$G$4:$G$504<=$B12)*(ST!$K$4:$K$504="B"))} -> 0 | K12: {=SUMPRODUCT((ST!$C$4:$C$504<>"")*(ST!$D$4:$D$504<>"")*(ST!$G$4:$G$504<=$B12)*(ST!$K$4:$K$504="C"))} -> 0
B22: Architectural
B23: w/e | C23: Total Expected | D23: Planned Submission | E23: Actual Submitted | F23: Status
F24: Under Review | I24: A | J24: B | K24: C
F25: CTA | G25: AUR | H25: STT
B26: =B8 -> 46027 | C26: {=SUMPRODUCT((AR!$C$4:$C$507<>"")*(AR!$D$4:$D$507<>"")*((AR!$F$4:$F$507<=B26)+(AR!$F$4:$F$507>B26)))} -> 83 | D26: {=SUMPRODUCT((AR!$C$4:$C$507<>"")*(AR!$D$4:$D$507<>"")*(AR!$F$4:$F$507<=B26))} -> 9 | E26: {=SUMPRODUCT((AR!$C$4:$C$507<>"")*(AR!$D$4:$D$507<>"")*(AR!$G$4:$G$507<>"")*(AR!$G$4:$G$507<=B26))} -> 0 | F26: {=SUMPRODUCT((AR!$C$4:$C$507<>"")*(AR!$D$4:$D$507<>"")*(AR!$G$4:$G$507<=$B26)*(AR!$K$4:$K$507="Pending")*(AR!$J$4:$J$507="CTA"))} -> 0 | G26: {=SUMPRODUCT((AR!$C$4:$C$507<>"")*(AR!$D$4:$D$507<>"")*(AR!$G$4:$G$507<=$B26)*(AR!$K$4:$K$507="Pending")*(AR!$J$4:$J$507="AUR"))} -> 0 | H26: {=SUMPRODUCT((AR!$C$4:$C$507<>"")*(AR!$D$4:$D$507<>"")*(AR!$G$4:$G$507<=$B26)*(AR!$K$4:$K$507="Pending")*(AR!$J$4:$J$507="STT"))} -> 0 | I26: {=SUMPRODUCT((AR!$C$4:$C$507<>"")*(AR!$D$4:$D$507<>"")*(AR!$G$4:$G$507<=$B26)*(AR!$K$4:$K$507="A"))} -> 0 | J26: {=SUMPRODUCT((AR!$C$4:$C$507<>"")*(AR!$D$4:$D$507<>"")*(AR!$G$4:$G$507<=$B26)*(AR!$K$4:$K$507="B"))} -> 0 | K26: {=SUMPRODUCT((AR!$C$4:$C$507<>"")*(AR!$D$4:$D$507<>"")*(AR!$G$4:$G$507<=$B26)*(AR!$K$4:$K$507="C"))} -> 0
B27: =B9 -> 46034 | C27: {=SUMPRODUCT((AR!$C$4:$C$507<>"")*(AR!$D$4:$D$507<>"")*((AR!$F$4:$F$507<=B27)+(AR!$F$4:$F$507>B27)))} -> 83 | D27: {=SUMPRODUCT((AR!$C$4:$C$507<>"")*(AR!$D$4:$D$507<>"")*(AR!$F$4:$F$507<=B27))} -> 12 | E27: {=SUMPRODUCT((AR!$C$4:$C$507<>"")*(AR!$D$4:$D$507<>"")*(AR!$G$4:$G$507<>"")*(AR!$G$4:$G$507<=B27))} -> 1 | F27: {=SUMPRODUCT((AR!$C$4:$C$507<>"")*(AR!$D$4:$D$507<>"")*(AR!$G$4:$G$507<=$B27)*(AR!$K$4:$K$507="Pending")*(AR!$J$4:$J$507="CTA"))} -> 0 | G27: {=SUMPRODUCT((AR!$C$4:$C$507<>"")*(AR!$D$4:$D$507<>"")*(AR!$G$4:$G$507<=$B27)*(AR!$K$4:$K$507="Pending")*(AR!$J$4:$J$507="AUR"))} -> 0 | H27: {=SUMPRODUCT((AR!$C$4:$C$507<>"")*(AR!$D$4:$D$507<>"")*(AR!$G$4:$G$507<=$B27)*(AR!$K$4:$K$507="Pending")*(AR!$J$4:$J$507="STT"))} -> 0 | I27: {=SUMPRODUCT((AR!$C$4:$C$507<>"")*(AR!$D$4:$D$507<>"")*(AR!$G$4:$G$507<=$B27)*(AR!$K$4:$K$507="A"))} -> 0 | J27: {=SUMPRODUCT((AR!$C$4:$C$507<>"")*(AR!$D$4:$D$507<>"")*(AR!$G$4:$G$507<=$B27)*(AR!$K$4:$K$507="B"))} -> 1 | K27: {=SUMPRODUCT((AR!$C$4:$C$507<>"")*(AR!$D$4:$D$507<>"")*(AR!$G$4:$G$507<=$B27)*(AR!$K$4:$K$507="C"))} -> 0
B28: =B10 -> 46041 | C28: {=SUMPRODUCT((AR!$C$4:$C$507<>"")*(AR!$D$4:$D$507<>"")*((AR!$F$4:$F$507<=B28)+(AR!$F$4:$F$507>B28)))} -> 83 | D28: {=SUMPRODUCT((AR!$C$4:$C$507<>"")*(AR!$D$4:$D$507<>"")*(AR!$F$4:$F$507<=B28))} -> 17 | E28: {=SUMPRODUCT((AR!$C$4:$C$507<>"")*(AR!$D$4:$D$507<>"")*(AR!$G$4:$G$507<>"")*(AR!$G$4:$G$507<=B28))} -> 3 | F28: {=SUMPRODUCT((AR!$C$4:$C$507<>"")*(AR!$D$4:$D$507<>"")*(AR!$G$4:$G$507<=$B28)*(AR!$K$4:$K$507="Pending")*(AR!$J$4:$J$507="CTA"))} -> 0 | G28: {=SUMPRODUCT((AR!$C$4:$C$507<>"")*(AR!$D$4:$D$507<>"")*(AR!$G$4:$G$507<=$B28)*(AR!$K$4:$K$507="Pending")*(AR!$J$4:$J$507="AUR"))} -> 1 | H28: {=SUMPRODUCT((AR!$C$4:$C$507<>"")*(AR!$D$4:$D$507<>"")*(AR!$G$4:$G$507<=$B28)*(AR!$K$4:$K$507="Pending")*(AR!$J$4:$J$507="STT"))} -> 0 | I28: {=SUMPRODUCT((AR!$C$4:$C$507<>"")*(AR!$D$4:$D$507<>"")*(AR!$G$4:$G$507<=$B28)*(AR!$K$4:$K$507="A"))} -> 0 | J28: {=SUMPRODUCT((AR!$C$4:$C$507<>"")*(AR!$D$4:$D$507<>"")*(AR!$G$4:$G$507<=$B28)*(AR!$K$4:$K$507="B"))} -> 1 | K28: {=SUMPRODUCT((AR!$C$4:$C$507<>"")*(AR!$D$4:$D$507<>"")*(AR!$G$4:$G$507<=$B28)*(AR!$K$4:$K$507="C"))} -> 1
B29: =B11 -> 46048 | C29: {=SUMPRODUCT((AR!$C$4:$C$507<>"")*(AR!$D$4:$D$507<>"")*((AR!$F$4:$F$507<=B29)+(AR!$F$4:$F$507>B29)))} -> 83 | D29: {=SUMPRODUCT((AR!$C$4:$C$507<>"")*(AR!$D$4:$D$507<>"")*(AR!$F$4:$F$507<=B29))} -> 21 | E29: {=SUMPRODUCT((AR!$C$4:$C$507<>"")*(AR!$D$4:$D$507<>"")*(AR!$G$4:$G$507<>"")*(AR!$G$4:$G$507<=B29))} -> 14 | F29: {=SUMPRODUCT((AR!$C$4:$C$507<>"")*(AR!$D$4:$D$507<>"")*(AR!$G$4:$G$507<=$B29)*(AR!$K$4:$K$507="Pending")*(AR!$J$4:$J$507="CTA"))} -> 0 | G29: {=SUMPRODUCT((AR!$C$4:$C$507<>"")*(AR!$D$4:$D$507<>"")*(AR!$G$4:$G$507<=$B29)*(AR!$K$4:$K$507="Pending")*(AR!$J$4:$J$507="AUR"))} -> 1 | H29: {=SUMPRODUCT((AR!$C$4:$C$507<>"")*(AR!$D$4:$D$507<>"")*(AR!$G$4:$G$507<=$B29)*(AR!$K$4:$K$507="Pending")*(AR!$J$4:$J$507="STT"))} -> 0 | I29: {=SUMPRODUCT((AR!$C$4:$C$507<>"")*(AR!$D$4:$D$507<>"")*(AR!$G$4:$G$507<=$B29)*(AR!$K$4:$K$507="A"))} -> 0 | J29: {=SUMPRODUCT((AR!$C$4:$C$507<>"")*(AR!$D$4:$D$507<>"")*(AR!$G$4:$G$507<=$B29)*(AR!$K$4:$K$507="B"))} -> 12 | K29: {=SUMPRODUCT((AR!$C$4:$C$507<>"")*(AR!$D$4:$D$507<>"")*(AR!$G$4:$G$507<=$B29)*(AR!$K$4:$K$507="C"))} -> 1
B30: =B12 -> 46055 | C30: {=SUMPRODUCT((AR!$C$4:$C$507<>"")*(AR!$D$4:$D$507<>"")*((AR!$F$4:$F$507<=B30)+(AR!$F$4:$F$507>B30)))} -> 83 | D30: {=SUMPRODUCT((AR!$C$4:$C$507<>"")*(AR!$D$4:$D$507<>"")*(AR!$F$4:$F$507<=B30))} -> 27 | E30: {=SUMPRODUCT((AR!$C$4:$C$507<>"")*(AR!$D$4:$D$507<>"")*(AR!$G$4:$G$507<>"")*(AR!$G$4:$G$507<=B30))} -> 19 | F30: {=SUMPRODUCT((AR!$C$4:$C$507<>"")*(AR!$D$4:$D$507<>"")*(AR!$G$4:$G$507<=$B30)*(AR!$K$4:$K$507="Pending")*(AR!$J$4:$J$507="CTA"))} -> 0 | G30: {=SUMPRODUCT((AR!$C$4:$C$507<>"")*(AR!$D$4:$D$507<>"")*(AR!$G$4:$G$507<=$B30)*(AR!$K$4:$K$507="Pending")*(AR!$J$4:$J$507="AUR"))} -> 1 | H30: {=SUMPRODUCT((AR!$C$4:$C$507<>"")*(AR!$D$4:$D$507<>"")*(AR!$G$4:$G$507<=$B30)*(AR!$K$4:$K$507="Pending")*(AR!$J$4:$J$507="STT"))} -> 3 | I30: {=SUMPRODUCT((AR!$C$4:$C$507<>"")*(AR!$D$4:$D$507<>"")*(AR!$G$4:$G$507<=$B30)*(AR!$K$4:$K$507="A"))} -> 0 | J30: {=SUMPRODUCT((AR!$C$4:$C$507<>"")*(AR!$D$4:$D$507<>"")*(AR!$G$4:$G$507<=$B30)*(AR!$K$4:$K$507="B"))} -> 14 | K30: {=SUMPRODUCT((AR!$C$4:$C$507<>"")*(AR!$D$4:$D$507<>"")*(AR!$G$4:$G$507<=$B30)*(AR!$K$4:$K$507="C"))} -> 1
B40: Electrical
B41: w/e | C41: Total Expected | D41: Planned Submission | E41: Actual Submitted | F41: Status
F42: Under Review | I42: A | J42: B | K42: C
F43: CTA | G43: AUR | H43: STT
B44: =B8 -> 46027 | C44: {=SUMPRODUCT((EL!$E$4:$E$618<>"")*(EL!$D$4:$D$618<>"")*((EL!$F$4:$F$618<=B44)+(EL!$F$4:$F$618>B44)))} -> 255 | D44: {=SUMPRODUCT((EL!$C$4:$C$618<>"")*(EL!$D$4:$D$618<>"")*(EL!$H$4:$H$618<=B44))} -> 13 | E44: {=SUMPRODUCT((EL!$C$4:$C$618<>"")*(EL!$D$4:$D$618<>"")*(EL!$G$4:$G$618<>"")*(EL!$G$4:$G$618<=B44))} -> 0 | F44: {=SUMPRODUCT((EL!$C$4:$C$441<>"")*(EL!$D$4:$D$441<>"")*(EL!$I$4:$I$441<=$B44)*(EL!$M$4:$M$441="Pending")*(EL!$L$4:$L$441="CTA"))} -> 0 | G44: {=SUMPRODUCT((EL!$C$4:$C$441<>"")*(EL!$D$4:$D$441<>"")*(EL!$I$4:$I$441<=$B44)*(EL!$M$4:$M$441="Pending")*(EL!$L$4:$L$441="AUR"))} -> 0 | H44: {=SUMPRODUCT((EL!$C$4:$C$441<>"")*(EL!$D$4:$D$441<>"")*(EL!$I$4:$I$441<=$B44)*(EL!$M$4:$M$441="Pending")*(EL!$L$4:$L$441="STT"))} -> 0 | I44: {=SUMPRODUCT((EL!$C$4:$C$441<>"")*(EL!$D$4:$D$441<>"")*(EL!$I$4:$I$441<=$B44)*(EL!$M$4:$M$441="A"))} -> 0 | J44: {=SUMPRODUCT((EL!$C$4:$C$441<>"")*(EL!$D$4:$D$441<>"")*(EL!$I$4:$I$441<=$B44)*(EL!$M$4:$M$441="B"))} -> 0 | K44: {=SUMPRODUCT((EL!$C$4:$C$441<>"")*(EL!$D$4:$D$441<>"")*(EL!$I$4:$I$441<=$B44)*(EL!$M$4:$M$441="C"))} -> 1
B45: =B9 -> 46034 | C45: {=SUMPRODUCT((EL!$E$4:$E$618<>"")*(EL!$D$4:$D$618<>"")*((EL!$F$4:$F$618<=B45)+(EL!$F$4:$F$618>B45)))} -> 255 | D45: {=SUMPRODUCT((EL!$C$4:$C$618<>"")*(EL!$D$4:$D$618<>"")*(EL!$H$4:$H$618<=B45))} -> 13 | E45: {=SUMPRODUCT((EL!$C$4:$C$618<>"")*(EL!$D$4:$D$618<>"")*(EL!$G$4:$G$618<>"")*(EL!$G$4:$G$618<=B45))} -> 0 | F45: {=SUMPRODUCT((EL!$C$4:$C$441<>"")*(EL!$D$4:$D$441<>"")*(EL!$I$4:$I$441<=$B45)*(EL!$M$4:$M$441="Pending")*(EL!$L$4:$L$441="CTA"))} -> 0 | G45: {=SUMPRODUCT((EL!$C$4:$C$441<>"")*(EL!$D$4:$D$441<>"")*(EL!$I$4:$I$441<=$B45)*(EL!$M$4:$M$441="Pending")*(EL!$L$4:$L$441="AUR"))} -> 0 | H45: {=SUMPRODUCT((EL!$C$4:$C$441<>"")*(EL!$D$4:$D$441<>"")*(EL!$I$4:$I$441<=$B45)*(EL!$M$4:$M$441="Pending")*(EL!$L$4:$L$441="STT"))} -> 0 | I45: {=SUMPRODUCT((EL!$C$4:$C$441<>"")*(EL!$D$4:$D$441<>"")*(EL!$I$4:$I$441<=$B45)*(EL!$M$4:$M$441="A"))} -> 0 | J45: {=SUMPRODUCT((EL!$C$4:$C$441<>"")*(EL!$D$4:$D$441<>"")*(EL!$I$4:$I$441<=$B45)*(EL!$M$4:$M$441="B"))} -> 0 | K45: {=SUMPRODUCT((EL!$C$4:$C$441<>"")*(EL!$D$4:$D$441<>"")*(EL!$I$4:$I$441<=$B45)*(EL!$M$4:$M$441="C"))} -> 1
B46: =B10 -> 46041 | C46: {=SUMPRODUCT((EL!$E$4:$E$618<>"")*(EL!$D$4:$D$618<>"")*((EL!$F$4:$F$618<=B46)+(EL!$F$4:$F$618>B46)))} -> 255 | D46: {=SUMPRODUCT((EL!$C$4:$C$618<>"")*(EL!$D$4:$D$618<>"")*(EL!$H$4:$H$618<=B46))} -> 37 | E46: {=SUMPRODUCT((EL!$C$4:$C$618<>"")*(EL!$D$4:$D$618<>"")*(EL!$G$4:$G$618<>"")*(EL!$G$4:$G$618<=B46))} -> 0 | F46: {=SUMPRODUCT((EL!$C$4:$C$441<>"")*(EL!$D$4:$D$441<>"")*(EL!$I$4:$I$441<=$B46)*(EL!$M$4:$M$441="Pending")*(EL!$L$4:$L$441="CTA"))} -> 12 | G46: {=SUMPRODUCT((EL!$C$4:$C$441<>"")*(EL!$D$4:$D$441<>"")*(EL!$I$4:$I$441<=$B46)*(EL!$M$4:$M$441="Pending")*(EL!$L$4:$L$441="AUR"))} -> 0 | H46: {=SUMPRODUCT((EL!$C$4:$C$441<>"")*(EL!$D$4:$D$441<>"")*(EL!$I$4:$I$441<=$B46)*(EL!$M$4:$M$441="Pending")*(EL!$L$4:$L$441="STT"))} -> 7 | I46: {=SUMPRODUCT((EL!$C$4:$C$441<>"")*(EL!$D$4:$D$441<>"")*(EL!$I$4:$I$441<=$B46)*(EL!$M$4:$M$441="A"))} -> 0 | J46: {=SUMPRODUCT((EL!$C$4:$C$441<>"")*(EL!$D$4:$D$441<>"")*(EL!$I$4:$I$441<=$B46)*(EL!$M$4:$M$441="B"))} -> 0 | K46: {=SUMPRODUCT((EL!$C$4:$C$441<>"")*(EL!$D$4:$D$441<>"")*(EL!$I$4:$I$441<=$B46)*(EL!$M$4:$M$441="C"))} -> 1
B47: =B11 -> 46048 | C47: {=SUMPRODUCT((EL!$E$4:$E$618<>"")*(EL!$D$4:$D$618<>"")*((EL!$F$4:$F$618<=B47)+(EL!$F$4:$F$618>B47)))} -> 255 | D47: {=SUMPRODUCT((EL!$C$4:$C$618<>"")*(EL!$D$4:$D$618<>"")*(EL!$H$4:$H$618<=B47))} -> 53 | E47: {=SUMPRODUCT((EL!$C$4:$C$618<>"")*(EL!$D$4:$D$618<>"")*(EL!$I$4:$I$618<>"")*(EL!$I$4:$I$618<=B47))} -> 30 | F47: {=SUMPRODUCT((EL!$C$4:$C$441<>"")*(EL!$D$4:$D$441<>"")*(EL!$I$4:$I$441<=$B47)*(EL!$M$4:$M$441="Pending")*(EL!$L$4:$L$441="CTA"))} -> 12 | G47: {=SUMPRODUCT((EL!$C$4:$C$441<>"")*(EL!$D$4:$D$441<>"")*(EL!$I$4:$I$441<=$B47)*(EL!$M$4:$M$441="Pending")*(EL!$L$4:$L$441="AUR"))} -> 0 | H47: {=SUMPRODUCT((EL!$C$4:$C$441<>"")*(EL!$D$4:$D$441<>"")*(EL!$I$4:$I$441<=$B47)*(EL!$M$4:$M$441="Pending")*(EL!$L$4:$L$441="STT"))} -> 17 | I47: {=SUMPRODUCT((EL!$C$4:$C$441<>"")*(EL!$D$4:$D$441<>"")*(EL!$I$4:$I$441<=$B47)*(EL!$M$4:$M$441="A"))} -> 0 | J47: {=SUMPRODUCT((EL!$C$4:$C$441<>"")*(EL!$D$4:$D$441<>"")*(EL!$I$4:$I$441<=$B47)*(EL!$M$4:$M$441="B"))} -> 0 | K47: {=SUMPRODUCT((EL!$C$4:$C$441<>"")*(EL!$D$4:$D$441<>"")*(EL!$I$4:$I$441<=$B47)*(EL!$M$4:$M$441="C"))} -> 1
B48: =B12 -> 46055 | C48: {=SUMPRODUCT((EL!$E$4:$E$618<>"")*(EL!$D$4:$D$618<>"")*((EL!$F$4:$F$618<=B48)+(EL!$F$4:$F$618>B48)))} -> 255 | D48: {=SUMPRODUCT((EL!$C$4:$C$618<>"")*(EL!$D$4:$D$618<>"")*(EL!$H$4:$H$618<=B48))} -> 73 | E48: {=SUMPRODUCT((EL!$C$4:$C$618<>"")*(EL!$D$4:$D$618<>"")*(EL!$I$4:$I$618<>"")*(EL!$I$4:$I$618<=B48))} -> 36 | F48: {=SUMPRODUCT((EL!$C$4:$C$441<>"")*(EL!$D$4:$D$441<>"")*(EL!$I$4:$I$441<=$B48)*(EL!$M$4:$M$441="Pending")*(EL!$L$4:$L$441="CTA"))} -> 12 | G48: {=SUMPRODUCT((EL!$C$4:$C$441<>"")*(EL!$D$4:$D$441<>"")*(EL!$I$4:$I$441<=$B48)*(EL!$M$4:$M$441="Pending")*(EL!$L$4:$L$441="AUR"))} -> 2 | H48: {=SUMPRODUCT((EL!$C$4:$C$441<>"")*(EL!$D$4:$D$441<>"")*(EL!$I$4:$I$441<=$B48)*(EL!$M$4:$M$441="Pending")*(EL!$L$4:$L$441="STT"))} -> 21 | I48: {=SUMPRODUCT((EL!$C$4:$C$441<>"")*(EL!$D$4:$D$441<>"")*(EL!$I$4:$I$441<=$B48)*(EL!$M$4:$M$441="A"))} -> 0 | J48: {=SUMPRODUCT((EL!$C$4:$C$441<>"")*(EL!$D$4:$D$441<>"")*(EL!$I$4:$I$441<=$B48)*(EL!$M$4:$M$441="B"))} -> 0 | K48: {=SUMPRODUCT((EL!$C$4:$C$441<>"")*(EL!$D$4:$D$441<>"")*(EL!$I$4:$I$441<=$B48)*(EL!$M$4:$M$441="C"))} -> 1
B59: Mechanical
B60: w/e | C60: Total Expected | D60: Planned Submission | E60: Actual Submitted | F60: Status
F61: Under Review | I61: A | J61: B | K61: C
F62: CTA | G62: AUR | H62: STT
B63: =B8 -> 46027 | C63: {=SUMPRODUCT((ME!$C$4:$C$441<>"")*(ME!$D$4:$D$441<>"")*((ME!$F$4:$F$441<=B63)+(ME!$F$4:$F$441>B63)))} -> 52 | D63: {=SUMPRODUCT((ME!$C$4:$C$441<>"")*(ME!$D$4:$D$441<>"")*(ME!$F$4:$F$441<=B63))} -> 1 | E63: {=SUMPRODUCT((ME!$C$4:$C$441<>"")*(ME!$D$4:$D$441<>"")*(ME!$G$4:$G$441<>"")*(ME!$G$4:$G$441<=B63))} -> 0 | F63: {=SUMPRODUCT((ME!$C$4:$C$441<>"")*(ME!$D$4:$D$441<>"")*(ME!$G$4:$G$441<=$B63)*(ME!$K$4:$K$441="Pending")*(ME!$J$4:$J$441="CTA"))} -> 0 | G63: {=SUMPRODUCT((ME!$C$4:$C$441<>"")*(ME!$D$4:$D$441<>"")*(ME!$G$4:$G$441<=$B63)*(ME!$K$4:$K$441="Pending")*(ME!$J$4:$J$441="AUR"))} -> 0 | H63: {=SUMPRODUCT((ME!$C$4:$C$441<>"")*(ME!$D$4:$D$441<>"")*(ME!$G$4:$G$441<=$B63)*(ME!$K$4:$K$441="Pending")*(ME!$J$4:$J$441="STT"))} -> 0 | I63: {=SUMPRODUCT((ME!$C$4:$C$441<>"")*(ME!$D$4:$D$441<>"")*(ME!$G$4:$G$441<=$B63)*(ME!$K$4:$K$441="A"))} -> 0 | J63: {=SUMPRODUCT((ME!$C$4:$C$441<>"")*(ME!$D$4:$D$441<>"")*(ME!$G$4:$G$441<=$B63)*(ME!$K$4:$K$441="B"))} -> 0 | K63: {=SUMPRODUCT((ME!$C$4:$C$441<>"")*(ME!$D$4:$D$441<>"")*(ME!$G$4:$G$441<=$B63)*(ME!$K$4:$K$441="C"))} -> 0
B64: =B9 -> 46034 | C64: {=SUMPRODUCT((ME!$C$4:$C$441<>"")*(ME!$D$4:$D$441<>"")*((ME!$F$4:$F$441<=B64)+(ME!$F$4:$F$441>B64)))} -> 52 | D64: {=SUMPRODUCT((ME!$C$4:$C$441<>"")*(ME!$D$4:$D$441<>"")*(ME!$F$4:$F$441<=B64))} -> 2 | E64: {=SUMPRODUCT((ME!$C$4:$C$441<>"")*(ME!$D$4:$D$441<>"")*(ME!$G$4:$G$441<>"")*(ME!$G$4:$G$441<=B64))} -> 1 | F64: {=SUMPRODUCT((ME!$C$4:$C$441<>"")*(ME!$D$4:$D$441<>"")*(ME!$G$4:$G$441<=$B64)*(ME!$K$4:$K$441="Pending")*(ME!$J$4:$J$441="CTA"))} -> 0 | G64: {=SUMPRODUCT((ME!$C$4:$C$441<>"")*(ME!$D$4:$D$441<>"")*(ME!$G$4:$G$441<=$B64)*(ME!$K$4:$K$441="Pending")*(ME!$J$4:$J$441="AUR"))} -> 1 | H64: {=SUMPRODUCT((ME!$C$4:$C$441<>"")*(ME!$D$4:$D$441<>"")*(ME!$G$4:$G$441<=$B64)*(ME!$K$4:$K$441="Pending")*(ME!$J$4:$J$441="STT"))} -> 0 | I64: {=SUMPRODUCT((ME!$C$4:$C$441<>"")*(ME!$D$4:$D$441<>"")*(ME!$G$4:$G$441<=$B64)*(ME!$K$4:$K$441="A"))} -> 0 | J64: {=SUMPRODUCT((ME!$C$4:$C$441<>"")*(ME!$D$4:$D$441<>"")*(ME!$G$4:$G$441<=$B64)*(ME!$K$4:$K$441="B"))} -> 0 | K64: {=SUMPRODUCT((ME!$C$4:$C$441<>"")*(ME!$D$4:$D$441<>"")*(ME!$G$4:$G$441<=$B64)*(ME!$K$4:$K$441="C"))} -> 0
B65: =B10 -> 46041 | C65: {=SUMPRODUCT((ME!$C$4:$C$441<>"")*(ME!$D$4:$D$441<>"")*((ME!$F$4:$F$441<=B65)+(ME!$F$4:$F$441>B65)))} -> 52 | D65: {=SUMPRODUCT((ME!$C$4:$C$441<>"")*(ME!$D$4:$D$441<>"")*(ME!$F$4:$F$441<=B65))} -> 4 | E65: {=SUMPRODUCT((ME!$C$4:$C$441<>"")*(ME!$D$4:$D$441<>"")*(ME!$G$4:$G$441<>"")*(ME!$G$4:$G$441<=B65))} -> 2 | F65: {=SUMPRODUCT((ME!$C$4:$C$441<>"")*(ME!$D$4:$D$441<>"")*(ME!$G$4:$G$441<=$B65)*(ME!$K$4:$K$441="Pending")*(ME!$J$4:$J$441="CTA"))} -> 0 | G65: {=SUMPRODUCT((ME!$C$4:$C$441<>"")*(ME!$D$4:$D$441<>"")*(ME!$G$4:$G$441<=$B65)*(ME!$K$4:$K$441="Pending")*(ME!$J$4:$J$441="AUR"))} -> 2 | H65: {=SUMPRODUCT((ME!$C$4:$C$441<>"")*(ME!$D$4:$D$441<>"")*(ME!$G$4:$G$441<=$B65)*(ME!$K$4:$K$441="Pending")*(ME!$J$4:$J$441="STT"))} -> 0 | I65: {=SUMPRODUCT((ME!$C$4:$C$441<>"")*(ME!$D$4:$D$441<>"")*(ME!$G$4:$G$441<=$B65)*(ME!$K$4:$K$441="A"))} -> 0 | J65: {=SUMPRODUCT((ME!$C$4:$C$441<>"")*(ME!$D$4:$D$441<>"")*(ME!$G$4:$G$441<=$B65)*(ME!$K$4:$K$441="B"))} -> 0 | K65: {=SUMPRODUCT((ME!$C$4:$C$441<>"")*(ME!$D$4:$D$441<>"")*(ME!$G$4:$G$441<=$B65)*(ME!$K$4:$K$441="C"))} -> 0
B66: =B11 -> 46048 | C66: {=SUMPRODUCT((ME!$C$4:$C$441<>"")*(ME!$D$4:$D$441<>"")*((ME!$F$4:$F$441<=B66)+(ME!$F$4:$F$441>B66)))} -> 52 | D66: {=SUMPRODUCT((ME!$C$4:$C$441<>"")*(ME!$D$4:$D$441<>"")*(ME!$F$4:$F$441<=B66))} -> 5 | E66: {=SUMPRODUCT((ME!$C$4:$C$441<>"")*(ME!$D$4:$D$441<>"")*(ME!$G$4:$G$441<>"")*(ME!$G$4:$G$441<=B66))} -> 3 | F66: {=SUMPRODUCT((ME!$C$4:$C$441<>"")*(ME!$D$4:$D$441<>"")*(ME!$G$4:$G$441<=$B66)*(ME!$K$4:$K$441="Pending")*(ME!$J$4:$J$441="CTA"))} -> 0 | G66: {=SUMPRODUCT((ME!$C$4:$C$441<>"")*(ME!$D$4:$D$441<>"")*(ME!$G$4:$G$441<=$B66)*(ME!$K$4:$K$441="Pending")*(ME!$J$4:$J$441="AUR"))} -> 3 | H66: {=SUMPRODUCT((ME!$C$4:$C$441<>"")*(ME!$D$4:$D$441<>"")*(ME!$G$4:$G$441<=$B66)*(ME!$K$4:$K$441="Pending")*(ME!$J$4:$J$441="STT"))} -> 0 | I66: {=SUMPRODUCT((ME!$C$4:$C$441<>"")*(ME!$D$4:$D$441<>"")*(ME!$G$4:$G$441<=$B66)*(ME!$K$4:$K$441="A"))} -> 0 | J66: {=SUMPRODUCT((ME!$C$4:$C$441<>"")*(ME!$D$4:$D$441<>"")*(ME!$G$4:$G$441<=$B66)*(ME!$K$4:$K$441="B"))} -> 0 | K66: {=SUMPRODUCT((ME!$C$4:$C$441<>"")*(ME!$D$4:$D$441<>"")*(ME!$G$4:$G$441<=$B66)*(ME!$K$4:$K$441="C"))} -> 0
B67: =B12 -> 46055 | C67: {=SUMPRODUCT((ME!$C$4:$C$441<>"")*(ME!$D$4:$D$441<>"")*((ME!$F$4:$F$441<=B67)+(ME!$F$4:$F$441>B67)))} -> 52 | D67: {=SUMPRODUCT((ME!$C$4:$C$441<>"")*(ME!$D$4:$D$441<>"")*(ME!$F$4:$F$441<=B67))} -> 5 | E67: {=SUMPRODUCT((ME!$C$4:$C$441<>"")*(ME!$D$4:$D$441<>"")*(ME!$G$4:$G$441<>"")*(ME!$G$4:$G$441<=B67))} -> 3 | F67: {=SUMPRODUCT((ME!$C$4:$C$441<>"")*(ME!$D$4:$D$441<>"")*(ME!$G$4:$G$441<=$B67)*(ME!$K$4:$K$441="Pending")*(ME!$J$4:$J$441="CTA"))} -> 0 | G67: {=SUMPRODUCT((ME!$C$4:$C$441<>"")*(ME!$D$4:$D$441<>"")*(ME!$G$4:$G$441<=$B67)*(ME!$K$4:$K$441="Pending")*(ME!$J$4:$J$441="AUR"))} -> 3 | H67: {=SUMPRODUCT((ME!$C$4:$C$441<>"")*(ME!$D$4:$D$441<>"")*(ME!$G$4:$G$441<=$B67)*(ME!$K$4:$K$441="Pending")*(ME!$J$4:$J$441="STT"))} -> 0 | I67: {=SUMPRODUCT((ME!$C$4:$C$441<>"")*(ME!$D$4:$D$441<>"")*(ME!$G$4:$G$441<=$B67)*(ME!$K$4:$K$441="A"))} -> 0 | J67: {=SUMPRODUCT((ME!$C$4:$C$441<>"")*(ME!$D$4:$D$441<>"")*(ME!$G$4:$G$441<=$B67)*(ME!$K$4:$K$441="B"))} -> 0 | K67: {=SUMPRODUCT((ME!$C$4:$C$441<>"")*(ME!$D$4:$D$441<>"")*(ME!$G$4:$G$441<=$B67)*(ME!$K$4:$K$441="C"))} -> 0
B77: Fire Protection
B78: w/e | C78: Total Expected | D78: Planned Submission | E78: Actual Submitted | F78: Status
F79: Under Review | I79: A | J79: B | K79: C
...

Sheet AR
A1: Status: (A) Approved with No Comments, (B) Approved with Comments, (C) Revise & Resubmit | N1: Action by | O1: GAA | P1: CTA | Q1: AUR
A2: S/N | B2: Trade | C2: SDW Doc No. | D2: Document Description | E2: RFAS Doc No. | F2: Planned Submission | G2: Submission Date | H2: Consultant Respond Date | I2: Rev | J2: Action | K2: Status | L2: Approval Date | M2: Scope | N2: Remarks | O2: Rev 0 | T2: Rev 1 | Y2: Rev 2 | AD2: Rev 3 | AI2: Rev 4 | AN2: Rev 5 | AS2: Rev 6 | AX2: Rev 7 | BC2: Required Review by STT's Engineering Team (YES/NO)
O3: Submitted | P3: CTA | Q3: AUR | R3: STT | S3: Status | T3: Submitted | U3: CTA | V3: AUR | W3: STT | X3: Status | Y3: Submitted | Z3: CTA | AA3: AUR | AB3: STT | AC3: Status | AD3: Submitted | AE3: CTA | AF3: AUR | AG3: STT | AH3: Status | AI3: Submitted | AJ3: CTA | AK3: AUR | AL3: STT | AM3: Status | AN3: Submitted | AO3: CTA | AP3: AUR | AQ3: STT | AR3: Status | AS3: Submitted | AT3: CTA | AU3: AUR | AV3: STT | AW3: Status | AX3: Submitted | AY3: CTA | AZ3: AUR | BA3: STT | BB3: Status
A4: 1 | B4: Architectural | C4: 523213-01-SDW-AR-0001 | D4: Architectural Drawing Index | E4: 523213-01-RFAS-AR-0001 | F4: 46034 | G4: 46034 | H4: =G4+7 -> 46041 | I4: 0 | J4: Closed | K4: B | L4: 46050 | M4: GC | O4: 46034 | P4: 46043 | Q4: 46045 | R4: 46050 | S4: B | BC4: NO
A5: 2 | B5: Architectural | C5: 523213-01-SDW-AR-0100 | D5: Level 1 - Overall Base Plan | E5: 523213-01-RFAS-AR-0002 | F5: =F6+7 -> 46041 | G5: 46041 | H5: =G5+7 -> 46048 | I5: 0 | J5: GAA | K5: C | L5: 46050 | M5: GC | O5: 46041 | P5: 46043 | Q5: 46045 | R5: 46050 | S5: C | BC5: NO
A6: 3 | B6: Architectural | C6: 523213-01-SDW-AR-0200 | D6: Level 2 - Overall Base Plan | E6: 523213-01-RFAS-AR-0003 | F6: 46034 | G6: 46039 | H6: =G6+7 -> 46046 | I6: 0 | J6: AUR | K6: Pending | M6: GC | N6: RFI-EL-0018 | O6: 46039 | P6: 46043 | BC6: NO
A7: 4 | B7: Architectural | C7: 523213-01-SDW-AR-0300 | D7: Level 3 - Overall Base Plan | E7: 523213-01-RFAS-AR-0004 | F7: =F5 -> 46041 | G7: 46042 | H7: =G7+7 -> 46049 | I7: 0 | J7: Closed | K7: B | L7: 46055 | M7: GC | O7: 46042 | P7: 46044 | Q7: 46050 | R7: 46055 | S7: B | BC7: NO
A8: 5 | B8: Architectural | C8: 523213-01-SDW-AR-0400 | D8: Level 4 - Overall Base Plan | E8: 523213-01-RFAS-AR-0005 | F8: =F7+7 -> 46048 | G8: 46049 | H8: =G8+7 -> 46056 | I8: 0 | J8: Closed | K8: B | L8: 46059 | M8: GC | O8: 46049 | P8: 46050 | Q8: 46052 | R8: 46059 | S8: B | BC8: NO
A9: 6 | B9: Architectural | C9: 523213-01-SDW-AR-0500 | D9: Level 5 - Overall Base Plan | E9: 523213-01-RFAS-AR-0006 | F9: =F8 -> 46048 | G9: 46050 | H9: =G9+7 -> 46057 | I9: 0 | J9: STT | K9: Pending | M9: GC | O9: 46050 | P9: 46053 | Q9: 46057 | BC9: NO
A10: 7 | B10: Architectural | C10: 523213-01-SDW-AR-0600 | D10: Level 6 - Overall Base Plan | E10: 523213-01-RFAS-AR-0007 | F10: =F5 -> 46041 | G10: 46044 | H10: =G10+7 -> 46051 | I10: 0 | J10: Closed | K10: B | L10: 46059 | M10: GC | O10: 46044 | P10: 46049 | Q10: 46052 | R10: 46059 | S10: B | BC10: NO
A11: 8 | B11: Architectural | C11: 523213-01-SDW-AR-0700 | D11: Roof Deck - Overall Base Plan | E11: 523213-01-RFAS-AR-0008 | F11: =F5 -> 46041 | G11: 46062 | H11: =G11+7 -> 46069 | I11: 0 | J11: AUR | K11: Pending | M11: GC | O11: 46062 | P11: 46064 | BC11: NO
A12: 9 | B12: Architectural | C12: 523213-01-SDW-AR-1100 | D12: Level 1 - Floor Finishes & Details | E12: 523213-01-RFAS-AR-0009 | F12: =F13+7 -> 46041 | G12: 46055 | H12: =G12+7 -> 46062 | I12: 0 | J12: Closed | K12: B | L12: 46059 | M12: GC | O12: 46055 | P12: 46057 | Q12: 46059 | R12: 46059 | S12: B | BC12: NO
A13: 10 | B13: Architectural | C13: 523213-01-SDW-AR-1200 | D13: Level 2 - Floor Finishes & Details | E13: 523213-01-RFAS-AR-0010 | F13: =F6 -> 46034 | G13: 46045 | H13: =G13+7 -> 46052 | I13: 0 | J13: Closed | K13: B | L13: 46059 | M13: GC | O13: 46045 | P13: 46049 | Q13: 46052 | R13: 46059 | S13: B | BC13: NO
A14: 11 | B14: Architectural | C14: 523213-01-SDW-AR-1300 | D14: Level 3 - Floor Finishes & Details | E14: 523213-01-RFAS-AR-0011 | F14: =F25 -> 46072 | G14: 46057 | H14: =G14+7 -> 46064 | I14: 0 | J14: STT | K14: Pending | M14: GC | O14: 46057 | P14: 46059 | Q14: 46062 | BC14: NO
A15: 12 | B15: Architectural | C15: 523213-01-SDW-AR-1600 | D15: Level 6 - Floor Finishes & Details | E15: 523213-01-RFAS-AR-0012 | F15: 46044 | G15: 46056 | H15: =G15+7 -> 46063 | I15: 0 | J15: STT | K15: Pending | M15: GC | O15: 46056 | P15: 46059 | Q15: 46062 | BC15: NO
A16: 13 | B16: Architectural | C16: 523213-01-SDW-AR-2100 | D16: Level 1 - Bund Wall Setting-out & Details | E16: 523213-01-RFAS-AR-0013 | F16: =F20+7 -> 46058 | M16: GC | BC16: NO
A17: 14 | B17: Architectural | C17: 523213-01-SDW-AR-2110 | D17: Level 1 - Wall Finishes & Details | E17: 523213-01-RFAS-AR-0014 | F17: =F16 -> 46058 | M17: GC | BC17: NO
A18: 15 | B18: Architectural | C18: 523213-01-SDW-AR-2140 | D18: Level 1 - Block Wall Layout & Details | E18: 523213-01-RFAS-AR-0015 | F18: =F17 -> 46058 | M18: GC | BC18: NO
A19: 16 | B19: Architectural | C19: 523213-01-SDW-AR-2200 | D19: Level 2 - Bund Wall Setting-out & Details | E19: 523213-01-RFAS-AR-0016 | F19: 46048 | G19: 46045 | H19: =G19+7 -> 46052 | I19: 0 | J19: Closed | K19: B | L19: 46059 | M19: GC | O19: 46045 | P19: 46048 | Q19: 46059 | R19: 46059 | S19: B | BC19: NO
A20: 17 | B20: Architectural | C20: 523213-01-SDW-AR-2210 | D20: Level 2 - Wall Finishes & Details | E20: 523213-01-RFAS-AR-0017 | F20: =F15+7 -> 46051 | G20: 46045 | H20: =G20+7 -> 46052 | I20: 0 | J20: Closed | K20: B | L20: 46059 | M20: GC | O20: 46045 | P20: 46048 | Q20: 46059 | R20: 46059 | S20: B | BC20: NO
A21: 18 | B21: Architectural | C21: 523213-01-SDW-AR-2220 | D21: Level 2 - Wall Setting-out | E21: 523213-01-RFAS-AR-0018 | F21: =F20 -> 46051 | G21: 46045 | H21: =G21+7 -> 46052 | I21: 0 | J21: Closed | K21: B | L21: 46059 | M21: GC | O21: 46045 | P21: 46048 | Q21: 46059 | R21: 46059 | S21: B | BC21: NO
A22: 19 | B22: Architectural | C22: 523213-01-SDW-AR-2230 | D22: Level 2 - Block Wall Layout & Details | E22: 523213-01-RFAS-AR-0019 | F22: =F21 -> 46051 | G22: 46059 | H22: =G22+7 -> 46066 | I22: 0 | J22: STT | K22: Pending | M22: GC | O22: 46059 | P22: 46062 | Q22: 46065 | BC22: NO
A23: 20 | B23: Architectural | C23: 523213-01-SDW-AR-2240 | D23: Level 2 - Partition Wall Support Layout & Details | E23: 523213-01-RFAS-AR-0020 | F23: =F22 -> 46051 | G23: 46059 | H23: =G23+7 -> 46066 | I23: 1 | J23: STT | K23: Pending | M23: GC | O23: 46055 | P23: 46058 | S23: C | T23: 46059 | U23: 46062 | V23: 46065 | BC23: NO
A24: 21 | B24: Architectural | C24: 523213-01-SDW-AR-2250 | D24: Level 2 - Wire Mesh Layout & Details | E24: 523213-01-RFAS-AR-0021 | F24: =F23+7 -> 46058 | M24: GC | BC24: NO
