Workbook

Sheet Overview
A1: Request for Information Summary
A3: Trade | B3: Planned Equipment Material Approval | C3: Rev0 | N3: Rev1 | Z3: Rev2
C4: GAA Stats | D4: CTA Stats | F4: AUR Stats | H4: STT Stats | N4: GAA Stats | P4: CTA Stats | R4: AUR Stats | T4: STT Stats | Z4: GAA Stats | AB4: CTA Stats | AD4: AUR Stats | AF4: STT Stats
C5: Total Submission | D5: Total reviewed | E5: Total outstanding | F5: Total reviewed | G5: Total outstanding | H5: Total reviewed | I5: Total outstanding | J5: Status A | K5: Status B | L5: Status C | N5: Pending resubmission | O5: Submitted | P5: Total reviewed | Q5: Total outstanding | R5: Total reviewed | S5: Total outstanding | T5: Total reviewed | U5: Total outstanding | V5: Status A | W5: Status B | X5: Status C | Z5: Pending resubmission | AA5: Submitted | AB5: Total reviewed | AC5: Total outstanding | AD5: Total reviewed | AE5: Total outstanding | AF5: Total reviewed | AG5: Total outstanding | AH5: Status A | AI5: Status B | AJ5: Status C
A6: Structural | B6: {=SUMPRODUCT((ST!$C$4:$C$1000<>"")*(ST!$D$4:$D$1000<>""))} -> 1 | C6: {=SUMPRODUCT((ST!$C$4:$C$1000<>"")*(ST!$M$4:$M$1000<>""))} -> 1 | D6: =SUMPRODUCT((ST!$C$4:$C$1000<>"")*(ST!$N$4:$N$1000<>"")) -> 1 | E6: =SUMPRODUCT((ST!$C$4:$C$1000<>"")*(ST!$M$4:$M$1000<>"")*(ST!$N$4:$N$1000="")) -> 0 | F6: =SUMPRODUCT((ST!$C$4:$C$1000<>"")*(ST!$O$4:$O$1000<>"")) -> 1 | G6: =SUMPRODUCT((ST!$C$4:$C$1000<>"")*(ST!$M$4:$M$1000<>"")*(ST!$O$4:$O$1000="")) -> 0 | H6: =SUMPRODUCT((ST!$C$4:$C$1000<>"")*(ST!$P$4:$P$1000<>"")) -> 0 | I6: =SUMPRODUCT((ST!$C$4:$C$1000<>"")*(ST!$M$4:$M$1000<>"")*(ST!$P$4:$P$1000="")) -> 1 | J6: =SUMPRODUCT((ST!$C$4:$C$1000<>"")*(ST!$Q$4:$Q$1000="A")) -> 0 | K6: =SUMPRODUCT((ST!$C$4:$C$1000<>"")*(ST!$Q$4:$Q$1000="B")) -> 0 | L6: =SUMPRODUCT((ST!$C$4:$C$1000<>"")*(ST!$Q$4:$Q$1000="C")) -> 0 | N6: =L6 -> 0 | O6: =SUMPRODUCT((ST!$C$4:$C$1000<>"")*(ST!$R$4:$R$1000<>"")) -> 0 | P6: =SUMPRODUCT((ST!$C$4:$C$1000<>"")*(ST!$S$4:$S$1000<>"")) -> 0 | Q6: =SUMPRODUCT((ST!$C$4:$C$1000<>"")*(ST!$R$4:$R$1000<>"")*(ST!$S$4:$S$1000="")) -> 0 | R6: =SUMPRODUCT((ST!$C$4:$C$1000<>"")*(ST!$T$4:$T$1000<>"")) -> 0 | S6: =SUMPRODUCT((ST!$C$4:$C$1000<>"")*(ST!$R$4:$R$1000<>"")*(ST!$T$4:$T$1000="")) -> 0 | T6: =SUMPRODUCT((ST!$C$4:$C$1000<>"")*(ST!$U$4:$U$1000<>"")) -> 0 | U6: =SUMPRODUCT((ST!$C$4:$C$1000<>"")*(ST!$R$4:$R$1000<>"")*(ST!$U$4:$U$1000="")) -> 0 | V6: =SUMPRODUCT((ST!$C$4:$C$1000<>"")*(ST!$V$4:$V$1000="A")) -> 0 | W6: =SUMPRODUCT((ST!$C$4:$C$1000<>"")*(ST!$V$4:$V$1000="B")) -> 0 | X6: =SUMPRODUCT((ST!$C$4:$C$1000<>"")*(ST!$V$4:$V$1000="C")) -> 0 | Z6: =X6 -> 0 | AA6: =SUMPRODUCT((ST!$C$4:$C$1000<>"")*(ST!$W$4:$W$1000<>"")) -> 0 | AB6: =SUMPRODUCT((ST!$C$4:$C$1000<>"")*(ST!$X$4:$X$1000<>"")) -> 0 | AC6: =SUMPRODUCT((ST!$C$4:$C$1000<>"")*(ST!$W$4:$W$1000<>"")*(ST!$X$4:$X$1000="")) -> 0 | AD6: =SUMPRODUCT((ST!$C$4:$C$1000<>"")*(ST!$Y$4:$Y$1000<>"")) -> 0 | AE6: =SUMPRODUCT((ST!$C$4:$C$1000<>"")*(ST!$W$4:$W$1000<>"")*(ST!$Y$4:$Y$1000="")) -> 0 | AF6: =SUMPRODUCT((ST!$C$4:$C$1000<>"")*(ST!$Z$4:$Z$1000<>"")) -> 0 | AG6: =SUMPRODUCT((ST!$C$4:$C$1000<>"")*(ST!$W$4:$W$1000<>"")*(ST!$Z$4:$Z$1000="")) -> 0 | AH6: =SUMPRODUCT((ST!$C$4:$C$1000<>"")*(ST!$AA$4:$AA$1000="A")) -> 0 | AI6: =SUMPRODUCT((ST!$C$4:$C$1000<>"")*(ST!$AA$4:$AA$1000="B")) -> 0 | AJ6: =SUMPRODUCT((ST!$C$4:$C$1000<>"")*(ST!$AA$4:$AA$1000="C")) -> 0
A7: Architectural | B7: {=SUMPRODUCT((AR!$C$4:$C$989<>"")*(AR!$D$4:$D$989<>""))} -> 38 | C7: =SUMPRODUCT((AR!$C$4:$C$989<>"")*(AR!$M$4:$M$989<>"")) -> 38 | D7: =SUMPRODUCT((AR!$C$4:$C$989<>"")*(AR!$N$4:$N$989<>"")) -> 37 | E7: =SUMPRODUCT((AR!$C$4:$C$989<>"")*(AR!$M$4:$M$989<>"")*(AR!$N$4:$N$989="")) -> 1 | F7: =SUMPRODUCT((AR!$C$4:$C$989<>"")*(AR!$O$4:$O$989<>"")) -> 37 | G7: =SUMPRODUCT((AR!$C$4:$C$989<>"")*(AR!$M$4:$M$989<>"")*(AR!$O$4:$O$989="")) -> 1 | H7: =SUMPRODUCT((AR!$C$4:$C$989<>"")*(AR!$P$4:$P$989<>"")) -> 24 | I7: =SUMPRODUCT((AR!$C$4:$C$989<>"")*(AR!$M$4:$M$989<>"")*(AR!$P$4:$P$989="")) -> 14 | J7: =SUMPRODUCT((AR!$C$4:$C$989<>"")*(AR!$Q$4:$Q$989="A")) -> 1 | K7: =SUMPRODUCT((AR!$C$4:$C$989<>"")*(AR!$Q$4:$Q$989="B")) -> 15 | L7: =SUMPRODUCT((AR!$C$4:$C$989<>"")*(AR!$Q$4:$Q$989="C")) -> 0 | N7: =L7 -> 0 | O7: =SUMPRODUCT((AR!$C$4:$C$989<>"")*(AR!$R$4:$R$989<>"")) -> 1 | P7: =SUMPRODUCT((AR!$C$4:$C$989<>"")*(AR!$S$4:$S$989<>"")) -> 0 | Q7: =SUMPRODUCT((AR!$C$4:$C$989<>"")*(AR!$R$4:$R$989<>"")*(AR!$S$4:$S$989="")) -> 1 | R7: =SUMPRODUCT((AR!$C$4:$C$989<>"")*(AR!$T$4:$T$989<>"")) -> 0 | S7: =SUMPRODUCT((AR!$C$4:$C$989<>"")*(AR!$R$4:$R$989<>"")*(AR!$T$4:$T$989="")) -> 1 | T7: =SUMPRODUCT((AR!$C$4:$C$989<>"")*(AR!$U$4:$U$989<>"")) -> 0 | U7: =SUMPRODUCT((AR!$C$4:$C$989<>"")*(AR!$R$4:$R$989<>"")*(AR!$U$4:$U$989="")) -> 1 | V7: =SUMPRODUCT((AR!$C$4:$C$989<>"")*(AR!$V$4:$V$989="A")) -> 0 | W7: =SUMPRODUCT((AR!$C$4:$C$989<>"")*(AR!$V$4:$V$989="B")) -> 0 | X7: =SUMPRODUCT((AR!$C$4:$C$989<>"")*(AR!$V$4:$V$989="C")) -> 0 | Z7: =X7 -> 0 | AA7: =SUMPRODUCT((AR!$C$4:$C$989<>"")*(AR!$W$4:$W$989<>"")) -> 0 | AB7: =SUMPRODUCT((AR!$C$4:$C$989<>"")*(AR!$X$4:$X$989<>"")) -> 0 | AC7: =SUMPRODUCT((AR!$C$4:$C$989<>"")*(AR!$W$4:$W$989<>"")*(AR!$X$4:$X$989="")) -> 0 | AD7: =SUMPRODUCT((AR!$C$4:$C$989<>"")*(AR!$Y$4:$Y$989<>"")) -> 0 | AE7: =SUMPRODUCT((AR!$C$4:$C$989<>"")*(AR!$W$4:$W$989<>"")*(AR!$Y$4:$Y$989="")) -> 0 | AF7: =SUMPRODUCT((AR!$C$4:$C$989<>"")*(AR!$Z$4:$Z$989<>"")) -> 0 | AG7: =SUMPRODUCT((AR!$C$4:$C$989<>"")*(AR!$W$4:$W$989<>"")*(AR!$Z$4:$Z$989="")) -> 0 | AH7: =SUMPRODUCT((AR!$C$4:$C$989<>"")*(AR!$AA$4:$AA$989="A")) -> 0 | AI7: =SUMPRODUCT((AR!$C$4:$C$989<>"")*(AR!$AA$4:$AA$989="B")) -> 0 | AJ7: =SUMPRODUCT((AR!$C$4:$C$989<>"")*(AR!$AA$4:$AA$989="C")) -> 0
A8: Mechanical | B8: =SUMPRODUCT((ME!$C$4:$C$981<>"")*(ME!$D$4:$D$981<>"")) -> 24 | C8: =SUMPRODUCT((ME!$C$4:$C$981<>"")*(ME!$N$4:$N$981<>"")) -> 24 | D8: =SUMPRODUCT((ME!$C$4:$C$981<>"")*(ME!$O$4:$O$981<>"")) -> 21 | E8: =SUMPRODUCT((ME!$C$4:$C$981<>"")*(ME!$N$4:$N$981<>"")*(ME!$O$4:$O$981="")) -> 3 | F8: =SUMPRODUCT((ME!$C$4:$C$981<>"")*(ME!$P$4:$P$981<>"")) -> 12 | G8: =SUMPRODUCT((ME!$C$4:$C$981<>"")*(ME!$N$4:$N$981<>"")*(ME!$P$4:$P$981="")) -> 12 | H8: =SUMPRODUCT((ME!$C$4:$C$981<>"")*(ME!$Q$4:$Q$981<>"")) -> 2 | I8: =SUMPRODUCT((ME!$C$4:$C$981<>"")*(ME!$N$4:$N$981<>"")*(ME!$Q$4:$Q$981="")) -> 22 | J8: =SUMPRODUCT((ME!$C$4:$C$981<>"")*(ME!$R$4:$R$981="A")) -> 0 | K8: =SUMPRODUCT((ME!$C$4:$C$981<>"")*(ME!$R$4:$R$981="B")) -> 2 | L8: =SUMPRODUCT((ME!$C$4:$C$981<>"")*(ME!$R$4:$R$981="C")) -> 0 | N8: =L8 -> 0 | O8: =SUMPRODUCT((ME!$C$4:$C$981<>"")*(ME!$S$4:$S$981<>"")) -> 0 | P8: =SUMPRODUCT((ME!$C$4:$C$981<>"")*(ME!$T$4:$T$981<>"")) -> 0 | Q8: =SUMPRODUCT((ME!$C$4:$C$981<>"")*(ME!$S$4:$S$981<>"")*(ME!$T$4:$T$981="")) -> 0 | R8: =SUMPRODUCT((ME!$C$4:$C$981<>"")*(ME!$U$4:$U$981<>"")) -> 0 | S8: =SUMPRODUCT((ME!$C$4:$C$981<>"")*(ME!$S$4:$S$981<>"")*(ME!$U$4:$U$981="")) -> 0 | T8: =SUMPRODUCT((ME!$C$4:$C$981<>"")*(ME!$V$4:$V$981<>"")) -> 0 | U8: =SUMPRODUCT((ME!$C$4:$C$981<>"")*(ME!$S$4:$S$981<>"")*(ME!$V$4:$V$981="")) -> 0 | V8: =SUMPRODUCT((ME!$C$4:$C$981<>"")*(ME!$W$4:$W$981="A")) -> 0 | W8: =SUMPRODUCT((ME!$C$4:$C$981<>"")*(ME!$W$4:$W$981="B")) -> 0 | X8: =SUMPRODUCT((ME!$C$4:$C$981<>"")*(ME!$W$4:$W$981="C")) -> 0 | Z8: =X8 -> 0 | AA8: =SUMPRODUCT((ME!$C$4:$C$981<>"")*(ME!$X$4:$X$981<>"")) -> 0 | AB8: =SUMPRODUCT((ME!$C$4:$C$981<>"")*(ME!$Y$4:$Y$981<>"")) -> 0 | AC8: =SUMPRODUCT((ME!$C$4:$C$981<>"")*(ME!$X$4:$X$981<>"")*(ME!$Y$4:$Y$981="")) -> 0 | AD8: =SUMPRODUCT((ME!$C$4:$C$981<>"")*(ME!$Z$4:$Z$981<>"")) -> 0 | AE8: =SUMPRODUCT((ME!$C$4:$C$981<>"")*(ME!$X$4:$X$981<>"")*(ME!$Z$4:$Z$981="")) -> 0 | AF8: =SUMPRODUCT((ME!$C$4:$C$981<>"")*(ME!$AA$4:$AA$981<>"")) -> 0 | AG8: =SUMPRODUCT((ME!$C$4:$C$981<>"")*(ME!$X$4:$X$981<>"")*(ME!$AA$4:$AA$981="")) -> 0 | AH8: =SUMPRODUCT((ME!$C$4:$C$981<>"")*(ME!$AB$4:$AB$981="A")) -> 0 | AI8: =SUMPRODUCT((ME!$C$4:$C$981<>"")*(ME!$AB$4:$AB$981="B")) -> 0 | AJ8: =SUMPRODUCT((ME!$C$4:$C$981<>"")*(ME!$AB$4:$AB$981="C")) -> 0
A9: Fire Protection | B9: =SUMPRODUCT((FI!$C$4:$C$976<>"")*(FI!$D$4:$D$976<>"")) -> 14 | C9: =SUMPRODUCT((FI!$C$4:$C$976<>"")*(FI!$N$4:$N$976<>"")) -> 14 | D9: =SUMPRODUCT((FI!$C$4:$C$976<>"")*(FI!$O$4:$O$976<>"")) -> 14 | E9: =SUMPRODUCT((FI!$C$4:$C$976<>"")*(FI!$N$4:$N$976<>"")*(FI!$O$4:$O$976="")) -> 0 | F9: =SUMPRODUCT((FI!$C$4:$C$976<>"")*(FI!$P$4:$P$976<>"")) -> 0 | G9: =SUMPRODUCT((FI!$C$4:$C$976<>"")*(FI!$N$4:$N$976<>"")*(FI!$P$4:$P$976="")) -> 14 | H9: =SUMPRODUCT((FI!$C$4:$C$976<>"")*(FI!$Q$4:$Q$976<>"")) -> 0 | I9: =SUMPRODUCT((FI!$C$4:$C$976<>"")*(FI!$N$4:$N$976<>"")*(FI!$Q$4:$Q$976="")) -> 14 | J9: =SUMPRODUCT((FI!$C$4:$C$976<>"")*(FI!$R$4:$R$976="A")) -> 0 | K9: =SUMPRODUCT((FI!$C$4:$C$976<>"")*(FI!$R$4:$R$976="B")) -> 0 | L9: =SUMPRODUCT((FI!$C$4:$C$976<>"")*(FI!$R$4:$R$976="C")) -> 0 | N9: =L9 -> 0 | O9: =SUMPRODUCT((FI!$C$4:$C$976<>"")*(FI!$S$4:$S$976<>"")) -> 0 | P9: =SUMPRODUCT((FI!$C$4:$C$976<>"")*(FI!$T$4:$T$976<>"")) -> 0 | Q9: =SUMPRODUCT((FI!$C$4:$C$976<>"")*(FI!$S$4:$S$976<>"")*(FI!$T$4:$T$976="")) -> 0 | R9: =SUMPRODUCT((FI!$C$4:$C$976<>"")*(FI!$U$4:$U$976<>"")) -> 0 | S9: =SUMPRODUCT((FI!$C$4:$C$976<>"")*(FI!$S$4:$S$976<>"")*(FI!$U$4:$U$976="")) -> 0 | T9: =SUMPRODUCT((FI!$C$4:$C$976<>"")*(FI!$V$4:$V$976<>"")) -> 0 | U9: =SUMPRODUCT((FI!$C$4:$C$976<>"")*(FI!$S$4:$S$976<>"")*(FI!$V$4:$V$976="")) -> 0 | V9: =SUMPRODUCT((FI!$C$4:$C$976<>"")*(FI!$W$4:$W$976="A")) -> 0 | W9: =SUMPRODUCT((FI!$C$4:$C$976<>"")*(FI!$W$4:$W$976="B")) -> 0 | X9: =SUMPRODUCT((FI!$C$4:$C$976<>"")*(FI!$W$4:$W$976="C")) -> 0 | Z9: =X9 -> 0 | AA9: =SUMPRODUCT((FI!$C$4:$C$976<>"")*(FI!$X$4:$X$976<>"")) -> 0 | AB9: =SUMPRODUCT((FI!$C$4:$C$976<>"")*(FI!$Y$4:$Y$976<>"")) -> 0 | AC9: =SUMPRODUCT((FI!$C$4:$C$976<>"")*(FI!$X$4:$X$976<>"")*(FI!$Y$4:$Y$976="")) -> 0 | AD9: =SUMPRODUCT((FI!$C$4:$C$976<>"")*(FI!$Z$4:$Z$976<>"")) -> 0 | AE9: =SUMPRODUCT((FI!$C$4:$C$976<>"")*(FI!$X$4:$X$976<>"")*(FI!$Z$4:$Z$976="")) -> 0 | AF9: =SUMPRODUCT((FI!$C$4:$C$976<>"")*(FI!$AA$4:$AA$976<>"")) -> 0 | AG9: =SUMPRODUCT((FI!$C$4:$C$976<>"")*(FI!$X$4:$X$976<>"")*(FI!$AA$4:$AA$976="")) -> 0 | AH9: =SUMPRODUCT((FI!$C$4:$C$976<>"")*(FI!$AB$4:$AB$976="A")) -> 0 | AI9: =SUMPRODUCT((FI!$C$4:$C$976<>"")*(FI!$AB$4:$AB$976="B")) -> 0 | AJ9: =SUMPRODUCT((FI!$C$4:$C$976<>"")*(FI!$AB$4:$AB$976="C")) -> 0
A10: Hydraulics | B10: =SUMPRODUCT((HY!$C$4:$C$992<>"")*(HY!$D$4:$D$992<>"")) -> 11 | C10: =SUMPRODUCT((HY!$C$4:$C$992<>"")*(HY!$N$4:$N$992<>"")) -> 11 | D10: =SUMPRODUCT((HY!$C$4:$C$992<>"")*(HY!$O$4:$O$992<>"")) -> 11 | E10: =SUMPRODUCT((HY!$C$4:$C$992<>"")*(HY!$N$4:$N$992<>"")*(HY!$O$4:$O$992="")) -> 0 | F10: =SUMPRODUCT((HY!$C$4:$C$992<>"")*(HY!$P$4:$P$992<>"")) -> 0 | G10: =SUMPRODUCT((HY!$C$4:$C$992<>"")*(HY!$N$4:$N$992<>"")*(HY!$P$4:$P$992="")) -> 11 | H10: =SUMPRODUCT((HY!$C$4:$C$992<>"")*(HY!$Q$4:$Q$992<>"")) -> 0 | I10: =SUMPRODUCT((HY!$C$4:$C$992<>"")*(HY!$N$4:$N$992<>"")*(HY!$Q$4:$Q$992="")) -> 11 | J10: =SUMPRODUCT((HY!$C$4:$C$992<>"")*(HY!$R$4:$R$992="A")) -> 0 | K10: =SUMPRODUCT((HY!$C$4:$C$992<>"")*(HY!$R$4:$R$992="B")) -> 0 | L10: =SUMPRODUCT((HY!$C$4:$C$992<>"")*(HY!$R$4:$R$992="C")) -> 0 | N10: =L10 -> 0 | O10: =SUMPRODUCT((HY!$C$4:$C$992<>"")*(HY!$S$4:$S$992<>"")) -> 0 | P10: =SUMPRODUCT((HY!$C$4:$C$992<>"")*(HY!$T$4:$T$992<>"")) -> 0 | Q10: =SUMPRODUCT((HY!$C$4:$C$992<>"")*(HY!$S$4:$S$992<>"")*(HY!$T$4:$T$992="")) -> 0 | R10: =SUMPRODUCT((HY!$C$4:$C$992<>"")*(HY!$U$4:$U$992<>"")) -> 0 | S10: =SUMPRODUCT((HY!$C$4:$C$992<>"")*(HY!$S$4:$S$992<>"")*(HY!$U$4:$U$992="")) -> 0 | T10: =SUMPRODUCT((HY!$C$4:$C$992<>"")*(HY!$V$4:$V$992<>"")) -> 0 | U10: =SUMPRODUCT((HY!$C$4:$C$992<>"")*(HY!$S$4:$S$992<>"")*(HY!$V$4:$V$992="")) -> 0 | V10: =SUMPRODUCT((HY!$C$4:$C$992<>"")*(HY!$W$4:$W$992="A")) -> 0 | W10: =SUMPRODUCT((HY!$C$4:$C$992<>"")*(HY!$W$4:$W$992="B")) -> 0 | X10: =SUMPRODUCT((HY!$C$4:$C$992<>"")*(HY!$W$4:$W$992="C")) -> 0 | Z10: =X10 -> 0 | AA10: =SUMPRODUCT((HY!$C$4:$C$992<>"")*(HY!$X$4:$X$992<>"")) -> 0 | AB10: =SUMPRODUCT((HY!$C$4:$C$992<>"")*(HY!$Y$4:$Y$992<>"")) -> 0 | AC10: =SUMPRODUCT((HY!$C$4:$C$992<>"")*(HY!$X$4:$X$992<>"")*(HY!$Y$4:$Y$992="")) -> 0 | AD10: =SUMPRODUCT((HY!$C$4:$C$992<>"")*(HY!$Z$4:$Z$992<>"")) -> 0 | AE10: =SUMPRODUCT((HY!$C$4:$C$992<>"")*(HY!$X$4:$X$992<>"")*(HY!$Z$4:$Z$992="")) -> 0 | AF10: =SUMPRODUCT((HY!$C$4:$C$992<>"")*(HY!$AA$4:$AA$992<>"")) -> 0 | AG10: =SUMPRODUCT((HY!$C$4:$C$992<>"")*(HY!$X$4:$X$992<>"")*(HY!$AA$4:$AA$992="")) -> 0 | AH10: =SUMPRODUCT((HY!$C$4:$C$992<>"")*(HY!$AB$4:$AB$992="A")) -> 0 | AI10: =SUMPRODUCT((HY!$C$4:$C$992<>"")*(HY!$AB$4:$AB$992="B")) -> 0 | AJ10: =SUMPRODUCT((HY!$C$4:$C$992<>"")*(HY!$AB$4:$AB$992="C")) -> 0
A11: Electrical & Comms | B11: {=SUMPRODUCT((EL!$C$4:$C$920<>"")*(EL!$D$4:$D$920<>""))} -> 47 | C11: =SUMPRODUCT((EL!$C$4:$C$920<>"")*(EL!$N$4:$N$920<>"")) -> 47 | D11: =SUMPRODUCT((EL!$C$4:$C$920<>"")*(EL!$O$4:$O$920<>"")) -> 42 | E11: =SUMPRODUCT((EL!$C$4:$C$920<>"")*(EL!$N$4:$N$920<>"")*(EL!$O$4:$O$920="")) -> 5 | F11: =SUMPRODUCT((EL!$C$4:$C$920<>"")*(EL!$P$4:$P$920<>"")) -> 18 | G11: =SUMPRODUCT((EL!$C$4:$C$920<>"")*(EL!$N$4:$N$920<>"")*(EL!$P$4:$P$920="")) -> 29 | H11: =SUMPRODUCT((EL!$C$4:$C$920<>"")*(EL!$Q$4:$Q$920<>"")) -> 0 | I11: =SUMPRODUCT((EL!$C$4:$C$920<>"")*(EL!$N$4:$N$920<>"")*(EL!$Q$4:$Q$920="")) -> 47 | J11: =SUMPRODUCT((EL!$C$4:$C$920<>"")*(EL!$R$4:$R$920="A")) -> 0 | K11: =SUMPRODUCT((EL!$C$4:$C$920<>"")*(EL!$R$4:$R$920="B")) -> 0 | L11: =SUMPRODUCT((EL!$C$4:$C$920<>"")*(EL!$R$4:$R$920="C")) -> 0 | N11: =L11 -> 0 | O11: =SUMPRODUCT((EL!$C$4:$C$920<>"")*(EL!$S$4:$S$920<>"")) -> 0 | P11: =SUMPRODUCT((EL!$C$4:$C$920<>"")*(EL!$T$4:$T$920<>"")) -> 0 | Q11: =SUMPRODUCT((EL!$C$4:$C$920<>"")*(EL!$S$4:$S$920<>"")*(EL!$T$4:$T$920="")) -> 0 | R11: =SUMPRODUCT((EL!$C$4:$C$920<>"")*(EL!$U$4:$U$920<>"")) -> 0 | S11: =SUMPRODUCT((EL!$C$4:$C$920<>"")*(EL!$S$4:$S$920<>"")*(EL!$U$4:$U$920="")) -> 0 | T11: =SUMPRODUCT((EL!$C$4:$C$920<>"")*(EL!$V$4:$V$920<>"")) -> 0 | U11: =SUMPRODUCT((EL!$C$4:$C$920<>"")*(EL!$S$4:$S$920<>"")*(EL!$V$4:$V$920="")) -> 0 | V11: =SUMPRODUCT((EL!$C$4:$C$920<>"")*(EL!$W$4:$W$920="A")) -> 0 | W11: =SUMPRODUCT((EL!$C$4:$C$920<>"")*(EL!$W$4:$W$920="B")) -> 0 | X11: =SUMPRODUCT((EL!$C$4:$C$920<>"")*(EL!$W$4:$W$920="C")) -> 0 | Z11: =X11 -> 0 | AA11: =SUMPRODUCT((EL!$C$4:$C$920<>"")*(EL!$X$4:$X$920<>"")) -> 0 | AB11: =SUMPRODUCT((EL!$C$4:$C$920<>"")*(EL!$Y$4:$Y$920<>"")) -> 0 | AC11: =SUMPRODUCT((EL!$C$4:$C$920<>"")*(EL!$X$4:$X$920<>"")*(EL!$Y$4:$Y$920="")) -> 0 | AD11: =SUMPRODUCT((EL!$C$4:$C$920<>"")*(EL!$Z$4:$Z$920<>"")) -> 0 | AE11: =SUMPRODUCT((EL!$C$4:$C$920<>"")*(EL!$X$4:$X$920<>"")*(EL!$Z$4:$Z$920="")) -> 0 | AF11: =SUMPRODUCT((EL!$C$4:$C$920<>"")*(EL!$AA$4:$AA$920<>"")) -> 0 | AG11: =SUMPRODUCT((EL!$C$4:$C$920<>"")*(EL!$X$4:$X$920<>"")*(EL!$AA$4:$AA$920="")) -> 0 | AH11: =SUMPRODUCT((EL!$C$4:$C$920<>"")*(EL!$AB$4:$AB$920="A")) -> 0 | AI11: =SUMPRODUCT((EL!$C$4:$C$920<>"")*(EL!$AB$4:$AB$920="B")) -> 0 | AJ11: =SUMPRODUCT((EL!$C$4:$C$920<>"")*(EL!$AB$4:$AB$920="C")) -> 0
A12: Overall | B12: =SUM(B6:B11) -> 135 | C12: =SUM(C6:C11) -> 135 | D12: =SUM(D6:D11) -> 126 | E12: =SUM(E6:E11) -> 9 | F12: =SUM(F6:F11) -> 68 | G12: =SUM(G6:G11) -> 67 | H12: =SUM(H6:H11) -> 26 | I12: =SUM(I6:I11) -> 109 | ... L12: =SUM(L6:L11) -> 0 | N12: =SUM(N6:N11) -> 0 | O12: =SUM(O6:O11) -> 1 | P12: =SUM(P6:P11) -> 0 | Q12: =SUM(Q6:Q11) -> 1 | R12: =SUM(R6:R11) -> 0 | S12: =SUM(S6:S11) -> 1 | T12: =SUM(T6:T11) -> 0 | U12: =SUM(U6:U11) -> 1 | ... X12: =SUM(X6:X11) -> 0 | Z12: =SUM(Z6:Z11) -> 0 | AA12: =SUM(AA6:AA11) -> 0 | AB12: =SUM(AB6:AB11) -> 0 | AC12: =SUM(AC6:AC11) -> 0 | AD12: =SUM(AD6:AD11) -> 0 | AE12: =SUM(AE6:AE11) -> 0 | AF12: =SUM(AF6:AF11) -> 0 | AG12: =SUM(AG6:AG11) -> 0 | ... AJ12: =SUM(AJ6:AJ11) -> 0
C119: Trade | D119: Submission | E119: Submitted | F119: Approved by All | G119: Rejected | H119: Pending submission | I119: CTA Approved | J119: CTA Outstanding | K119: AUR Approved | L119: AUR Outstanding | M119: STT Approved | N119: STT outstanding
C120: Structural | D120: =B6 -> 1 | E120: {=SUMPRODUCT((ST!$C$4:$C$1000<>"")*(ST!$D$4:$D$1000<>"")*((ST!$J$4:$J$1000="A")+(ST!$J$4:$J$1000="B")+(ST!$J$4:$J$1000="PENDING")))} -> 1 | F120: =SUMPRODUCT((ST!$C$4:$C$1000<>"")*(ST!$D$4:$D$1000<>"")*((ST!$J$4:$J$1000="A")+(ST!$J$4:$J$1000="B"))) -> 0 | G120: =SUMPRODUCT((ST!$C$4:$C$1000<>"")*(ST!$D$4:$D$1000<>"")*(ST!$J$4:$J$1000="C")) -> 0 | H120: =SUMPRODUCT((ST!$C$4:$C$1000<>"")*(ST!$D$4:$D$1000<>"")*((ST!$J$4:$J$1000="C")+(ST!$J$4:$J$1000=""))) -> 0 | I120: {=SUMPRODUCT((ST!$C$4:$C$991<>"")*(ST!$D$4:$D$991<>"")*((ST!$H$4:$H$991=0)*(ST!$N$4:$N$991<>"")+(ST!$H$4:$H$991=1)*(ST!$S$4:$S$991<>"")+(ST!$H$4:$H$991=2)*(ST!$X$4:$X$991<>"")))} -> 1 | J120: {=SUMPRODUCT((ST!$C$4:$C$1000<>"")*(ST!$D$4:$D$1000<>"")*(ST!$I$4:$I$1000="CTA"))} -> 0 | K120: {=SUMPRODUCT((ST!$C$4:$C$991<>"")*(ST!$D$4:$D$991<>"")*((ST!$H$4:$H$991=0)*(ST!$O$4:$O$991<>"")+(ST!$H$4:$H$991=1)*(ST!$T$4:$T$991<>"")+(ST!$H$4:$H$991=2)*(ST!$Y$4:$Y$991<>"")))} -> 1 | L120: =SUMPRODUCT((ST!$C$4:$C$1000<>"")*(ST!$D$4:$D$1000<>"")*(ST!$I$4:$I$1000="AUR")) -> 0 | M120: {=SUMPRODUCT((ST!$C$4:$C$991<>"")*(ST!$D$4:$D$991<>"")*((ST!$H$4:$H$991=0)*(ST!$P$4:$P$991<>"")+(ST!$H$4:$H$991=1)*(ST!$U$4:$U$991<>"")+(ST!$H$4:$H$991=2)*(ST!$Z$4:$Z$991<>"")))} -> 0 | N120: =SUMPRODUCT((ST!$C$4:$C$1000<>"")*(ST!$D$4:$D$1000<>"")*(ST!$I$4:$I$1000="STT")) -> 1
C121: Architectural | D121: =B7 -> 38 | E121: =SUMPRODUCT((AR!$C$4:$C$989<>"")*(AR!$D$4:$D$989<>"")*((AR!$J$4:$J$989="A")+(AR!$J$4:$J$989="B")+(AR!$J$4:$J$989="PENDING"))) -> 38 | F121: =SUMPRODUCT((AR!$C$4:$C$989<>"")*(AR!$D$4:$D$989<>"")*((AR!$J$4:$J$989="A")+(AR!$J$4:$J$989="B"))) -> 25 | G121: =SUMPRODUCT((AR!$C$4:$C$989<>"")*(AR!$D$4:$D$989<>"")*(AR!$J$4:$J$989="C")) -> 0 | H121: =SUMPRODUCT((AR!$C$4:$C$989<>"")*(AR!$D$4:$D$989<>"")*((AR!$J$4:$J$989="C")+(AR!$J$4:$J$989=""))) -> 0 | I121: {=SUMPRODUCT((AR!$C$4:$C$997<>"")*(AR!$D$4:$D$997<>"")*((AR!$H$4:$H$997=0)*(AR!$N$4:$N$997<>"")+(AR!$H$4:$H$997=1)*(AR!$S$4:$S$997<>"")+(AR!$H$4:$H$997=2)*(AR!$X$4:$X$997<>"")))} -> 36 | J121: {=SUMPRODUCT((AR!$C$4:$C$989<>"")*(AR!$D$4:$D$989<>"")*(AR!$I$4:$I$989="CTA"))} -> 2 | K121: {=SUMPRODUCT((AR!$C$4:$C$997<>"")*(AR!$D$4:$D$997<>"")*((AR!$H$4:$H$997=0)*(AR!$O$4:$O$997<>"")+(AR!$H$4:$H$997=1)*(AR!$T$4:$T$997<>"")+(AR!$H$4:$H$997=2)*(AR!$Y$4:$Y$997<>"")))} -> 36 | L121: =SUMPRODUCT((AR!$C$4:$C$989<>"")*(AR!$D$4:$D$989<>"")*(AR!$I$4:$I$989="AUR")) -> 0 | M121: {=SUMPRODUCT((AR!$C$4:$C$997<>"")*(AR!$D$4:$D$997<>"")*((AR!$H$4:$H$997=0)*(AR!$P$4:$P$997<>"")+(AR!$H$4:$H$997=1)*(AR!$U$4:$U$997<>"")+(AR!$H$4:$H$997=2)*(AR!$Z$4:$Z$997<>"")))} -> 24 | N121: =SUMPRODUCT((AR!$C$4:$C$989<>"")*(AR!$D$4:$D$989<>"")*(AR!$I$4:$I$989="ART")) -> 0
C122: AR & ST | D122: =SUM(D120:D121) -> 39 | E122: =SUM(E120:E121) -> 39 | F122: =SUM(F120:F121) -> 25 | G122: =SUM(G120:G121) -> 0 | H122: =SUM(H120:H121) -> 0 | I122: =SUM(I120:I121) -> 37 | J122: =SUM(J120:J121) -> 2 | K122: =SUM(K120:K121) -> 37 | ... N122: =SUM(N120:N121) -> 1
C123: Mechanical | D123: =B8 -> 24 | E123: =SUMPRODUCT((ME!$C$4:$C$981<>"")*(ME!$D$4:$D$981<>"")*((ME!$K$4:$K$981="A")+(ME!$K$4:$K$981="B")+(ME!$K$4:$K$981="PENDING"))) -> 21 | F123: =SUMPRODUCT((ME!$C$4:$C$981<>"")*(ME!$D$4:$D$981<>"")*((ME!$K$4:$K$981="A")+(ME!$K$4:$K$981="B"))) -> 2 | G123: =SUMPRODUCT((ME!$C$4:$C$981<>"")*(ME!$D$4:$D$981<>"")*(ME!$K$4:$K$981="C")) -> 0 | H123: =SUMPRODUCT((ME!$C$4:$C$981<>"")*(ME!$D$4:$D$981<>"")*((ME!$K$4:$K$981="C")+(ME!$K$4:$K$981=""))) -> 0 | I123: {=SUMPRODUCT((ME!$C$4:$C$989<>"")*(ME!$D$4:$D$989<>"")*((ME!$H$4:$H$989=0)*(ME!$O$4:$O$989<>"")+(ME!$H$4:$H$989=1)*(ME!$T$4:$T$989<>"")+(ME!$H$4:$H$989=2)*(ME!$Y$4:$Y$989<>"")))} -> 21 | J123: {=SUMPRODUCT((ME!$C$4:$C$981<>"")*(ME!$D$4:$D$981<>"")*(ME!$J$4:$J$981="CTA"))} -> 2 | K123: {=SUMPRODUCT((ME!$C$4:$C$989<>"")*(ME!$D$4:$D$989<>"")*((ME!$H$4:$H$989=0)*(ME!$P$4:$P$989<>"")+(ME!$H$4:$H$989=1)*(ME!$U$4:$U$989<>"")+(ME!$H$4:$H$989=2)*(ME!$Z$4:$Z$989<>"")))} -> 12 | L123: =SUMPRODUCT((ME!$C$4:$C$981<>"")*(ME!$D$4:$D$981<>"")*(ME!$J$4:$J$981="AUR")) -> 10 | M123: {=SUMPRODUCT((ME!$C$4:$C$989<>"")*(ME!$D$4:$D$989<>"")*((ME!$H$4:$H$989=0)*(ME!$Q$4:$Q$989<>"")+(ME!$H$4:$H$989=1)*(ME!$V$4:$V$989<>"")+(ME!$H$4:$H$989=2)*(ME!$AA$4:$AA$989<>"")))} -> 2 | N123: =SUMPRODUCT((ME!$C$4:$C$981<>"")*(ME!$D$4:$D$981<>"")*(ME!$J$4:$J$981="MET")) -> 0
C124: Fire | D124: =B9 -> 14 | E124: =SUMPRODUCT((FI!$C$4:$C$976<>"")*(FI!$D$4:$D$976<>"")*((FI!$K$4:$K$976="A")+(FI!$K$4:$K$976="B")+(FI!$K$4:$K$976="PENDING"))) -> 14 | F124: =SUMPRODUCT((FI!$C$4:$C$976<>"")*(FI!$D$4:$D$976<>"")*((FI!$K$4:$K$976="A")+(FI!$K$4:$K$976="B"))) -> 0 | G124: =SUMPRODUCT((FI!$C$4:$C$976<>"")*(FI!$D$4:$D$976<>"")*(FI!$K$4:$K$976="C")) -> 0 | H124: =SUMPRODUCT((FI!$C$4:$C$976<>"")*(FI!$D$4:$D$976<>"")*((FI!$K$4:$K$976="C")+(FI!$K$4:$K$976=""))) -> 0 | I124: {=SUMPRODUCT((FI!$C$4:$C$991<>"")*(FI!$D$4:$D$991<>"")*((FI!$H$4:$H$991=0)*(FI!$O$4:$O$991<>"")+(FI!$H$4:$H$991=1)*(FI!$T$4:$T$991<>"")+(FI!$H$4:$H$991=2)*(FI!$Y$4:$Y$991<>"")))} -> 14 | J124: {=SUMPRODUCT((FI!$C$4:$C$991<>"")*(FI!$D$4:$D$991<>"")*(FI!$J$4:$J$991="CTA"))} -> 0 | K124: {=SUMPRODUCT((FI!$C$4:$C$991<>"")*(FI!$D$4:$D$991<>"")*((FI!$H$4:$H$991=0)*(FI!$O$4:$O$991<>"")+(FI!$H$4:$H$991=1)*(FI!$T$4:$T$991<>"")+(FI!$H$4:$H$991=2)*(FI!$Y$4:$Y$991<>"")))} -> 14 | L124: =SUMPRODUCT((FI!$C$4:$C$976<>"")*(FI!$D$4:$D$976<>"")*(FI!$J$4:$J$976="AUR")) -> 14 | M124: {=SUMPRODUCT((FI!$C$4:$C$991<>"")*(FI!$D$4:$D$991<>"")*((FI!$H$4:$H$991=0)*(FI!$Q$4:$Q$991<>"")+(FI!$H$4:$H$991=1)*(FI!$V$4:$V$991<>"")+(FI!$H$4:$H$991=2)*(FI!$AA$4:$AA$991<>"")))} -> 0 | N124: =SUMPRODUCT((FI!$C$4:$C$976<>"")*(FI!$D$4:$D$976<>"")*(FI!$J$4:$J$976="FIT")) -> 0
C125: Hydraulics | D125: =B10 -> 11 | E125: =SUMPRODUCT((HY!$C$4:$C$992<>"")*(HY!$D$4:$D$992<>"")*((HY!$K$4:$K$992="A")+(HY!$K$4:$K$992="B")+(HY!$K$4:$K$992="PENDING"))) -> 11 | F125: =SUMPRODUCT((HY!$C$4:$C$992<>"")*(HY!$D$4:$D$992<>"")*((HY!$K$4:$K$992="A")+(HY!$K$4:$K$992="B"))) -> 0 | G125: =SUMPRODUCT((HY!$C$4:$C$992<>"")*(HY!$D$4:$D$992<>"")*(HY!$K$4:$K$992="C")) -> 0 | H125: =SUMPRODUCT((HY!$C$4:$C$992<>"")*(HY!$D$4:$D$992<>"")*((HY!$K$4:$K$992="C")+(HY!$K$4:$K$992=""))) -> 0 | I125: {=SUMPRODUCT((HY!$C$4:$C$991<>"")*(HY!$D$4:$D$991<>"")*((HY!$H$4:$H$991=0)*(HY!$O$4:$O$991<>"")+(HY!$H$4:$H$991=1)*(HY!$T$4:$T$991<>"")+(HY!$H$4:$H$991=2)*(HY!$Y$4:$Y$991<>"")))} -> 11 | J125: {=SUMPRODUCT((HY!$C$4:$C$992<>"")*(HY!$D$4:$D$992<>"")*(HY!$J$4:$J$992="CTA"))} -> 0 | K125: {=SUMPRODUCT((HY!$C$4:$C$991<>"")*(HY!$D$4:$D$991<>"")*((HY!$H$4:$H$991=0)*(HY!$P$4:$P$991<>"")+(HY!$H$4:$H$991=1)*(HY!$U$4:$U$991<>"")+(HY!$H$4:$H$991=2)*(HY!$Z$4:$Z$991<>"")))} -> 0 | L125: =SUMPRODUCT((HY!$C$4:$C$992<>"")*(HY!$D$4:$D$992<>"")*(HY!$J$4:$J$992="AUR")) -> 11 | M125: {=SUMPRODUCT((HY!$C$4:$C$991<>"")*(HY!$D$4:$D$991<>"")*((HY!$H$4:$H$991=0)*(HY!$Q$4:$Q$991<>"")+(HY!$H$4:$H$991=1)*(HY!$V$4:$V$991<>"")+(HY!$H$4:$H$991=2)*(HY!$AA$4:$AA$991<>"")))} -> 0 | N125: =SUMPRODUCT((HY!$C$4:$C$992<>"")*(HY!$D$4:$D$992<>"")*(HY!$J$4:$J$992="HYT")) -> 0
C126: Electrical & Comms | D126: =B11 -> 47 | E126: {=SUMPRODUCT((EL!$C$4:$C$920<>"")*(EL!$D$4:$D$920<>"")*((EL!$K$4:$K$920="A")+(EL!$K$4:$K$920="B")+(EL!$K$4:$K$920="PENDING")))} -> 47 | F126: {=SUMPRODUCT((EL!$C$4:$C$920<>"")*(EL!$D$4:$D$920<>"")*((EL!$K$4:$K$920="A")+(EL!$K$4:$K$920="B")))} -> 0 | G126: {=SUMPRODUCT((EL!$C$4:$C$920<>"")*(EL!$D$4:$D$920<>"")*(EL!$K$4:$K$920="C"))} -> 0 | H126: {=SUMPRODUCT((EL!$C$4:$C$920<>"")*(EL!$D$4:$D$920<>"")*((EL!$K$4:$K$920="C")+(EL!$K$4:$K$920="")))} -> 0 | I126: {=SUMPRODUCT((EL!$C$4:$C$979<>"")*(EL!$D$4:$D$979<>"")*((EL!$H$4:$H$979=0)*(EL!$O$4:$O$979<>"")+(EL!$H$4:$H$979=1)*(EL!$T$4:$T$979<>"")+(EL!$H$4:$H$979=2)*(EL!$Y$4:$Y$979<>"")))} -> 42 | J126: {=SUMPRODUCT((EL!$C$4:$C$920<>"")*(EL!$D$4:$D$920<>"")*(EL!$J$4:$J$920="CTA"))} -> 5 | K126: {=SUMPRODUCT((EL!$C$4:$C$979<>"")*(EL!$D$4:$D$979<>"")*((EL!$H$4:$H$979=0)*(EL!$P$4:$P$979<>"")+(EL!$H$4:$H$979=1)*(EL!$U$4:$U$979<>"")+(EL!$H$4:$H$979=2)*(EL!$Z$4:$Z$979<>"")))} -> 18 | L126: {=SUMPRODUCT((EL!$C$4:$C$920<>"")*(EL!$D$4:$D$920<>"")*(EL!$J$4:$J$920="AUR"))} -> 24 | M126: {=SUMPRODUCT((EL!$C$4:$C$979<>"")*(EL!$D$4:$D$979<>"")*((EL!$H$4:$H$979=0)*(EL!$Q$4:$Q$979<>"")+(EL!$H$4:$H$979=1)*(EL!$V$4:$V$979<>"")+(EL!$H$4:$H$979=2)*(EL!$AA$4:$AA$979<>"")))} -> 0 | N126: {=SUMPRODUCT((EL!$C$4:$C$920<>"")*(EL!$D$4:$D$920<>"")*(EL!$J$4:$J$920="ELT"))} -> 0
C127: Overall | D127: =SUM(D122:D126) -> 135 | E127: =SUM(E122:E126) -> 132 | F127: =SUM(F122:F126) -> 27 | G127: =SUM(G122:G126) -> 0 | H127: =SUM(H122:H126) -> 0 | I127: =SUM(I122:I126) -> 125 | J127: =SUM(J122:J126) -> 9 | K127: =SUM(K122:K126) -> 81 | ... N127: =SUM(N122:N126) -> 1
C128: AR & ST | E128: =E122/$D122 -> 1 | F128: =F122/$D122 -> 0.64102564 | G128: =G122/$D122 -> 0 | H128: =H122/$D122 -> 0 | I128: =I122/$D122 -> 0.94871795 | J128: =J122/$D122 -> 0.051282051 | K128: =K122/$D122 -> 0.94871795 | L128: =L122/$D122 -> 0 | ... N128: =N122/$D122 -> 0.025641026
C129: Mechanical | E129: =E123/$D123 -> 0.875 | F129: =F123/$D123 -> 0.083333333 | G129: =G123/$D123 -> 0 | H129: =H123/$D123 -> 0 | I129: =I123/$D123 -> 0.875 | J129: =J123/$D123 -> 0.083333333 | K129: =K123/$D123 -> 0.5 | L129: =L123/$D123 -> 0.41666667 | ... N129: =N123/$D123 -> 0
C130: Fire | E130: =E124/$D124 -> 1 | F130: =F124/$D124 -> 0 | G130: =G124/$D124 -> 0 | H130: =H124/$D124 -> 0 | I130: =I124/$D124 -> 1 | J130: =J124/$D124 -> 0 | K130: =K124/$D124 -> 1 | L130: =L124/$D124 -> 1 | ... N130: =N124/$D124 -> 0
C131: Hydraulics | E131: =E125/$D125 -> 1 | F131: =F125/$D125 -> 0 | G131: =G125/$D125 -> 0 | H131: =H125/$D125 -> 0 | I131: =I125/$D125 -> 1 | J131: =J125/$D125 -> 0 | K131: =K125/$D125 -> 0 | L131: =L125/$D125 -> 1 | ... N131: =N125/$D125 -> 0
C132: Electrical & Comms | E132: =E126/$D126 -> 1 | F132: =F126/$D126 -> 0 | G132: =G126/$D126 -> 0 | H132: =H126/$D126 -> 0 | I132: =I126/$D126 -> 0.89361702 | J132: =J126/$D126 -> 0.10638298 | K132: =K126/$D126 -> 0.38297872 | L132: =L126/$D126 -> 0.5106383 | ... N132: =N126/$D126 -> 0
C133: Overall | E133: =E127/$D127 -> 0.97777778 | F133: =F127/$D127 -> 0.2 | G133: =G127/$D127 -> 0 | H133: =H127/$D127 -> 0 | I133: =I127/$D127 -> 0.92592593 | J133: =J127/$D127 -> 0.066666667 | K133: =K127/$D127 -> 0.6 | L133: =L127/$D127 -> 0.43703704 | ... N133: =N127/$D127 -> 0.0074074074
E135: Do not tounch

Sheet Summary
A2: Request for Information Summary
B5: Structural
B6: w/e | C6: Total Expected | D6: Planned Submission | E6: Actual Submitted | F6: Status
F7: Under Review | I7: A | J7: B | K7: C
F8: CTA | G8: AUR | H8: STT
B9: 46027 | C9: {=SUMPRODUCT((ST!$C$4:$C$501<>"")*(ST!$D$4:$D$501<>"")*((ST!$F$4:$F$501<=B9)+(ST!$F$4:$F$501>B9)))} -> 1 | D9: {=SUMPRODUCT((ST!$C$4:$C$501<>"")*(ST!$D$4:$D$501<>"")*(ST!$E$4:$E$501<=B9))} -> 1 | E9: {=SUMPRODUCT((ST!$C$4:$C$501<>"")*(ST!$D$4:$D$501<>"")*(ST!$F$4:$F$501<>"")*(ST!$F$4:$F$501<=B9))} -> 0 | F9: {=SUMPRODUCT((ST!$C$4:$C$501<>"")*(ST!$D$4:$D$501<>"")*(ST!$F$4:$F$501<=$B9)*(ST!$J$4:$J$501="Pending")*(ST!$I$4:$I$501="CTA"))} -> 0 | G9: {=SUMPRODUCT((ST!$C$4:$C$501<>"")*(ST!$D$4:$D$501<>"")*(ST!$F$4:$F$501<=$B9)*(ST!$J$4:$J$501="Pending")*(ST!$I$4:$I$501="AUR"))} -> 0 | H9: {=SUMPRODUCT((ST!$C$4:$C$501<>"")*(ST!$D$4:$D$501<>"")*(ST!$F$4:$F$501<=$B9)*(ST!$J$4:$J$501="Pending")*(ST!$I$4:$I$501="STT"))} -> 0 | I9: {=SUMPRODUCT((ST!$C$4:$C$501<>"")*(ST!$D$4:$D$501<>"")*(ST!$F$4:$F$501<=$B9)*(ST!$J$4:$J$501="A"))} -> 0 | J9: {=SUMPRODUCT((ST!$C$4:$C$501<>"")*(ST!$D$4:$D$501<>"")*(ST!$F$4:$F$501<=$B9)*(ST!$J$4:$J$501="B"))} -> 0 | K9: {=SUMPRODUCT((ST!$C$4:$C$501<>"")*(ST!$D$4:$D$501<>"")*(ST!$F$4:$F$501<=$B9)*(ST!$J$4:$J$501="C"))} -> 0
B10: =B9+7 -> 46034 | C10: {=SUMPRODUCT((ST!$C$4:$C$501<>"")*(ST!$D$4:$D$501<>"")*((ST!$F$4:$F$501<=B10)+(ST!$F$4:$F$501>B10)))} -> 1 | D10: {=SUMPRODUCT((ST!$C$4:$C$501<>"")*(ST!$D$4:$D$501<>"")*(ST!$E$4:$E$501<=B10))} -> 1 | E10: {=SUMPRODUCT((ST!$C$4:$C$501<>"")*(ST!$D$4:$D$501<>"")*(ST!$F$4:$F$501<>"")*(ST!$F$4:$F$501<=B10))} -> 0 | F10: {=SUMPRODUCT((ST!$C$4:$C$501<>"")*(ST!$D$4:$D$501<>"")*(ST!$F$4:$F$501<=$B10)*(ST!$J$4:$J$501="Pending")*(ST!$I$4:$I$501="CTA"))} -> 0 | G10: {=SUMPRODUCT((ST!$C$4:$C$501<>"")*(ST!$D$4:$D$501<>"")*(ST!$F$4:$F$501<=$B10)*(ST!$J$4:$J$501="Pending")*(ST!$I$4:$I$501="AUR"))} -> 0 | H10: {=SUMPRODUCT((ST!$C$4:$C$501<>"")*(ST!$D$4:$D$501<>"")*(ST!$F$4:$F$501<=$B10)*(ST!$J$4:$J$501="Pending")*(ST!$I$4:$I$501="STT"))} -> 0 | I10: {=SUMPRODUCT((ST!$C$4:$C$501<>"")*(ST!$D$4:$D$501<>"")*(ST!$F$4:$F$501<=$B10)*(ST!$J$4:$J$501="A"))} -> 0 | J10: {=SUMPRODUCT((ST!$C$4:$C$501<>"")*(ST!$D$4:$D$501<>"")*(ST!$F$4:$F$501<=$B10)*(ST!$J$4:$J$501="B"))} -> 0 | K10: {=SUMPRODUCT((ST!$C$4:$C$501<>"")*(ST!$D$4:$D$501<>"")*(ST!$F$4:$F$501<=$B10)*(ST!$J$4:$J$501="C"))} -> 0
B11: =B10+7 -> 46041 | C11: {=SUMPRODUCT((ST!$C$4:$C$501<>"")*(ST!$D$4:$D$501<>"")*((ST!$F$4:$F$501<=B11)+(ST!$F$4:$F$501>B11)))} -> 1 | D11: {=SUMPRODUCT((ST!$C$4:$C$501<>"")*(ST!$D$4:$D$501<>"")*(ST!$E$4:$E$501<=B11))} -> 1 | E11: {=SUMPRODUCT((ST!$C$4:$C$501<>"")*(ST!$D$4:$D$501<>"")*(ST!$F$4:$F$501<>"")*(ST!$F$4:$F$501<=B11))} -> 0 | F11: {=SUMPRODUCT((ST!$C$4:$C$501<>"")*(ST!$D$4:$D$501<>"")*(ST!$F$4:$F$501<=$B11)*(ST!$J$4:$J$501="Pending")*(ST!$I$4:$I$501="CTA"))} -> 0 | G11: {=SUMPRODUCT((ST!$C$4:$C$501<>"")*(ST!$D$4:$D$501<>"")*(ST!$F$4:$F$501<=$B11)*(ST!$J$4:$J$501="Pending")*(ST!$I$4:$I$501="AUR"))} -> 0 | H11: {=SUMPRODUCT((ST!$C$4:$C$501<>"")*(ST!$D$4:$D$501<>"")*(ST!$F$4:$F$501<=$B11)*(ST!$J$4:$J$501="Pending")*(ST!$I$4:$I$501="STT"))} -> 0 | I11: {=SUMPRODUCT((ST!$C$4:$C$501<>"")*(ST!$D$4:$D$501<>"")*(ST!$F$4:$F$501<=$B11)*(ST!$J$4:$J$501="A"))} -> 0 | J11: {=SUMPRODUCT((ST!$C$4:$C$501<>"")*(ST!$D$4:$D$501<>"")*(ST!$F$4:$F$501<=$B11)*(ST!$J$4:$J$501="B"))} -> 0 | K11: {=SUMPRODUCT((ST!$C$4:$C$501<>"")*(ST!$D$4:$D$501<>"")*(ST!$F$4:$F$501<=$B11)*(ST!$J$4:$J$501="C"))} -> 0
B12: =B11+7 -> 46048 | C12: {=SUMPRODUCT((ST!$C$4:$C$501<>"")*(ST!$D$4:$D$501<>"")*((ST!$F$4:$F$501<=B12)+(ST!$F$4:$F$501>B12)))} -> 1 | D12: {=SUMPRODUCT((ST!$C$4:$C$501<>"")*(ST!$D$4:$D$501<>"")*(ST!$E$4:$E$501<=B12))} -> 1 | E12: {=SUMPRODUCT((ST!$C$4:$C$501<>"")*(ST!$D$4:$D$501<>"")*(ST!$F$4:$F$501<>"")*(ST!$F$4:$F$501<=B12))} -> 0 | F12: {=SUMPRODUCT((ST!$C$4:$C$501<>"")*(ST!$D$4:$D$501<>"")*(ST!$F$4:$F$501<=$B12)*(ST!$J$4:$J$501="Pending")*(ST!$I$4:$I$501="CTA"))} -> 0 | G12: {=SUMPRODUCT((ST!$C$4:$C$501<>"")*(ST!$D$4:$D$501<>"")*(ST!$F$4:$F$501<=$B12)*(ST!$J$4:$J$501="Pending")*(ST!$I$4:$I$501="AUR"))} -> 0 | H12: {=SUMPRODUCT((ST!$C$4:$C$501<>"")*(ST!$D$4:$D$501<>"")*(ST!$F$4:$F$501<=$B12)*(ST!$J$4:$J$501="Pending")*(ST!$I$4:$I$501="STT"))} -> 0 | I12: {=SUMPRODUCT((ST!$C$4:$C$501<>"")*(ST!$D$4:$D$501<>"")*(ST!$F$4:$F$501<=$B12)*(ST!$J$4:$J$501="A"))} -> 0 | J12: {=SUMPRODUCT((ST!$C$4:$C$501<>"")*(ST!$D$4:$D$501<>"")*(ST!$F$4:$F$501<=$B12)*(ST!$J$4:$J$501="B"))} -> 0 | K12: {=SUMPRODUCT((ST!$C$4:$C$501<>"")*(ST!$D$4:$D$501<>"")*(ST!$F$4:$F$501<=$B12)*(ST!$J$4:$J$501="C"))} -> 0
B13: =B12+7 -> 46055 | C13: {=SUMPRODUCT((ST!$C$4:$C$501<>"")*(ST!$D$4:$D$501<>"")*((ST!$F$4:$F$501<=B13)+(ST!$F$4:$F$501>B13)))} -> 1 | D13: {=SUMPRODUCT((ST!$C$4:$C$501<>"")*(ST!$D$4:$D$501<>"")*(ST!$E$4:$E$501<=B13))} -> 1 | E13: {=SUMPRODUCT((ST!$C$4:$C$501<>"")*(ST!$D$4:$D$501<>"")*(ST!$F$4:$F$501<>"")*(ST!$F$4:$F$501<=B13))} -> 0 | F13: {=SUMPRODUCT((ST!$C$4:$C$501<>"")*(ST!$D$4:$D$501<>"")*(ST!$F$4:$F$501<=$B13)*(ST!$J$4:$J$501="Pending")*(ST!$I$4:$I$501="CTA"))} -> 0 | G13: {=SUMPRODUCT((ST!$C$4:$C$501<>"")*(ST!$D$4:$D$501<>"")*(ST!$F$4:$F$501<=$B13)*(ST!$J$4:$J$501="Pending")*(ST!$I$4:$I$501="AUR"))} -> 0 | H13: {=SUMPRODUCT((ST!$C$4:$C$501<>"")*(ST!$D$4:$D$501<>"")*(ST!$F$4:$F$501<=$B13)*(ST!$J$4:$J$501="Pending")*(ST!$I$4:$I$501="STT"))} -> 0 | I13: {=SUMPRODUCT((ST!$C$4:$C$501<>"")*(ST!$D$4:$D$501<>"")*(ST!$F$4:$F$501<=$B13)*(ST!$J$4:$J$501="A"))} -> 0 | J13: {=SUMPRODUCT((ST!$C$4:$C$501<>"")*(ST!$D$4:$D$501<>"")*(ST!$F$4:$F$501<=$B13)*(ST!$J$4:$J$501="B"))} -> 0 | K13: {=SUMPRODUCT((ST!$C$4:$C$501<>"")*(ST!$D$4:$D$501<>"")*(ST!$F$4:$F$501<=$B13)*(ST!$J$4:$J$501="C"))} -> 0
B14: =B13+7 -> 46062 | C14: {=SUMPRODUCT((ST!$C$4:$C$501<>"")*(ST!$D$4:$D$501<>"")*((ST!$F$4:$F$501<=B14)+(ST!$F$4:$F$501>B14)))} -> 1 | D14: {=SUMPRODUCT((ST!$C$4:$C$501<>"")*(ST!$D$4:$D$501<>"")*(ST!$E$4:$E$501<=B14))} -> 1 | E14: {=SUMPRODUCT((ST!$C$4:$C$501<>"")*(ST!$D$4:$D$501<>"")*(ST!$F$4:$F$501<>"")*(ST!$F$4:$F$501<=B14))} -> 0 | F14: {=SUMPRODUCT((ST!$C$4:$C$501<>"")*(ST!$D$4:$D$501<>"")*(ST!$F$4:$F$501<=$B14)*(ST!$J$4:$J$501="Pending")*(ST!$I$4:$I$501="CTA"))} -> 0 | G14: {=SUMPRODUCT((ST!$C$4:$C$501<>"")*(ST!$D$4:$D$501<>"")*(ST!$F$4:$F$501<=$B14)*(ST!$J$4:$J$501="Pending")*(ST!$I$4:$I$501="AUR"))} -> 0 | H14: {=SUMPRODUCT((ST!$C$4:$C$501<>"")*(ST!$D$4:$D$501<>"")*(ST!$F$4:$F$501<=$B14)*(ST!$J$4:$J$501="Pending")*(ST!$I$4:$I$501="STT"))} -> 0 | I14: {=SUMPRODUCT((ST!$C$4:$C$501<>"")*(ST!$D$4:$D$501<>"")*(ST!$F$4:$F$501<=$B14)*(ST!$J$4:$J$501="A"))} -> 0 | J14: {=SUMPRODUCT((ST!$C$4:$C$501<>"")*(ST!$D$4:$D$501<>"")*(ST!$F$4:$F$501<=$B14)*(ST!$J$4:$J$501="B"))} -> 0 | K14: {=SUMPRODUCT((ST!$C$4:$C$501<>"")*(ST!$D$4:$D$501<>"")*(ST!$F$4:$F$501<=$B14)*(ST!$J$4:$J$501="C"))} -> 0
B15: =B14+7 -> 46069 | C15: {=SUMPRODUCT((ST!$C$4:$C$501<>"")*(ST!$D$4:$D$501<>"")*((ST!$F$4:$F$501<=B15)+(ST!$F$4:$F$501>B15)))} -> 1 | D15: {=SUMPRODUCT((ST!$C$4:$C$501<>"")*(ST!$D$4:$D$501<>"")*(ST!$E$4:$E$501<=B15))} -> 1 | E15: {=SUMPRODUCT((ST!$C$4:$C$501<>"")*(ST!$D$4:$D$501<>"")*(ST!$F$4:$F$501<>"")*(ST!$F$4:$F$501<=B15))} -> 1
B16: =B15+7 -> 46076 | C16: {=SUMPRODUCT((ST!$C$4:$C$501<>"")*(ST!$D$4:$D$501<>"")*((ST!$F$4:$F$501<=B16)+(ST!$F$4:$F$501>B16)))} -> 1 | D16: {=SUMPRODUCT((ST!$C$4:$C$501<>"")*(ST!$D$4:$D$501<>"")*(ST!$E$4:$E$501<=B16))} -> 1 | E16: {=SUMPRODUCT((ST!$C$4:$C$501<>"")*(ST!$D$4:$D$501<>"")*(ST!$F$4:$F$501<>"")*(ST!$F$4:$F$501<=B16))} -> 1
B17: =B16+7 -> 46083 | C17: {=SUMPRODUCT((ST!$C$4:$C$501<>"")*(ST!$D$4:$D$501<>"")*((ST!$F$4:$F$501<=B17)+(ST!$F$4:$F$501>B17)))} -> 1 | D17: {=SUMPRODUCT((ST!$C$4:$C$501<>"")*(ST!$D$4:$D$501<>"")*(ST!$E$4:$E$501<=B17))} -> 1 | E17: {=SUMPRODUCT((ST!$C$4:$C$501<>"")*(ST!$D$4:$D$501<>"")*(ST!$F$4:$F$501<>"")*(ST!$F$4:$F$501<=B17))} -> 1
B18: =B17+7 -> 46090 | C18: {=SUMPRODUCT((ST!$C$4:$C$501<>"")*(ST!$D$4:$D$501<>"")*((ST!$F$4:$F$501<=B18)+(ST!$F$4:$F$501>B18)))} -> 1 | D18: {=SUMPRODUCT((ST!$C$4:$C$501<>"")*(ST!$D$4:$D$501<>"")*(ST!$E$4:$E$501<=B18))} -> 1 | E18: {=SUMPRODUCT((ST!$C$4:$C$501<>"")*(ST!$D$4:$D$501<>"")*(ST!$F$4:$F$501<>"")*(ST!$F$4:$F$501<=B18))} -> 1
B22: Architectural
B23: w/e | C23: Total Expected | D23: Planned Submission | E23: Actual Submitted | F23: Status
F24: Under Review | I24: A | J24: B | K24: C
F25: CTA | G25: AUR | H25: STT
B26: =B9 -> 46027 | C26: {=SUMPRODUCT((AR!$C$4:$C$498<>"")*(AR!$D$4:$D$498<>"")*((AR!$E$4:$E$498<=B26)+(AR!$E$4:$E$498>B26)))} -> 38 | D26: {=SUMPRODUCT((AR!$C$4:$C$498<>"")*(AR!$D$4:$D$498<>"")*(AR!$E$4:$E$498<=B26))} -> 38 | E26: {=SUMPRODUCT((AR!$C$4:$C$498<>"")*(AR!$D$4:$D$498<>"")*(AR!$F$4:$F$498<>"")*(AR!$F$4:$F$498<=B26))} -> 0 | F26: {=SUMPRODUCT((AR!$C$4:$C$498<>"")*(AR!$D$4:$D$498<>"")*(AR!$F$4:$F$498<=$B26)*(AR!$J$4:$J$498="Pending")*(AR!$I$4:$I$498="CTA"))} -> 0 | G26: {=SUMPRODUCT((AR!$C$4:$C$498<>"")*(AR!$D$4:$D$498<>"")*(AR!$F$4:$F$498<=$B26)*(AR!$J$4:$J$498="Pending")*(AR!$I$4:$I$498="AUR"))} -> 0 | H26: {=SUMPRODUCT((AR!$C$4:$C$498<>"")*(AR!$D$4:$D$498<>"")*(AR!$F$4:$F$498<=$B26)*(AR!$J$4:$J$498="Pending")*(AR!$I$4:$I$498="STT"))} -> 0 | I26: {=SUMPRODUCT((AR!$C$4:$C$498<>"")*(AR!$D$4:$D$498<>"")*(AR!$F$4:$F$498<=$B26)*(AR!$J$4:$J$498="A"))} -> 0 | J26: {=SUMPRODUCT((AR!$C$4:$C$498<>"")*(AR!$D$4:$D$498<>"")*(AR!$F$4:$F$498<=$B26)*(AR!$J$4:$J$498="B"))} -> 0 | K26: {=SUMPRODUCT((AR!$C$4:$C$498<>"")*(AR!$D$4:$D$498<>"")*(AR!$F$4:$F$498<=$B26)*(AR!$J$4:$J$498="C"))} -> 0
B27: =B10 -> 46034 | C27: {=SUMPRODUCT((AR!$C$4:$C$498<>"")*(AR!$D$4:$D$498<>"")*((AR!$E$4:$E$498<=B27)+(AR!$E$4:$E$498>B27)))} -> 38 | D27: {=SUMPRODUCT((AR!$C$4:$C$498<>"")*(AR!$D$4:$D$498<>"")*(AR!$E$4:$E$498<=B27))} -> 38 | E27: {=SUMPRODUCT((AR!$C$4:$C$498<>"")*(AR!$D$4:$D$498<>"")*(AR!$F$4:$F$498<>"")*(AR!$F$4:$F$498<=B27))} -> 1 | F27: {=SUMPRODUCT((AR!$C$4:$C$498<>"")*(AR!$D$4:$D$498<>"")*(AR!$F$4:$F$498<=$B27)*(AR!$J$4:$J$498="Pending")*(AR!$I$4:$I$498="CTA"))} -> 1 | G27: {=SUMPRODUCT((AR!$C$4:$C$498<>"")*(AR!$D$4:$D$498<>"")*(AR!$F$4:$F$498<=$B27)*(AR!$J$4:$J$498="Pending")*(AR!$I$4:$I$498="AUR"))} -> 0 | H27: {=SUMPRODUCT((AR!$C$4:$C$498<>"")*(AR!$D$4:$D$498<>"")*(AR!$F$4:$F$498<=$B27)*(AR!$J$4:$J$498="Pending")*(AR!$I$4:$I$498="STT"))} -> 0 | I27: {=SUMPRODUCT((AR!$C$4:$C$498<>"")*(AR!$D$4:$D$498<>"")*(AR!$F$4:$F$498<=$B27)*(AR!$J$4:$J$498="A"))} -> 0 | J27: {=SUMPRODUCT((AR!$C$4:$C$498<>"")*(AR!$D$4:$D$498<>"")*(AR!$F$4:$F$498<=$B27)*(AR!$J$4:$J$498="B"))} -> 0 | K27: {=SUMPRODUCT((AR!$C$4:$C$498<>"")*(AR!$D$4:$D$498<>"")*(AR!$F$4:$F$498<=$B27)*(AR!$J$4:$J$498="C"))} -> 0
B28: =B11 -> 46041 | C28: {=SUMPRODUCT((AR!$C$4:$C$498<>"")*(AR!$D$4:$D$498<>"")*((AR!$E$4:$E$498<=B28)+(AR!$E$4:$E$498>B28)))} -> 38 | D28: {=SUMPRODUCT((AR!$C$4:$C$498<>"")*(AR!$D$4:$D$498<>"")*(AR!$E$4:$E$498<=B28))} -> 38 | E28: {=SUMPRODUCT((AR!$C$4:$C$498<>"")*(AR!$D$4:$D$498<>"")*(AR!$F$4:$F$498<>"")*(AR!$F$4:$F$498<=B28))} -> 12 | F28: {=SUMPRODUCT((AR!$C$4:$C$498<>"")*(AR!$D$4:$D$498<>"")*(AR!$F$4:$F$498<=$B28)*(AR!$J$4:$J$498="Pending")*(AR!$I$4:$I$498="CTA"))} -> 1 | G28: {=SUMPRODUCT((AR!$C$4:$C$498<>"")*(AR!$D$4:$D$498<>"")*(AR!$F$4:$F$498<=$B28)*(AR!$J$4:$J$498="Pending")*(AR!$I$4:$I$498="AUR"))} -> 0 | H28: {=SUMPRODUCT((AR!$C$4:$C$498<>"")*(AR!$D$4:$D$498<>"")*(AR!$F$4:$F$498<=$B28)*(AR!$J$4:$J$498="Pending")*(AR!$I$4:$I$498="STT"))} -> 1 | I28: {=SUMPRODUCT((AR!$C$4:$C$498<>"")*(AR!$D$4:$D$498<>"")*(AR!$F$4:$F$498<=$B28)*(AR!$J$4:$J$498="A"))} -> 1 | J28: {=SUMPRODUCT((AR!$C$4:$C$498<>"")*(AR!$D$4:$D$498<>"")*(AR!$F$4:$F$498<=$B28)*(AR!$J$4:$J$498="B"))} -> 9 | K28: {=SUMPRODUCT((AR!$C$4:$C$498<>"")*(AR!$D$4:$D$498<>"")*(AR!$F$4:$F$498<=$B28)*(AR!$J$4:$J$498="C"))} -> 0
B29: =B12 -> 46048 | C29: {=SUMPRODUCT((AR!$C$4:$C$498<>"")*(AR!$D$4:$D$498<>"")*((AR!$E$4:$E$498<=B29)+(AR!$E$4:$E$498>B29)))} -> 38 | D29: {=SUMPRODUCT((AR!$C$4:$C$498<>"")*(AR!$D$4:$D$498<>"")*(AR!$E$4:$E$498<=B29))} -> 38 | E29: {=SUMPRODUCT((AR!$C$4:$C$498<>"")*(AR!$D$4:$D$498<>"")*(AR!$F$4:$F$498<>"")*(AR!$F$4:$F$498<=B29))} -> 33 | F29: {=SUMPRODUCT((AR!$C$4:$C$498<>"")*(AR!$D$4:$D$498<>"")*(AR!$F$4:$F$498<=$B29)*(AR!$J$4:$J$498="Pending")*(AR!$I$4:$I$498="CTA"))} -> 1 | G29: {=SUMPRODUCT((AR!$C$4:$C$498<>"")*(AR!$D$4:$D$498<>"")*(AR!$F$4:$F$498<=$B29)*(AR!$J$4:$J$498="Pending")*(AR!$I$4:$I$498="AUR"))} -> 0 | H29: {=SUMPRODUCT((AR!$C$4:$C$498<>"")*(AR!$D$4:$D$498<>"")*(AR!$F$4:$F$498<=$B29)*(AR!$J$4:$J$498="Pending")*(AR!$I$4:$I$498="STT"))} -> 7 | I29: {=SUMPRODUCT((AR!$C$4:$C$498<>"")*(AR!$D$4:$D$498<>"")*(AR!$F$4:$F$498<=$B29)*(AR!$J$4:$J$498="A"))} -> 1 | J29: {=SUMPRODUCT((AR!$C$4:$C$498<>"")*(AR!$D$4:$D$498<>"")*(AR!$F$4:$F$498<=$B29)*(AR!$J$4:$J$498="B"))} -> 24 | K29: {=SUMPRODUCT((AR!$C$4:$C$498<>"")*(AR!$D$4:$D$498<>"")*(AR!$F$4:$F$498<=$B29)*(AR!$J$4:$J$498="C"))} -> 0
B30: =B13 -> 46055 | C30: {=SUMPRODUCT((AR!$C$4:$C$498<>"")*(AR!$D$4:$D$498<>"")*((AR!$E$4:$E$498<=B30)+(AR!$E$4:$E$498>B30)))} -> 38 | D30: {=SUMPRODUCT((AR!$C$4:$C$498<>"")*(AR!$D$4:$D$498<>"")*(AR!$E$4:$E$498<=B30))} -> 38 | E30: {=SUMPRODUCT((AR!$C$4:$C$498<>"")*(AR!$D$4:$D$498<>"")*(AR!$F$4:$F$498<>"")*(AR!$F$4:$F$498<=B30))} -> 33 | F30: {=SUMPRODUCT((AR!$C$4:$C$498<>"")*(AR!$D$4:$D$498<>"")*(AR!$F$4:$F$498<=$B30)*(AR!$J$4:$J$498="Pending")*(AR!$I$4:$I$498="CTA"))} -> 1 | G30: {=SUMPRODUCT((AR!$C$4:$C$498<>"")*(AR!$D$4:$D$498<>"")*(AR!$F$4:$F$498<=$B30)*(AR!$J$4:$J$498="Pending")*(AR!$I$4:$I$498="AUR"))} -> 0 | H30: {=SUMPRODUCT((AR!$C$4:$C$498<>"")*(AR!$D$4:$D$498<>"")*(AR!$F$4:$F$498<=$B30)*(AR!$J$4:$J$498="Pending")*(AR!$I$4:$I$498="STT"))} -> 7 | I30: {=SUMPRODUCT((AR!$C$4:$C$498<>"")*(AR!$D$4:$D$498<>"")*(AR!$F$4:$F$498<=$B30)*(AR!$J$4:$J$498="A"))} -> 1 | J30: {=SUMPRODUCT((AR!$C$4:$C$498<>"")*(AR!$D$4:$D$498<>"")*(AR!$F$4:$F$498<=$B30)*(AR!$J$4:$J$498="B"))} -> 24 | K30: {=SUMPRODUCT((AR!$C$4:$C$498<>"")*(AR!$D$4:$D$498<>"")*(AR!$F$4:$F$498<=$B30)*(AR!$J$4:$J$498="C"))} -> 0
B31: =B14 -> 46062 | C31: {=SUMPRODUCT((AR!$C$4:$C$498<>"")*(AR!$D$4:$D$498<>"")*((AR!$E$4:$E$498<=B31)+(AR!$E$4:$E$498>B31)))} -> 38 | D31: {=SUMPRODUCT((AR!$C$4:$C$498<>"")*(AR!$D$4:$D$498<>"")*(AR!$E$4:$E$498<=B31))} -> 38 | E31: {=SUMPRODUCT((AR!$C$4:$C$498<>"")*(AR!$D$4:$D$498<>"")*(AR!$F$4:$F$498<>"")*(AR!$F$4:$F$498<=B31))} -> 37 | F31: {=SUMPRODUCT((AR!$C$4:$C$498<>"")*(AR!$D$4:$D$498<>"")*(AR!$F$4:$F$498<=$B31)*(AR!$J$4:$J$498="Pending")*(AR!$I$4:$I$498="CTA"))} -> 1 | G31: {=SUMPRODUCT((AR!$C$4:$C$498<>"")*(AR!$D$4:$D$498<>"")*(AR!$F$4:$F$498<=$B31)*(AR!$J$4:$J$498="Pending")*(AR!$I$4:$I$498="AUR"))} -> 0 | H31: {=SUMPRODUCT((AR!$C$4:$C$498<>"")*(AR!$D$4:$D$498<>"")*(AR!$F$4:$F$498<=$B31)*(AR!$J$4:$J$498="Pending")*(AR!$I$4:$I$498="STT"))} -> 11 | I31: {=SUMPRODUCT((AR!$C$4:$C$498<>"")*(AR!$D$4:$D$498<>"")*(AR!$F$4:$F$498<=$B31)*(AR!$J$4:$J$498="A"))} -> 1 | J31: {=SUMPRODUCT((AR!$C$4:$C$498<>"")*(AR!$D$4:$D$498<>"")*(AR!$F$4:$F$498<=$B31)*(AR!$J$4:$J$498="B"))} -> 24 | K31: {=SUMPRODUCT((AR!$C$4:$C$498<>"")*(AR!$D$4:$D$498<>"")*(AR!$F$4:$F$498<=$B31)*(AR!$J$4:$J$498="C"))} -> 0
B32: =B15 -> 46069 | C32: {=SUMPRODUCT((AR!$C$4:$C$498<>"")*(AR!$D$4:$D$498<>"")*((AR!$E$4:$E$498<=B32)+(AR!$E$4:$E$498>B32)))} -> 38 | D32: {=SUMPRODUCT((AR!$C$4:$C$498<>"")*(AR!$D$4:$D$498<>"")*(AR!$E$4:$E$498<=B32))} -> 38 | E32: {=SUMPRODUCT((AR!$C$4:$C$498<>"")*(AR!$D$4:$D$498<>"")*(AR!$F$4:$F$498<>"")*(AR!$F$4:$F$498<=B32))} -> 38
B33: =B16 -> 46076 | C33: {=SUMPRODUCT((AR!$C$4:$C$498<>"")*(AR!$D$4:$D$498<>"")*((AR!$E$4:$E$498<=B33)+(AR!$E$4:$E$498>B33)))} -> 38 | D33: {=SUMPRODUCT((AR!$C$4:$C$498<>"")*(AR!$D$4:$D$498<>"")*(AR!$E$4:$E$498<=B33))} -> 38 | E33: {=SUMPRODUCT((AR!$C$4:$C$498<>"")*(AR!$D$4:$D$498<>"")*(AR!$F$4:$F$498<>"")*(AR!$F$4:$F$498<=B33))} -> 38
B34: =B17 -> 46083 | C34: {=SUMPRODUCT((AR!$C$4:$C$498<>"")*(AR!$D$4:$D$498<>"")*((AR!$E$4:$E$498<=B34)+(AR!$E$4:$E$498>B34)))} -> 38 | D34: {=SUMPRODUCT((AR!$C$4:$C$498<>"")*(AR!$D$4:$D$498<>"")*(AR!$E$4:$E$498<=B34))} -> 38 | E34: {=SUMPRODUCT((AR!$C$4:$C$498<>"")*(AR!$D$4:$D$498<>"")*(AR!$F$4:$F$498<>"")*(AR!$F$4:$F$498<=B34))} -> 38
B35: =B18 -> 46090 | C35: {=SUMPRODUCT((AR!$C$4:$C$498<>"")*(AR!$D$4:$D$498<>"")*((AR!$E$4:$E$498<=B35)+(AR!$E$4:$E$498>B35)))} -> 38 | D35: {=SUMPRODUCT((AR!$C$4:$C$498<>"")*(AR!$D$4:$D$498<>"")*(AR!$E$4:$E$498<=B35))} -> 38 | E35: {=SUMPRODUCT((AR!$C$4:$C$498<>"")*(AR!$D$4:$D$498<>"")*(AR!$F$4:$F$498<>"")*(AR!$F$4:$F$498<=B35))} -> 38
B38: Electrical
B39: w/e | C39: Total Expected | D39: Planned Submission | E39: Actual Submitted | F39: Status
F40: Under Review | I40: A | J40: B | K40: C
F41: CTA | G41: AUR | H41: STT
B42: =B9 -> 46027 | C42: {=SUMPRODUCT((EL!$C$4:$C$477<>"")*(EL!$D$4:$D$477<>"")*((EL!$E$4:$E$477<=B42)+(EL!$E$4:$E$477>B42)))} -> 47 | D42: {=SUMPRODUCT((EL!$C$4:$C$477<>"")*(EL!$D$4:$D$477<>"")*(EL!$E$4:$E$477<=B42))} -> 47 | E42: {=SUMPRODUCT((EL!$C$4:$C$477<>"")*(EL!$D$4:$D$477<>"")*(EL!$F$4:$F$477<>"")*(EL!$F$4:$F$477<=B42))} -> 0 | F42: {=SUMPRODUCT((EL!$C$4:$C$477<>"")*(EL!$D$4:$D$477<>"")*(EL!$F$4:$F$477<=$B42)*(EL!$K$4:$K$477="Pending")*(EL!$J$4:$J$477="CTA"))} -> 0 | G42: {=SUMPRODUCT((EL!$C$4:$C$477<>"")*(EL!$D$4:$D$477<>"")*(EL!$F$4:$F$477<=$B42)*(EL!$K$4:$K$477="Pending")*(EL!$J$4:$J$477="AUR"))} -> 0 | H42: {=SUMPRODUCT((EL!$C$4:$C$477<>"")*(EL!$D$4:$D$477<>"")*(EL!$F$4:$F$477<=$B42)*(EL!$K$4:$K$477="Pending")*(EL!$J$4:$J$477="STT"))} -> 0 | I42: {=SUMPRODUCT((EL!$C$4:$C$477<>"")*(EL!$D$4:$D$477<>"")*(EL!$F$4:$F$477<=$B42)*(EL!$K$4:$K$477="A"))} -> 0 | J42: {=SUMPRODUCT((EL!$C$4:$C$477<>"")*(EL!$D$4:$D$477<>"")*(EL!$F$4:$F$477<=$B42)*(EL!$K$4:$K$477="B"))} -> 0 | K42: {=SUMPRODUCT((EL!$C$4:$C$477<>"")*(EL!$D$4:$D$477<>"")*(EL!$F$4:$F$477<=$B42)*(EL!$K$4:$K$477="C"))} -> 0
B43: =B10 -> 46034 | C43: {=SUMPRODUCT((EL!$C$4:$C$477<>"")*(EL!$D$4:$D$477<>"")*((EL!$E$4:$E$477<=B43)+(EL!$E$4:$E$477>B43)))} -> 47 | D43: {=SUMPRODUCT((EL!$C$4:$C$477<>"")*(EL!$D$4:$D$477<>"")*(EL!$E$4:$E$477<=B43))} -> 47 | E43: {=SUMPRODUCT((EL!$C$4:$C$477<>"")*(EL!$D$4:$D$477<>"")*(EL!$F$4:$F$477<>"")*(EL!$F$4:$F$477<=B43))} -> 0 | F43: {=SUMPRODUCT((EL!$C$4:$C$477<>"")*(EL!$D$4:$D$477<>"")*(EL!$F$4:$F$477<=$B43)*(EL!$K$4:$K$477="Pending")*(EL!$J$4:$J$477="CTA"))} -> 0 | G43: {=SUMPRODUCT((EL!$C$4:$C$477<>"")*(EL!$D$4:$D$477<>"")*(EL!$F$4:$F$477<=$B43)*(EL!$K$4:$K$477="Pending")*(EL!$J$4:$J$477="AUR"))} -> 0 | H43: {=SUMPRODUCT((EL!$C$4:$C$477<>"")*(EL!$D$4:$D$477<>"")*(EL!$F$4:$F$477<=$B43)*(EL!$K$4:$K$477="Pending")*(EL!$J$4:$J$477="STT"))} -> 0 | I43: {=SUMPRODUCT((EL!$C$4:$C$477<>"")*(EL!$D$4:$D$477<>"")*(EL!$F$4:$F$477<=$B43)*(EL!$K$4:$K$477="A"))} -> 0 | J43: {=SUMPRODUCT((EL!$C$4:$C$477<>"")*(EL!$D$4:$D$477<>"")*(EL!$F$4:$F$477<=$B43)*(EL!$K$4:$K$477="B"))} -> 0 | K43: {=SUMPRODUCT((EL!$C$4:$C$477<>"")*(EL!$D$4:$D$477<>"")*(EL!$F$4:$F$477<=$B43)*(EL!$K$4:$K$477="C"))} -> 0
B44: =B11 -> 46041 | C44: {=SUMPRODUCT((EL!$C$4:$C$477<>"")*(EL!$D$4:$D$477<>"")*((EL!$E$4:$E$477<=B44)+(EL!$E$4:$E$477>B44)))} -> 47 | D44: {=SUMPRODUCT((EL!$C$4:$C$477<>"")*(EL!$D$4:$D$477<>"")*(EL!$E$4:$E$477<=B44))} -> 47 | E44: {=SUMPRODUCT((EL!$C$4:$C$477<>"")*(EL!$D$4:$D$477<>"")*(EL!$F$4:$F$477<>"")*(EL!$F$4:$F$477<=B44))} -> 17 | F44: {=SUMPRODUCT((EL!$C$4:$C$477<>"")*(EL!$D$4:$D$477<>"")*(EL!$F$4:$F$477<=$B44)*(EL!$K$4:$K$477="Pending")*(EL!$J$4:$J$477="CTA"))} -> 0 | G44: {=SUMPRODUCT((EL!$C$4:$C$477<>"")*(EL!$D$4:$D$477<>"")*(EL!$F$4:$F$477<=$B44)*(EL!$K$4:$K$477="Pending")*(EL!$J$4:$J$477="AUR"))} -> 7 | H44: {=SUMPRODUCT((EL!$C$4:$C$477<>"")*(EL!$D$4:$D$477<>"")*(EL!$F$4:$F$477<=$B44)*(EL!$K$4:$K$477="Pending")*(EL!$J$4:$J$477="STT"))} -> 10 | I44: {=SUMPRODUCT((EL!$C$4:$C$477<>"")*(EL!$D$4:$D$477<>"")*(EL!$F$4:$F$477<=$B44)*(EL!$K$4:$K$477="A"))} -> 0 | J44: {=SUMPRODUCT((EL!$C$4:$C$477<>"")*(EL!$D$4:$D$477<>"")*(EL!$F$4:$F$477<=$B44)*(EL!$K$4:$K$477="B"))} -> 0 | K44: {=SUMPRODUCT((EL!$C$4:$C$477<>"")*(EL!$D$4:$D$477<>"")*(EL!$F$4:$F$477<=$B44)*(EL!$K$4:$K$477="C"))} -> 0
B45: =B12 -> 46048 | C45: {=SUMPRODUCT((EL!$C$4:$C$477<>"")*(EL!$D$4:$D$477<>"")*((EL!$E$4:$E$477<=B45)+(EL!$E$4:$E$477>B45)))} -> 47 | D45: {=SUMPRODUCT((EL!$C$4:$C$477<>"")*(EL!$D$4:$D$477<>"")*(EL!$E$4:$E$477<=B45))} -> 47 | E45: {=SUMPRODUCT((EL!$C$4:$C$477<>"")*(EL!$D$4:$D$477<>"")*(EL!$F$4:$F$477<>"")*(EL!$F$4:$F$477<=B45))} -> 30 | F45: {=SUMPRODUCT((EL!$C$4:$C$477<>"")*(EL!$D$4:$D$477<>"")*(EL!$F$4:$F$477<=$B45)*(EL!$K$4:$K$477="Pending")*(EL!$J$4:$J$477="CTA"))} -> 0 | G45: {=SUMPRODUCT((EL!$C$4:$C$477<>"")*(EL!$D$4:$D$477<>"")*(EL!$F$4:$F$477<=$B45)*(EL!$K$4:$K$477="Pending")*(EL!$J$4:$J$477="AUR"))} -> 12 | H45: {=SUMPRODUCT((EL!$C$4:$C$477<>"")*(EL!$D$4:$D$477<>"")*(EL!$F$4:$F$477<=$B45)*(EL!$K$4:$K$477="Pending")*(EL!$J$4:$J$477="STT"))} -> 18 | I45: {=SUMPRODUCT((EL!$C$4:$C$477<>"")*(EL!$D$4:$D$477<>"")*(EL!$F$4:$F$477<=$B45)*(EL!$K$4:$K$477="A"))} -> 0 | J45: {=SUMPRODUCT((EL!$C$4:$C$477<>"")*(EL!$D$4:$D$477<>"")*(EL!$F$4:$F$477<=$B45)*(EL!$K$4:$K$477="B"))} -> 0 | K45: {=SUMPRODUCT((EL!$C$4:$C$477<>"")*(EL!$D$4:$D$477<>"")*(EL!$F$4:$F$477<=$B45)*(EL!$K$4:$K$477="C"))} -> 0
B46: =B13 -> 46055 | C46: {=SUMPRODUCT((EL!$C$4:$C$477<>"")*(EL!$D$4:$D$477<>"")*((EL!$E$4:$E$477<=B46)+(EL!$E$4:$E$477>B46)))} -> 47 | D46: {=SUMPRODUCT((EL!$C$4:$C$477<>"")*(EL!$D$4:$D$477<>"")*(EL!$E$4:$E$477<=B46))} -> 47 | E46: {=SUMPRODUCT((EL!$C$4:$C$477<>"")*(EL!$D$4:$D$477<>"")*(EL!$F$4:$F$477<>"")*(EL!$F$4:$F$477<=B46))} -> 37 | F46: {=SUMPRODUCT((EL!$C$4:$C$477<>"")*(EL!$D$4:$D$477<>"")*(EL!$F$4:$F$477<=$B46)*(EL!$K$4:$K$477="Pending")*(EL!$J$4:$J$477="CTA"))} -> 0 | G46: {=SUMPRODUCT((EL!$C$4:$C$477<>"")*(EL!$D$4:$D$477<>"")*(EL!$F$4:$F$477<=$B46)*(EL!$K$4:$K$477="Pending")*(EL!$J$4:$J$477="AUR"))} -> 19 | H46: {=SUMPRODUCT((EL!$C$4:$C$477<>"")*(EL!$D$4:$D$477<>"")*(EL!$F$4:$F$477<=$B46)*(EL!$K$4:$K$477="Pending")*(EL!$J$4:$J$477="STT"))} -> 18 | I46: {=SUMPRODUCT((EL!$C$4:$C$477<>"")*(EL!$D$4:$D$477<>"")*(EL!$F$4:$F$477<=$B46)*(EL!$K$4:$K$477="A"))} -> 0 | J46: {=SUMPRODUCT((EL!$C$4:$C$477<>"")*(EL!$D$4:$D$477<>"")*(EL!$F$4:$F$477<=$B46)*(EL!$K$4:$K$477="B"))} -> 0 | K46: {=SUMPRODUCT((EL!$C$4:$C$477<>"")*(EL!$D$4:$D$477<>"")*(EL!$F$4:$F$477<=$B46)*(EL!$K$4:$K$477="C"))} -> 0
B47: =B14 -> 46062 | C47: {=SUMPRODUCT((EL!$C$4:$C$477<>"")*(EL!$D$4:$D$477<>"")*((EL!$E$4:$E$477<=B47)+(EL!$E$4:$E$477>B47)))} -> 47 | D47: {=SUMPRODUCT((EL!$C$4:$C$477<>"")*(EL!$D$4:$D$477<>"")*(EL!$E$4:$E$477<=B47))} -> 47 | E47: {=SUMPRODUCT((EL!$C$4:$C$477<>"")*(EL!$D$4:$D$477<>"")*(EL!$F$4:$F$477<>"")*(EL!$F$4:$F$477<=B47))} -> 40 | F47: {=SUMPRODUCT((EL!$C$4:$C$477<>"")*(EL!$D$4:$D$477<>"")*(EL!$F$4:$F$477<=$B47)*(EL!$K$4:$K$477="Pending")*(EL!$J$4:$J$477="CTA"))} -> 0 | G47: {=SUMPRODUCT((EL!$C$4:$C$477<>"")*(EL!$D$4:$D$477<>"")*(EL!$F$4:$F$477<=$B47)*(EL!$K$4:$K$477="Pending")*(EL!$J$4:$J$477="AUR"))} -> 22 | H47: {=SUMPRODUCT((EL!$C$4:$C$477<>"")*(EL!$D$4:$D$477<>"")*(EL!$F$4:$F$477<=$B47)*(EL!$K$4:$K$477="Pending")*(EL!$J$4:$J$477="STT"))} -> 18 | I47: {=SUMPRODUCT((EL!$C$4:$C$477<>"")*(EL!$D$4:$D$477<>"")*(EL!$F$4:$F$477<=$B47)*(EL!$K$4:$K$477="A"))} -> 0 | J47: {=SUMPRODUCT((EL!$C$4:$C$477<>"")*(EL!$D$4:$D$477<>"")*(EL!$F$4:$F$477<=$B47)*(EL!$K$4:$K$477="B"))} -> 0 | K47: {=SUMPRODUCT((EL!$C$4:$C$477<>"")*(EL!$D$4:$D$477<>"")*(EL!$F$4:$F$477<=$B47)*(EL!$K$4:$K$477="C"))} -> 0
B48: =B15 -> 46069 | C48: {=SUMPRODUCT((EL!$C$4:$C$477<>"")*(EL!$D$4:$D$477<>"")*((EL!$E$4:$E$477<=B48)+(EL!$E$4:$E$477>B48)))} -> 47 | D48: {=SUMPRODUCT((EL!$C$4:$C$477<>"")*(EL!$D$4:$D$477<>"")*(EL!$E$4:$E$477<=B48))} -> 47 | E48: {=SUMPRODUCT((EL!$C$4:$C$477<>"")*(EL!$D$4:$D$477<>"")*(EL!$F$4:$F$477<>"")*(EL!$F$4:$F$477<=B48))} -> 47
...

Sheet ST
A1: Status: (A) Approved with No Comments, (B) Approved with Comments, (C) Revise & Resubmit | L1: Action by | M1: GAA | N1: CTA | O1: AUR
A2: S/N | B2: Trade | C2: Doc Ref No. | D2: Document Description | E2: Planned Date | F2: Submission Date | G2: Consultant Respond Date | H2: Rev | I2: Action | J2: Status | K2: Approval Date | L2: Remarks | M2: Rev 0 | R2: Rev 1 | W2: Rev 2
M3: Submitted | N3: CTA | O3: AUR | P3: STT | Q3: Status | R3: Submitted | S3: CTA | T3: AUR | U3: STT | V3: Status | W3: Submitted | X3: CTA | Y3: AUR | Z3: STT | AA3: Status
A4: 1 | B4: Civil & Structure | C4: 523213-01-RFI-ST-0001 | D4: Request for Additional Steel Manufacturers Approval due to Material Stock Unavailability | F4: 46063 | G4: =F4+7 -> 46070 | H4: 0 | I4: STT | J4: Pending | M4: 46063 | N4: 46064 | O4: 46064
A5: 2 | B5: Civil & Structure | C5: 523213-01-RFI-ST-0002
I75: DO NOT DELETE
I76: GAA
I77: CTA
I78: AUR
I79: STT
I80: Closed
D89: x

Sheet AR
A1: Status: (A) Approved with No Comments, (B) Approved with Comments, (C) Revise & Resubmit | L1: Action by | M1: GAA | N1: CTA | O1: AUR
A2: S/N | B2: Trade | C2: Doc Ref No. | D2: Document Description | E2: Planned Date | F2: Submission Date | G2: Consultant Respond Date | H2: Rev | I2: Action | J2: Status | K2: Approval Date | L2: Remarks | M2: Rev 0 | R2: Rev 1 | W2: Rev 2
M3: Submitted | N3: CTA | O3: AUR | P3: STT | Q3: Status | R3: Submitted | S3: CTA | T3: AUR | U3: STT | V3: Status | W3: Submitted | X3: CTA | Y3: AUR | Z3: STT | AA3: Status
A4: 1 | B4: Architectural | C4: 523213-01-RFI-AR-0001 | D4: Clarification on Mortar Specification | F4: 46034 | G4: =F4+7 -> 46041 | H4: 0 | I4: CTA | J4: Pending | M4: 46034
A5: =A4+1 -> 2 | B5: Architectural | C5: 523213-01-RFI-AR-0002
A6: =A5+1 -> 3 | B6: Architectural | C6: 523213-01-RFI-AR-0003 | D6: Partition wall or Block Wall HV3 and HV 4 Shaft 2nd Floor | F6: 46042 | G6: =F6+7 -> 46049 | H6: 0 | I6: Closed | J6: B | K6: 46057 | M6: =F6 -> 46042 | N6: 46043 | O6: 46051 | P6: 46057 | Q6: B
A7: =A6+1 -> 4 | B7: Architectural | C7: 523213-01-RFI-AR-0004 | D7: Confirmation for Store Room or EE Riser | F7: 46042 | G7: =F7+7 -> 46049 | H7: 0 | I7: Closed | J7: B | K7: 46058 | M7: =F7 -> 46042 | N7: 46043 | O7: 46052 | P7: 46058
A8: =A7+1 -> 5 | B8: Architectural | C8: 523213-01-RFI-AR-0005 | D8: Partition wall or Block wall Chiller 2nd 3rd 4th and 5th FL | F8: 46042 | G8: =F8+7 -> 46049 | H8: 0 | I8: Closed | J8: B | K8: 46057 | M8: =F8 -> 46042 | N8: 46043 | O8: 46051 | P8: 46057 | Q8: B
A9: =A8+1 -> 6 | B9: Architectural | C9: 523213-01-RFI-AR-0006 | D9: Confirmation for Whether the Door Handle is to be Installed on the Right-Hand Side or Left-Hand Side. 2nd Floor | F9: 46042 | G9: =F9+7 -> 46049 | H9: 0 | I9: STT | J9: Pending | M9: =F9 -> 46042 | N9: 46052 | O9: 46058
A10: =A9+1 -> 7 | B10: Architectural | C10: 523213-01-RFI-AR-0007
A11: =A10+1 -> 8 | B11: Architectural | C11: 523213-01-RFI-AR-0008
A12: =A11+1 -> 9 | B12: Architectural | C12: 523213-01-RFI-AR-0009 | D12: Indicate Wall Structure and Wall Finishes Type for Store and ELV. B Room | F12: 46042 | G12: =F12+7 -> 46049 | H12: 0 | I12: Closed | J12: B | K12: 46057 | M12: =F12 -> 46042 | N12: 46043 | O12: 46051 | P12: 46057 | Q12: B
A13: =A12+1 -> 10 | B13: Architectural | C13: 523213-01-RFI-AR-0010 | D13: Indicate Wall Structure and Wall Finishes Type for Batt S2, S3 and EE Room 6th Floor | F13: 46042 | G13: =F13+7 -> 46049 | H13: 0 | I13: Closed | J13: B | K13: 46057 | M13: =F13 -> 46042 | N13: 46043 | O13: 46051 | P13: 46057 | Q13: B
A14: =A13+1 -> 11 | B14: Architectural | C14: 523213-01-RFI-AR-0011 | D14: Indicate Wall Structure and Wall Finishes Type for D22 6th Floor | F14: 46042 | G14: =F14+7 -> 46049 | H14: 0 | I14: Closed | J14: B | K14: 46057 | M14: =F14 -> 46042 | N14: 46043 | O14: 46051 | P14: 46057 | Q14: B
A15: =A14+1 -> 12 | B15: Architectural | C15: 523213-01-RFI-AR-0012 | D15: Clarification on Raised Floor for DB Load Bank Room | F15: 46042 | G15: =F15+7 -> 46049 | H15: 0 | I15: Closed | J15: B | K15: 46057 | M15: =F15 -> 46042 | N15: 46043 | O15: 46051 | P15: 46057 | Q15: B
A16: =A15+1 -> 13 | B16: Architectural | C16: 523213-01-RFI-AR-0013 | D16: Floor Tiles Size, Start Point, Layout and Orientation for Security Room and Reception Hall 1st FL | F16: 46042 | G16: =F16+7 -> 46049 | H16: 0 | I16: Closed | J16: B | K16: 46059 | M16: =F16 -> 46042 | N16: 46052 | O16: 46057 | P16: 46059 | Q16: B
A17: =A16+1 -> 14 | B17: Architectural | C17: 523213-01-RFI-AR-0014 | D17: C11 Ceiling type Specification | F17: 46042 | G17: =F17+7 -> 46049 | H17: 0 | I17: Closed | J17: B | K17: 46057 | M17: =F17 -> 46042 | N17: 46043 | O17: 46051 | P17: 46057 | Q17: B
A18: =A17+1 -> 15 | B18: Architectural | C18: 523213-01-RFI-AR-0015 | D18: Confirm Ceiling Type 6th FL (C4 or C10) | F18: 46037 | G18: =F18+7 -> 46044 | H18: 0 | I18: Closed | J18: B | K18: 46057 | M18: 46037 | N18: 46043 | O18: 46051 | P18: 46057 | Q18: B
A19: =A18+1 -> 16 | B19: Architectural | C19: 523213-01-RFI-AR-0016 | D19: Generator Set and PAU Rooms Waterproofing Scope | F19: 46042 | G19: =F19+7 -> 46049 | H19: 0 | I19: STT | J19: Pending | M19: =F19 -> 46042 | N19: 46058 | O19: 46059
A20: =A19+1 -> 17 | B20: Architectural | C20: 523213-01-RFI-AR-0017 | D20: Busway Riser or EE Riser 2nd Floor | F20: 46037 | G20: =F20+7 -> 46044 | H20: 0 | I20: STT | J20: Pending | M20: 46037 | N20: 46052 | O20: 46058
A21: =A20+1 -> 18 | B21: Architectural | C21: 523213-01-RFI-AR-0018 | D21: Regarding the alignment of the wall between IFC and TTI model is not the same. Gaa would like to confirm which model we should use? | F21: 46035 | G21: 46042 | H21: 0 | I21: Closed | J21: B | K21: 46058 | M21: 46035 | N21: 46043 | O21: 46052 | P21: 46058
A22: =A21+1 -> 19 | B22: Architectural | C22: 523213-01-RFI-AR-0019 | D22: Clarification on Door Frame Depth Considering Different Wall Thicknesses | F22: 46036 | G22: =F22+7 -> 46043 | H22: 0 | I22: Closed | J22: B | K22: 46058 | M22: 46036 | N22: 46043 | O22: 46052 | P22: 46058
A23: =A22+1 -> 20 | B23: Architectural | C23: 523213-01-RFI-AR-0020 | D23: Clarification of Return Air Grills 2nd, 3rd, 4th and 5th Floor | F23: 46037 | G23: =F23+7 -> 46044 | H23: 0 | I23: Closed | J23: B | K23: 46058 | M23: 46037 | N23: 46043 | O23: 46052 | P23: 46058
A24: =A23+1 -> 21 | B24: Architectural | C24: 523213-01-RFI-AR-0021
A25: =A24+1 -> 22 | B25: Architectural | C25: 523213-01-RFI-AR-0022 | D25: Floor Flatness FM2 and Screed Reinforcement details for Data Hall and Related Area | F25: 46039 | G25: 46046 | H25: 0 | I25: Closed | J25: B | K25: 46055 | M25: =F25 -> 46039 | N25: 46044 | O25: 46048
A26: =A25+1 -> 23 | B26: Architectural | C26: 523213-01-RFI-AR-0023 | D26: Finishing Schedule | F26: 46038 | G26: =F26+7 -> 46045 | H26: 0 | I26: Closed | J26: B | K26: 46058 | M26: =F26 -> 46038 | N26: 46043 | O26: 46052 | P26: 46058
A27: =A26+1 -> 24 | B27: Architectural | C27: 523213-01-RFI-AR-0024 | D27: Confirmation on the Wire Mesh Screen Details at the Fan wall Corridors | F27: 46041 | G27: =F27+7 -> 46048 | H27: 0 | I27: Closed | J27: B | K27: 46058 | M27: =F27 -> 46041 | N27: 46043 | O27: 46052 | P27: 46058
A28: =A27+1 -> 25 | B28: Architectural | C28: 523213-01-RFI-AR-0025 | D28: Confirm for the Final Height of HMI Display from Fan wall unit (FWU) with Respects to Human Ratio | F28: 46041 | G28: =F28+7 -> 46048 | H28: 0 | I28: Closed | J28: B | K28: 46058 | M28: =F28 -> 46041 | N28: 46043 | O28: 46052 | P28: 46058
A29: =A28+1 -> 26 | B29: Architectural | C29: 523213-01-RFI-AR-0026 | D29: Reduce the Thickness of Glass block in the Curve Wall from 12.7 mm. to 10.0 mm. | F29: 46041 | G29: =F29+7 -> 46048 | H29: 0 | I29: Closed | J29: B | K29: 46058 | M29: =F29 -> 46041 | N29: 46043 | O29: 46052 | P29: 46058
A30: =A29+1 -> 27 | B30: Architectural | C30: 523213-01-RFI-AR-0027 | D30: Confirm Colour Code and Type - Semi-Gloss or Matt Type | F30: 46041 | G30: =F30+7 -> 46048 | H30: 0 | I30: Closed | J30: A | K30: 46059 | M30: =F30 -> 46041 | N30: 46049 | O30: 46055 | P30: 46059 | Q30: A
A31: =A30+1 -> 28 | B31: Architectural | C31: 523213-01-RFI-AR-0028 | D31: Proposal for Waterproofing Termination Level at RC Curb for F3, F3C and F6 | F31: 46042 | G31: =F31+7 -> 46049 | H31: 0 | I31: STT | J31: Pending | M31: =F31 -> 46042 | N31: 46044 | O31: 46055
A32: =A31+1 -> 29 | B32: Architectural | C32: 523213-01-RFI-AR-0029 | D32: Confirm Colour for Partition Wall Toilet Room 1st to 5th Floor | F32: 46042 | G32: =F32+7 -> 46049 | H32: 0 | I32: Closed | J32: B | K32: 46059 | M32: =F32 -> 46042 | N32: 46052 | O32: 46057 | P32: 46059 | Q32: B
A33: =A32+1 -> 30 | B33: Architectural | C33: 523213-01-RFI-AR-0030 | D33: Clarify Ceiling Soffit Color for Ceiling Painting | F33: 46042 | G33: =F33+7 -> 46049 | H33: 0 | I33: Closed | J33: B | K33: 46059 | M33: =F33 -> 46042 | N33: 46052 | O33: 46057 | P33: 46059 | Q33: B
A34: =A33+1 -> 31 | B34: Architectural | C34: 523213-01-RFI-AR-0031 | D34: Request Product to Replace SIKA Bituseal-1500SA (Due to Discontinue to Produce) | F34: 46043 | G34: =F34+7 -> 46050 | H34: 0 | I34: STT | J34: Pending | M34: =F34 -> 46043 | N34: 46058 | O34: 46059
A35: =A34+1 -> 32 | B35: Architectural | C35: 523213-01-RFI-AR-0032 | D35: Confirm the Correct Floor Finishes for ID Works 1st-ID Works and 2nd to 5th Toilet | F35: 46043 | G35: =F35+7 -> 46050 | H35: 0 | I35: Closed | J35: B | K35: 46059 | M35: =F35 -> 46043 | N35: 46052 | O35: 46057 | P35: 46059 | Q35: B
A36: =A35+1 -> 33 | B36: Architectural | C36: 523213-01-RFI-AR-0033 | D36: Confirm the Correct Ceiling Finishes for ID Works 1st to 5th Floor | F36: 46043 | G36: =F36+7 -> 46050 | H36: 0 | I36: Closed | J36: B | K36: 46059 | M36: =F36 -> 46043 | N36: 46052 | O36: 46057 | P36: 46059 | Q36: B
A37: =A36+1 -> 34 | B37: Architectural | C37: 523213-01-RFI-AR-0034 | D37: Clarify the C2 T-Bar Ceiling and Specify the Colour | F37: 46043 | G37: =F37+7 -> 46050 | H37: 0 | I37: Closed | J37: B | K37: 46059 | M37: =F37 -> 46043 | N37: 46052 | O37: 46057 | P37: 46059 | Q37: B
